Workbook

Sheet STEMI
B1: PAZIENTI CON DATE DI ACQUISIZIONE ERRATE
B3: PAT ID | C3: DATI PROCEDURA E RICOVERO | D3: ANTIAGGREGANTE
B4: Cognome-nome | C4: Data evento | D4: (1 Plavix; 2 Altro) | E4: TnThs MIRE 1 | F4: CK-MB 1 | G4: TnThs MIRE 2 | H4: CK-MB 2 | I4: TnThs MIRE 3 | J4: CK-MB 3 | K4: TnThs MIRE 4 | L4: CK-MB 4 | M4: TnThs MIRE 5 | N4: CK-MB 5 | O4: TnThs MIRE 6 | P4: CK-MB 6 | Q4: TnThs MIRE 7 | R4: CK-MB 7 | S4: TnThs MIRE 8 | T4: CK-MB 8 | U4: TnThs MIRE 9 | V4: CK-MB 9 | W4: TnThs MIRE 10 | X4: CK-MB 10 | Y4: TnThs MIRE 11 | Z4: CK-MB 11
A5: 1 | B5: ANANIA Luigi | C5: 19/08/2016 ore 21:00 | D5: Prasugrel | E5: 0,814 ore 15:07 22/08/2016 | F5: 9.51 | G5: 0,814 ore 14:44 22/08/2016 | H5: 9.51 | I5: 0,967 ore 18:25 22/08/2016 | J5: 10.91 | K5: 0,848 ore 18:58 23/08/2016 | L5: 11.3 | M5: 0,909 ore 11:07 25/08/2016 | N5: 3.1
A6: 2 | B6: PIPERNO Antonio Giuseppe | C6: 23/08/2016 ore 18:00 | D6: Clopidogrel | E6: 0,098 ore 22:44 23/08/2016 | F6: 3.82 | G6: 0,098 ore 22:43 23/08/2016 | H6: 3.82 | I6: 0,130 ore 06:54 24/08/2016 | J6: 12.48 | K6: 0,131 ore 08:34 24/08/2016 | L6: 11.17 | M6: 0,163 ore 09:22 25/08/2016 | N6: 5.59 | O6: 0,150 ore 09:35 26/08/2016 | P6: 2.65 | Q6: 0,147 ore 18:55 26/08/2016 | R6: 3.79 | S6: 0,178 ore 09:54 27/08/2016 | T6: 8.54 | U6: 0,181 ore 09:27 28/08/2016 | V6: 3.58 | W6: 0,183 ore 08:29 29/08/2016 | X6: 1.73 | Y6: 0,139 ore 08:56 30/08/2016 | Z6: 0.86 | AA6: 0,094 ore 10:50 31/08/2016 | AB6: 1.04
A7: 3 | B7: PROLOGO Mario Luigi | C7: 23/08/2016 ore 14:00 | D7: Prasugrel | E7: 12,900 ore 20:00 23/08/2016 | F7: 273.3 | G7: 6,940 ore 00:28 24/08/2016 | H7: 6.94 | I7: 4,580 ore 08:56 24/08/2016 | J7: 226.8 | K7: 2,930 ore 09:28 25/08/2016 | L7: 18.73 | M7: 4,080 ore 09:25 26/08/2016 | N7: 5.1 | O7: 3,720 ore 10:35 27/08/2016 | P7: 2.77 | Q7: 2,410 ore 10:12 28/08/2016 | R7: 2.59 | S7: 0,674 ore 10:06 30/08/2016 | T7: 2.28
A8: 4 | B8: VISCOMI Vincenza | C8: 23/08/2016 ore 09:30 | D8: Prasugrel | E8: 0,189 ore 14:34 23/08/2016 | F8: 8.8 | G8: 0,468 ore 19:49 23/08/2016 | H8: 20.22 | I8: 0,322 ore 08:20 24/08/2016 | J8: 17.35 | K8: 0,232 ore 09:37 25/08/2016 | L8: 7.4 | M8: 0,240 ore 09:35 26/08/2016 | N8: 3.22 | O8: 0,231 ore 10:46 27/08/2016 | P8: 2.86 | Q8: 0,199 ore 10:16 28/08/2016 | R8: 1.94 | S8: 0,146 ore 10:09 29/08/2016 | T8: 1.64 | U8: 0,11 ore 10:12 30/08/2016 | V8: 1.44
A9: 5 | B9: PLATANIA Francesco | C9: 25/08/2016 ore 22:30 | D9: Prasugrel | E9: 2,240 ore 22:21 25/08/2016 | F9: 169.4 | G9: 6,930 ore 02:21 26/08/2016 | H9: 287 | I9: 7,010 ore 09:35 26/08/2016 | J9: 251.6 | K9: 2,490 ore 09:38 27/08/2016 | L9: 31.87 | M9: 3,160 ore 09:00 28/08/2016 | N9: 9.64 | O9: 3,820 ore 08:29 29/08/2016 | P9: 6.12 | Q9: 3,4 ore 08:49 30/08/2016 | R9: 5.26
A10: 6 | B10: CASTELLI Alfonso | C10: 25/08/2016 ORE 13:50 | D10: Prasugrel | E10: 0,345 ore18:59 25/08/2016 | F10: 45.42 | G10: 1,3 ore 02:12 26/08/2016 | H10: 60.54 | I10: 0,893 ore 09:18 26/08/2016 | J10: 34.91 | K10: 0,759 ore 10:34 27/08/2016 | L10: 3.92 | M10: 1,020 ore 10:05 28/08/2016 | N10: 1.49
A11: 7 | B11: FERRAGINE Domenico | C11: 29/08/2016 ore 03:15 | D11: Ticagrelor | E11: 0,096 ore 08:26 29/08/2016 | F11: 8.18 | G11: 0,245 ore 12:42 29/08/2016 | H11: 28.97 | I11: 0,636 ore 08:49 30/08/2016 | J11: 36.69 | K11: 0,474 ore 10:13 31/08/2016 | L11: 6.5 | M11: 0,614 ore 09:54 01/09/2016 | N11: 1.76 | O11: 0,628 ore 09:43 02/09/2016 | P11: 1.52 | Q11: 0,390 ore 09:46 03/09/2016 | R11: 1.91
A12: 8 | B12: AIELLO Lucia | C12: 07/09/2016 ore 20:00 | D12: Prasugrel | E12: 0,153 ore 00,23 08/09/2016 | F12: 5.5 | G12: 0,155 ore 08:05 08/09/2016 | H12: 8.07 | I12: 0,174 ore 10:07 08/09/2016 | J12: 8.24 | K12: 0,113 ore 10:16 09/09/2016 | L12: 8.33 | M12: 0,114 ore 09:50 10/09/2016 | N12: 3.16 | O12: 0,142 ore 10:02 11/09/2016 | P12: 2.65 | Q12: 0,070 ore 10:22 12/09/2016 | R12: 3.24
A13: 9 | B13: RESTUCCIA Giuseppe | C13: 10/09/2016 ore 08:00 | D13: Clopidogrel | E13: 0,029 ore 16:43 10/09/2016 | F13: 4.37 | G13: 0,031 ore 10:02 11/09/2016 | H13: 3.75 | I13: 0,036 ore 10:50 12/09/2016 | J13: 3.6
A14: 10 | B14: IANNUZZI Luigi | C14: 09/09/2016 ore 15:00 | D14: Prasugrel | E14: 1,780 ore 23_23 10/09/2016 | F14: 4.39 | G14: 2,060 ore 10:02 11/09/2016 | H14: 3.18 | I14: 2,170 ore 10:50 12/09/2016 | J14: 2.01 | K14: 1,960 ore 18:27 12/09/2016 | L14: 2.23 | M14: 1,670 ore 09:39 13/09/2016 | N14: 2.62 | O14: 1,060 ore 10:32 14/09/2016 | P14: 1.63
A15: 11 | B15: BOZON Maddalena | C15: 15/09/2016 ore 15:00 | D15: Clopidogrel | E15: 0,096 ore 19:56 15/09/2016 | F15: 5.73 | G15: 0,389 ore 23:47 15/09/2016 | H15: 12.95 | I15: 0,796 ore 09:59 16/09/2016 | J15: 23.55 | K15: 0,436 ore 10:28 17/09/2016 | L15: 9.12 | M15: 0,487 ore 10:25 18/09/2016 | N15: 5.75 | O15: 0,521 ore 09:34 19/09/2016 | P15: 3.78
A16: 12 | B16: ROSTITOLLA Pietro | C16: 15/09/2016 ore 16:00 | D16: Clopidogrel | E16: 18,240 ore 23:22 15/09/2016 | F16: 482.7 | G16: 11,910 ore 07:45 16/09/2016 | H16: 169.8 | I16: 8,330 ore 17:32 16/09/2016 | J16: 122.5 | K16: 6,010 ore 11:1717/09/2016 | L16: 24.54 | M16: 5,640 ore 10:25 18/09/2016 | N16: 6.44 | O16: 5,680 ore 09:34 19/09/2016 | P16: 3.63 | Q16: 5,450 ore 10:56 20/09/2016 | R16: 3.35 | S16: 2,070 ore 10:37 22/09/2016 | T16: 3.53
A17: 13 | B17: LOCCISANO Francesco | C17: 15/09/2016 ore 16:00 | D17: Clopidogrel | E17: 3,870 ore15:48 16/09/2016 | F17: 125.4 | G17: 3,870 ore 15:46 16/09/2016 | H17: 125.4 | I17: 2,9 ore 21:13 16/09/2016 | J17: 65.41 | K17: 3,1 ore 10:28 17/09/2016 | L17: 22.77 | M17: 2,380 ore 10:25 18/09/2016 | N17: 7.29 | O17: 2,640 ore 09:04 19/09/2016 | P17: 4.22 | Q17: 2,490 ore 10:22 20/09/2016 | R17: 4.29 | S17: 0,010 ore 10:44 21/09/2016 | T17: 1.89 | U17: 2,030 ore 10:44 21/09/2016 | V17: 3.56
A18: 14 | B18: SORIANO Giuseppe | C18: 25/09/2016 ore 06:00 | D18: Prasugrel | E18: 2,830 ore 19:33 25/09/2016 | F18: 210.7 | G18: 4,100 ore 00:33 26/06/2016 | H18: 248.8 | I18: 2,440 ore 09:43 26/09/2016 | J18: 108.5 | K18: 1,680 ore 20:30 26/09/2016 | L18: 24.3 | M18: 2,160 ore 09:18 27/09/2016 | N18: 11.5 | O18: 2,870 ore 09:19 28/09/2016 | P18: 4.5 | Q18: 2,090 ore 10:53 29/09/2016 | R18: 2.73 | S18: 0,992 ore 09:57 30/09/2016 | T18: 2.11 | U18: 0,451 ore 10:07 01/10/2016 | V18: 2.1 | W18: 0,205 ore 09:38 02/10/2016 | X18: 2.05
A19: 15 | B19: COLOSIMO Domenico | C19: 24/09/2016 ore 18:00 | D19: Clopidogrel | E19: 1,440 ore 11:56 25/09/2016 | F19: 12.73 | G19: 2,010 ore 00:33 26/09/2016 | H19: 13.87 | I19: 1,7 ore 08:47 26/09/2016 | J19: 11.42 | K19: 1,890 ore 09:18 27/09/2016 | L19: 5.81 | M19: 1,720 ore 18:15 27/09/2016 | N19: 4.81 | O19: 1,690 ore 09:33 28/09/2016 | P19: 3.58 | Q19: 0,731 ore 10:15 30/09/2016 | R19: 2.05
A20: 16 | B20: LOCHIATTO Francesco | C20: 26/09/2016 ore 01:00 | D20: Ticagrelor | E20: 3,940 ore 12:40 26/09/2016 | F20: 257.3 | G20: >10 ore 13:09 26/09/2016 | H20: >300 | I20: 10,680 ore 20:21 2/09/2016 | J20: 260.3 | K20: 7,180 ore 09:31 27/09/2016 | L20: 91.75 | M20: 4,980 ore 09:33 28/09/2016 | N20: 10.56 | O20: 5,100 ore 10:11 29/09/2016 | P20: 5.04 | Q20: 4,450 ore 09:57 30/09/2016 | R20: 4.91 | S20: 3,220 ore 08:46 01/10/2016 | T20: 6.47 | U20: 1,250 ore 11:17 03/10/2016 | V20: 6.47 | W20: 0,744 ore 09:50 04/10/2016 | X20: 5.29
A21: 17 | B21: SALFO Pasqule | C21: 26/09/2016 ore 01:00 | D21: Clopidogrel | E21: 7,010 ore 26/09/2016 26/09/2016 | F21: >300 | G21: 5,270 ore 21:25 26/09/2016 | H21: 429.5 | I21: 4,950 ore 09:36 27/09/2016 | J21: 184.8 | K21: 3,430 ore 09:33 28/09/2016 | L21: 18.03 | M21: 4,010 ore 10:53 29/09/2016 | N21: 5.81 | O21: 4,7 ore 10:00 30/09/2016 | P21: 3.55 | Q21: 3,720 ore 08:40 01/10/2016 | R21: 3.18 | S21: 3,060 ore 09:31 02/10/2016 | T21: 2.12
A22: 18 | B22: CORDARO franco | C22: 27/09/2016 ore 01:00 | D22: Prasugrel | E22: 11,240 ore18:58 27/09/2016 | F22: 237.4 | G22: 7,790 ore 21:46 27/09/2016 | H22: 250.8 | I22: 5,030 ore 09:42 28/09/2016 | J22: 103.3 | K22: 2,840 ore 10:53 29/09/2016 | L22: 14.89 | M22: 3,690 ore 09:57 30/09/2016 | N22: 4.1 | O22: 4,560 ore 08:51 01/10/2016 | P22: 2.65 | Q22: 3,980 ore 09:31 02/10/2016 | R22: 1.9 | S22: 2,270 ore 10:19 03/10/2016 | T22: 1.62 | U22: 1,650 ore 09:03 04/10/2016 | V22: 1.58 | W22: 1,500 ore 23:28 04/10/2016 | X22: 2.37 | Y22: 1,300 ore 09:21 05/10/2016 | Z22: 4.19 | AA22: 1,160 ore 18:09 05/10/2016 | AB22: 3.67 | AC22: 0,711 ore 09:26 07/10/2016 | AD22: 1.7 | AE22: 0,540 ore 09:32 08/10/2016 | AF22: 1.52
A23: 19 | B23: GIORGI Giovanni | C23: 06/10/2016 ore 10:30 | D23: Prasugrel | E23: 28,390 ore 21:20 05/10/2016 | F23: 377.7 | G23: 15,650 ore 01:12 06/10/2016 | H23: 304 | I23: 9,970 ore 09:26 06/10/2016 | J23: 228.4 | K23: 2,660 ore 09:32 08/10/2016 | L23: 3.94 | M23: 2,270 ore 09:14 09/10/2016 | N23: 5.23 | O23: 1,760 ore 09:25 10/10/2016 | P23: 5.68 | Q23: 1,460 ore 10:25 11/10/2016 | R23: 6.34
A24: 20 | B24: TAMBORRINO Nerina | C24: 09/10/2016 ore 00:00 | D24: Ticagrelor | E24: 5,740 ore 14:58 10/10/2016 | F24: 292.4 | G24: 8,740 ore 20:00 10/10/2016 | H24: 345.5 | I24: 3,300 ore 11:51 11/10/2016 | J24: 151.2 | K24: 3,260 ore 09:41 12/10/2016 | L24: 17.02 | M24: 3,360 ore 09:09 13/10/2016 | N24: 5.85 | O24: 3,010 ore 10:25 14/10/2016 | P24: 3.24 | Q24: 2,570 ore 19:03 14/10/2016 | R24: 3.05 | S24: 1,290 ore 11:12 15/10/2016 | T24: 2.74 | U24: 0,579 ore 11:15 16/10/2016 | V24: 2.65 | W24: 0,305 ore 10:45 17/10/2016 | X24: 3.24

Sheet CK-MB
A1: Paziente | B1: CK-MB1 | C1: CK-MB2 | D1: CK-MB3 | E1: CK-MB4 | F1: CK-MB5 | G1: CK-MB6 | H1: CK-MB7 | I1: CK-MB8 | J1: CK-MB9 | K1: CK-MB10 | L1: CK-MB11 | M1: CK-MB12 | N1: CK-MB13 | O1: CK-MB14
A2: ANANIA Luigi | B2: 9.51 | C2: 10.91 | D2: 11.3 | E2: 3.1
A3: PIPERNO Antonio Giuseppe | B3: 3.82 | C3: 12.48 | D3: 11.17 | E3: 5.59 | F3: 2.65 | G3: 3.79 | H3: 8.54 | I3: 3.58 | J3: 1.73 | K3: 0.86 | L3: 1.04
A4: PROLOGO Mario Luigi | B4: 273.3 | C4: 6.94 | D4: 226.8 | E4: 18.73 | F4: 5.1 | G4: 2.77 | H4: 2.59 | I4: 2.28
A5: VISCOMI Vincenza | B5: 8.8 | C5: 20.22 | D5: 17.35 | E5: 7.4 | F5: 3.22 | G5: 2.86 | H5: 1.94 | I5: 1.64 | J5: 1.44
A6: PLATANIA Francesco | B6: 169.4 | C6: 287 | D6: 251.6 | E6: 31.87 | F6: 9.64 | G6: 6.12 | H6: 5.26
A7: CASTELLI Alfonso | B7: 45.42 | C7: 60.54 | D7: 34.91 | E7: 3.92 | F7: 1.49
A8: FERRAGINE Domenico | B8: 8.18 | C8: 28.97 | D8: 36.69 | E8: 6.5 | F8: 1.76 | G8: 1.52 | H8: 1.91
A9: AIELLO Lucia | B9: 5.5 | C9: 8.07 | D9: 8.24 | E9: 8.33 | F9: 3.16 | G9: 2.65 | H9: 3.24
A10: RESTUCCIA Giuseppe | B10: 4.37 | C10: 3.75 | D10: 3.6
A11: IANNUZZI Luigi | B11: 4.39 | C11: 3.18 | D11: 2.01 | E11: 2.23 | F11: 2.62 | G11: 1.63
A12: BOZON Maddalena | B12: 5.73 | C12: 12.95 | D12: 23.55 | E12: 9.12 | F12: 5.75 | G12: 3.78
A13: ROSTITOLLA Pietro | B13: 482.7 | C13: 169.8 | D13: 122.5 | E13: 24.54 | F13: 6.44 | G13: 3.63 | H13: 3.35 | I13: 3.53
A14: LOCCISANO Francesco | B14: 125.4 | C14: 125.4 | D14: 65.41 | E14: 22.77 | F14: 7.29 | G14: 4.22 | H14: 4.29 | I14: 1.89 | J14: 3.56
A15: SORIANO Giuseppe | B15: 210.7 | C15: 248.8 | D15: 108.5 | E15: 24.3 | F15: 11.5 | G15: 4.5 | H15: 2.73 | I15: 2.11 | J15: 2.1 | K15: 2.05
A16: COLOSIMO Domenico | B16: 12.73 | C16: 13.87 | D16: 11.42 | E16: 5.81 | F16: 4.81 | G16: 3.58 | H16: 2.05
A17: LOCHIATTO Francesco | B17: 257.3 | C17: 300 | D17: 260.3 | E17: 91.75 | F17: 10.56 | G17: 5.04 | H17: 4.91 | I17: 6.47 | J17: 6.47 | K17: 5.29
A18: SALFO Pasqule | B18: 300 | C18: 429.5 | D18: 184.8 | E18: 18.03 | F18: 5.81 | G18: 3.55 | H18: 3.18 | I18: 2.12
A19: CORDARO franco | B19: 237.4 | C19: 250.8 | D19: 103.3 | E19: 14.89 | F19: 4.1 | G19: 2.65 | H19: 1.9 | I19: 1.62 | J19: 1.58 | K19: 2.37 | L19: 4.19 | M19: 3.67 | N19: 1.7 | O19: 1.52
A20: GIORGI Giovanni | B20: 377.7 | C20: 304 | D20: 228.4 | E20: 3.94 | F20: 5.23 | G20: 5.68 | H20: 6.34
A21: TAMBORRINO Nerina | B21: 292.4 | C21: 345.5 | D21: 151.2 | E21: 17.02 | F21: 5.85 | G21: 3.24 | H21: 3.05 | I21: 2.74 | J21: 2.65 | K21: 3.24
A23: 300: Il valore originale è >300

Sheet STEMI_ORGANIZZATI
A1: ACQUISIZIONI EFFETTUATE IN TEMPI BREVISSIMI
A2: PAZIENTI CON DATE DI ACQUISIZIONE CORRETTE
B3: PAT ID | C3: DATI PROCEDURA E RICOVERO | D3: ANTIAGGREGANTE
B4: Cognome-nome | C4: Data evento | D4: (1 Plavix; 2 Altro) | E4: Tempo 1° Acquisizione | F4: 1° Intervallo temporale | G4: TnThs MIRE 1 | H4: CK-MB 1 | I4: Tempo 2° Acquisizione | J4: 2° Intervallo temporale | K4: TnThs MIRE 2 | L4: CK-MB 2 | M4: Tempo 3° Acquisizione | N4: 3° Intervallo temporale | O4: TnThs MIRE 3 | P4: CK-MB 3 | Q4: Tempo 4° Acquisizione | R4: 4° Intervallo temporale | S4: TnThs MIRE 4 | T4: CK-MB 4 | U4: Tempo 5° Acquisizione | V4: 5° Intervallo temporale | W4: TnThs MIRE 5 | X4: CK-MB 5 | Y4: Tempo 6° Acquisizione | Z4: 6° Intervallo temporale | AA4: TnThs MIRE 6 | AB4: CK-MB 6 | AC4: Tempo 7° Acquisizione | AD4: 7° Intervallo temporale | AE4: TnThs MIRE 7 | AF4: CK-MB 7 | AG4: Tempo 8° Acquisizione | AH4: 8° Intervallo temporale | AI4: TnThs MIRE 8 | AJ4: CK-MB 8 | AK4: Tempo 9° Acquisizione | AL4: 9° Intervallo temporale | AM4: TnThs MIRE 9 | AN4: CK-MB 9 | AO4: Tempo 10° Acquisizione | AP4: 10° Intervallo temporale | AQ4: TnThs MIRE 10 | AR4: CK-MB 10 | AS4: Tempo 11° Acquisizione | AT4: 11° Intervallo temporale | AU4: TnThs MIRE 11 | AV4: CK-MB 11 | AW4: Tempo 12° Acquisizione | AX4: 12° Intervallo temporale | AY4: TnThs MIRE 12 | AZ4: CK-MB 12 | BA4: Tempo 13° Acquisizione | BB4: 13° Intervallo temporale | BC4: TnThs MIRE 13 | BD4: CK-MB 13 | BE4: Tempo 14° Acquisizione | BF4: 14° Intervallo temporale | BG4: TnThs MIRE 14 | BH4: CK-MB 14
A5: 1 | B5: ANANIA Luigi | C5: 42601.875 | D5: Prasugrel | E5: 42604.63 | F5: =E5-C5 -> 2.7548611 | G5: 0.814 | H5: 9.51 | I5: 42604.614 | J5: =I5-C5 -> 2.7388889 | K5: 0.814 | L5: 9.51 | M5: 42604.767 | N5: =M5-C5 -> 2.8923611 | O5: 0.967 | P5: 10.91 | Q5: 42605.79 | R5: =Q5-C5 -> 3.9152778 | S5: 0.848 | T5: 11.3 | U5: 42607.463 | V5: =U5-C5 -> 5.5881944 | W5: 0.909 | X5: 3.1
A6: 2 | B6: PIPERNO Antonio Giuseppe | C6: 42605.75 | D6: Clopidogrel | E6: 42605.947 | F6: =E6-C6 -> 0.19722222 | G6: 0.098 | H6: 3.82 | I6: 42605.947 | J6: =I6-C6 -> 0.19652778 | K6: 0.098 | L6: 3.82 | M6: 42606.287 | N6: =M6-C6 -> 0.5375 | O6: 0.13 | P6: 12.48 | Q6: 42606.357 | R6: =Q6-C6 -> 0.60694444 | S6: 0.131 | T6: 11.17 | U6: 42607.39 | V6: =U6-C6 -> 1.6402778 | W6: 0.163 | X6: 5.59 | Y6: 42608.399 | Z6: =Y6-C6 -> 2.6493056 | AA6: 0.15 | AB6: 2.65 | AC6: 42608.788 | AD6: =AC6-C6 -> 3.0381944 | AE6: 0.147 | AF6: 3.79 | AG6: 42609.412 | AH6: =AG6-C6 -> 3.6625 | AI6: 0.178 | AJ6: 8.54 | AK6: 42610.394 | AL6: =AK6-C6 -> 4.64375 | AM6: 0.181 | AN6: 3.58 | AO6: 42611.353 | AP6: =AO6-C6 -> 5.6034722 | AQ6: 0.183 | AR6: 1.73 | AS6: 42612.372 | AT6: =AS6-C6 -> 6.6222222 | AU6: 0.139 | AV6: 0.86 | AW6: 42613.451 | AX6: =AW6-C6 -> 7.7013889 | AY6: 0.094 | AZ6: 1.04
A7: 3 | B7: PROLOGO Mario Luigi | C7: 42605.583 | D7: Prasugrel | E7: 42605.833 | F7: =E7-C7 -> 0.25 | G7: 12.9 | H7: 273.3 | I7: 42606.019 | J7: =I7-C7 -> 0.43611111 | K7: 6.94 | L7: 6.94 | M7: 42606.372 | N7: =M7-C7 -> 0.78888889 | O7: 4.58 | P7: 226.8 | Q7: 42607.394 | R7: =Q7-C7 -> 1.8111111 | S7: 2.93 | T7: 18.73 | U7: 42608.392 | V7: =U7-C7 -> 2.8090278 | W7: 4.08 | X7: 5.1 | Y7: 42609.441 | Z7: =Y7-C7 -> 3.8576389 | AA7: 3.72 | AB7: 2.77 | AC7: 42610.425 | AD7: =AC7-C7 -> 4.8416667 | AE7: 2.41 | AF7: 2.59 | AG7: 42612.421 | AH7: =AG7-C7 -> 6.8375 | AI7: 0.674 | AJ7: 2.28
A8: 4 | B8: VISCOMI Vincenza | C8: 42605.396 | D8: Prasugrel | E8: 42605.607 | F8: =E8-C8 -> 0.21111111 | G8: 0.189 | H8: 8.8 | I8: 42605.826 | J8: =I8-C8 -> 0.42986111 | K8: 0.468 | L8: 20.22 | M8: 42606.347 | N8: =M8-C8 -> 0.95138889 | O8: 0.322 | P8: 17.35 | Q8: 42607.401 | R8: =Q8-C8 -> 2.0048611 | S8: 0.232 | T8: 7.4 | U8: 42608.399 | V8: =U8-C8 -> 3.0034722 | W8: 0.24 | X8: 3.22 | Y8: 42609.449 | Z8: =Y8-C8 -> 4.0527778 | AA8: 0.231 | AB8: 2.86 | AC8: 42610.428 | AD8: =AC8-C8 -> 5.0319444 | AE8: 0.199 | AF8: 1.94 | AG8: 42611.423 | AH8: =AG8-C8 -> 6.0270833 | AI8: 0.146 | AJ8: 1.64 | AK8: 42612.425 | AL8: =AK8-C8 -> 7.0291667 | AM8: 0.11 | AN8: 1.44
A9: 5 | B9: PLATANIA Francesco | C9: 42607.938 | D9: Prasugrel | E9: 42607.973 | F9: =E9-C9 -> 0.035416667 | G9: 2.24 | H9: 169.4 | I9: 42608.098 | J9: =I9-C9 -> 0.16041667 | K9: 6.93 | L9: 287 | M9: 42608.399 | N9: =M9-C9 -> 0.46180556 | O9: 7.01 | P9: 251.6 | Q9: 42609.401 | R9: =Q9-C9 -> 1.4638889 | S9: 2.49 | T9: 31.87 | U9: 42610.375 | V9: =U9-C9 -> 2.4375 | W9: 3.16 | X9: 9.64 | Y9: 42611.353 | Z9: =Y9-C9 -> 3.4159722 | AA9: 3.82 | AB9: 6.12 | AC9: 42612.367 | AD9: =AC9-C9 -> 4.4298611 | AE9: 3.4 | AF9: 5.26
A10: 6 | B10: CASTELLI Alfonso | C10: 42607.576 | D10: Prasugrel | E10: 42607.791 | F10: =E10-C10 -> 0.21458333 | G10: 0.345 | H10: 45.42 | I10: 42608.092 | J10: =I10-C10 -> 0.51527778 | K10: 1.3 | L10: 60.54 | M10: 42608.387 | N10: =M10-C10 -> 0.81111111 | O10: 0.893 | P10: 34.91 | Q10: 42609.44 | R10: =Q10-C10 -> 1.8638889 | S10: 0.759 | T10: 3.92 | U10: 42610.42 | V10: =U10-C10 -> 2.84375 | W10: 1.02 | X10: 1.49
A11: 7 | B11: FERRAGINE Domenico | C11: 42611.135 | D11: Ticagrelor | E11: 42611.351 | F11: =E11-C11 -> 0.21597222 | G11: 0.096 | H11: 8.18 | I11: 42611.529 | J11: =I11-C11 -> 0.39375 | K11: 0.245 | L11: 28.97 | M11: 42612.367 | N11: =M11-C11 -> 1.2319444 | O11: 0.636 | P11: 36.69 | Q11: 42613.426 | R11: =Q11-C11 -> 2.2902778 | S11: 0.474 | T11: 6.5 | U11: 42614.412 | V11: =U11-C11 -> 3.2770833 | W11: 0.614 | X11: 1.76 | Y11: 42615.405 | Z11: =Y11-C11 -> 4.2694444 | AA11: 0.628 | AB11: 1.52 | AC11: 42616.407 | AD11: =AC11-C11 -> 5.2715278 | AE11: 0.39 | AF11: 1.91
A12: 8 | B12: AIELLO Lucia | C12: 42620.833 | D12: Prasugrel | E12: 42621.016 | F12: =E12-C12 -> 0.18263889 | G12: 0.153 | H12: 5.5 | I12: 42621.337 | J12: =I12-C12 -> 0.50347222 | K12: 0.155 | L12: 8.07 | M12: 42621.422 | N12: =M12-C12 -> 0.58819444 | O12: 0.174 | P12: 8.24 | Q12: 42622.428 | R12: =Q12-C12 -> 1.5944444 | S12: 0.113 | T12: 8.33 | U12: 42623.41 | V12: =U12-C12 -> 2.5763889 | W12: 0.114 | X12: 3.16 | Y12: 42624.418 | Z12: =Y12-C12 -> 3.5847222 | AA12: 0.142 | AB12: 2.65 | AC12: 42625.432 | AD12: =AC12-C12 -> 4.5986111 | AE12: 0.07 | AF12: 3.24
A13: 9 | B13: RESTUCCIA Giuseppe | C13: 42623.333 | D13: Clopidogrel | E13: 42623.697 | F13: =E13-C13 -> 0.36319444 | G13: 0.029 | H13: 4.37 | I13: 42624.418 | J13: =I13-C13 -> 1.0847222 | K13: 0.031 | L13: 3.75 | M13: 42625.451 | N13: =M13-C13 -> 2.1180556 | O13: 0.036 | P13: 3.6
A14: 10 | B14: IANNUZZI Luigi | C14: 42622.625 | D14: Prasugrel | E14: 42623.974 | F14: =E14-C14 -> 1.3493056 | G14: 1.78 | H14: 4.39 | I14: 42624.418 | J14: =I14-C14 -> 1.7930556 | K14: 2.06 | L14: 3.18 | M14: 42625.451 | N14: =M14-C14 -> 2.8263889 | O14: 2.17 | P14: 2.01 | Q14: 42625.769 | R14: =Q14-C14 -> 3.14375 | S14: 1.96 | T14: 2.23 | U14: 42626.402 | V14: =U14-C14 -> 3.7770833 | W14: 1.67 | X14: 2.62 | Y14: 42627.439 | Z14: =Y14-C14 -> 4.8138889 | AA14: 1.06 | AB14: 1.63
A15: 11 | B15: BOZON Maddalena | C15: 42628.625 | D15: Clopidogrel | E15: 42628.831 | F15: =E15-C15 -> 0.20555556 | G15: 0.096 | H15: 5.73 | I15: 42628.991 | J15: =I15-C15 -> 0.36597222 | K15: 0.389 | L15: 12.95 | M15: 42629.416 | N15: =M15-C15 -> 0.79097222 | O15: 0.796 | P15: 23.55 | Q15: 42630.436 | R15: =Q15-C15 -> 1.8111111 | S15: 0.436 | T15: 9.12 | U15: 42631.434 | V15: =U15-C15 -> 2.8090278 | W15: 0.487 | X15: 5.75 | Y15: 42632.399 | Z15: =Y15-C15 -> 3.7736111 | AA15: 0.521 | AB15: 3.78
A16: 12 | B16: ROSTITOLLA Pietro | C16: 42628.667 | D16: Clopidogrel | E16: 42628.974 | F16: =E16-C16 -> 0.30694444 | G16: 18.24 | H16: 482.7 | I16: 42629.323 | J16: =I16-C16 -> 0.65625 | K16: 11.91 | L16: 169.8 | M16: 42629.731 | N16: =M16-C16 -> 1.0638889 | O16: 8.33 | P16: 122.5 | Q16: 42630.47 | R16: =Q16-C16 -> 1.8034722 | S16: 6.01 | T16: 24.54 | U16: 42631.434 | V16: =U16-C16 -> 2.7673611 | W16: 5.64 | X16: 6.44 | Y16: 42632.399 | Z16: =Y16-C16 -> 3.7319444 | AA16: 5.68 | AB16: 3.63 | AC16: 42633.456 | AD16: =AC16-C16 -> 4.7888889 | AE16: 5.45 | AF16: 3.35 | AG16: 42635.442 | AH16: =AG16-C16 -> 6.7756944 | AI16: 2.07 | AJ16: 3.53
A17: 13 | B17: LOCCISANO Francesco | C17: 42628.667 | D17: Clopidogrel | E17: 42629.658 | F17: =E17-C17 -> 0.99166667 | G17: 3.87 | H17: 125.4 | I17: 42629.657 | J17: =I17-C17 -> 0.99027778 | K17: 3.87 | L17: 125.4 | M17: 42629.884 | N17: =M17-C17 -> 1.2173611 | O17: 2.9 | P17: 65.41 | Q17: 42630.436 | R17: =Q17-C17 -> 1.7694444 | S17: 3.1 | T17: 22.77 | U17: 42631.434 | V17: =U17-C17 -> 2.7673611 | W17: 2.38 | X17: 7.29 | Y17: 42632.378 | Z17: =Y17-C17 -> 3.7111111 | AA17: 2.64 | AB17: 4.22 | AC17: 42633.432 | AD17: =AC17-C17 -> 4.7652778 | AE17: 2.49 | AF17: 4.29 | AG17: 42634.447 | AH17: =AG17-C17 -> 5.7805556 | AI17: 0.01 | AJ17: 1.89 | AK17: 42634.447 | AL17: =AK17-C17 -> 5.7805556 | AM17: 2.03 | AN17: 3.56
A18: 14 | B18: SORIANO Giuseppe | C18: 42638.25 | D18: Prasugrel | E18: 42638.815 | F18: =E18-C18 -> 0.56458333 | G18: 2.83 | H18: 210.7 | I18: 42639.023 | J18: =I18-C18 -> 0.77291667 | K18: 4.1 | L18: 248.8 | M18: 42639.405 | N18: =M18-C18 -> 1.1548611 | O18: 2.44 | P18: 108.5 | Q18: 42639.854 | R18: =Q18-C18 -> 1.6041667 | S18: 1.68 | T18: 24.3 | U18: 42640.387 | V18: =U18-C18 -> 2.1375 | W18: 2.16 | X18: 11.5 | Y18: 42641.388 | Z18: =Y18-C18 -> 3.1381944 | AA18: 2.87 | AB18: 4.5 | AC18: 42642.453 | AD18: =AC18-C18 -> 4.2034722 | AE18: 2.09 | AF18: 2.73 | AG18: 42643.415 | AH18: =AG18-C18 -> 5.1645833 | AI18: 0.992 | AJ18: 2.11 | AK18: 42644.422 | AL18: =AK18-C18 -> 6.1715278 | AM18: 0.451 | AN18: 2.1 | AO18: 42645.401 | AP18: =AO18-C18 -> 7.1513889 | AQ18: 0.205 | AR18: 2.05
A19: 15 | B19: COLOSIMO Domenico | C19: 42637.75 | D19: Clopidogrel | E19: 42638.497 | F19: =E19-C19 -> 0.74722222 | G19: 1.44 | H19: 12.73 | I19: 42639.023 | J19: =I19-C19 -> 1.2729167 | K19: 2.01 | L19: 13.87 | M19: 42639.366 | N19: =M19-C19 -> 1.6159722 | O19: 1.7 | P19: 11.42 | Q19: 42640.387 | R19: =Q19-C19 -> 2.6375 | S19: 1.89 | T19: 5.81 | U19: 42640.76 | V19: =U19-C19 -> 3.0104167 | W19: 1.72 | X19: 4.81 | Y19: 42641.398 | Z19: =Y19-C19 -> 3.6479167 | AA19: 1.69 | AB19: 3.58 | AC19: 42643.427 | AD19: =AC19-C19 -> 5.6770833 | AE19: 0.731 | AF19: 2.05
A20: 16 | B20: LOCHIATTO Francesco | C20: 42639.042 | D20: Ticagrelor | E20: 42639.528 | F20: =E20-C20 -> 0.48611111 | G20: 3.94 | H20: 257.3 | I20: 42639.548 | J20: =I20-C20 -> 0.50625 | K20: 10 | L20: >300 | M20: 42639.848 | N20: =M20-C20 -> 0.80625 | O20: 10.68 | P20: 260.3 | Q20: 42640.397 | R20: =Q20-C20 -> 1.3548611 | S20: 7.18 | T20: 91.75 | U20: 42641.398 | V20: =U20-C20 -> 2.35625 | W20: 4.98 | X20: 10.56 | Y20: 42642.424 | Z20: =Y20-C20 -> 3.3826389 | AA20: 5.1 | AB20: 5.04 | AC20: 42643.415 | AD20: =AC20-C20 -> 4.3729167 | AE20: 4.45 | AF20: 4.91 | AG20: 42644.365 | AH20: =AG20-C20 -> 5.3236111 | AI20: 3.22 | AJ20: 6.47 | AK20: 42646.47 | AL20: =AK20-C20 -> 7.4284722 | AM20: 1.25 | AN20: 6.47 | AO20: 42647.41 | AP20: =AO20-C20 -> 8.3680556 | AQ20: 0.744 | AR20: 5.29
A21: 17 | B21: SALFO Pasqule | C21: 42639.042 | D21: Clopidogrel | E21: 42639.417 | F21: =E21-C21 -> 0.375 | G21: 7.01 | H21: >300 | I21: 42639.892 | J21: =I21-C21 -> 0.85069444 | K21: 5.27 | L21: 429.5 | M21: 42640.4 | N21: =M21-C21 -> 1.3583333 | O21: 4.95 | P21: 184.8 | Q21: 42641.398 | R21: =Q21-C21 -> 2.35625 | S21: 3.43 | T21: 18.03 | U21: 42642.453 | V21: =U21-C21 -> 3.4118056 | W21: 4.01 | X21: 5.81 | Y21: 42643.417 | Z21: =Y21-C21 -> 4.375 | AA21: 4.7 | AB21: 3.55 | AC21: 42644.361 | AD21: =AC21-C21 -> 5.3194444 | AE21: 3.72 | AF21: 3.18 | AG21: 42645.397 | AH21: =AG21-C21 -> 6.3548611 | AI21: 3.06 | AJ21: 2.12
A22: 18 | B22: CORDARO franco | C22: 42640.042 | D22: Prasugrel | E22: 42640.79 | F22: =E22-C22 -> 0.74861111 | G22: 11.24 | H22: 237.4 | I22: 42640.907 | J22: =I22-C22 -> 0.86527778 | K22: 7.79 | L22: 250.8 | M22: 42641.404 | N22: =M22-C22 -> 1.3625 | O22: 5.03 | P22: 103.3 | Q22: 42642.453 | R22: =Q22-C22 -> 2.4118056 | S22: 2.84 | T22: 14.89 | U22: 42643.415 | V22: =U22-C22 -> 3.3729167 | W22: 3.69 | X22: 4.1 | Y22: 42644.369 | Z22: =Y22-C22 -> 4.3270833 | AA22: 4.56 | AB22: 2.65 | AC22: 42645.397 | AD22: =AC22-C22 -> 5.3548611 | AE22: 3.98 | AF22: 1.9 | AG22: 42646.43 | AH22: =AG22-C22 -> 6.3881944 | AI22: 2.27 | AJ22: 1.62 | AK22: 42647.377 | AL22: =AK22-C22 -> 7.3354167 | AM22: 1.65 | AN22: 1.58 | AO22: 42647.978 | AP22: =AO22-C22 -> 7.9361111 | AQ22: 1.5 | AR22: 2.37 | AS22: 42648.39 | AT22: =AS22-C22 -> 8.3479167 | AU22: 1.3 | AV22: 4.19 | AW22: 42648.756 | AX22: =AW22-C22 -> 8.7145833 | AY22: 1.16 | AZ22: 3.67 | BA22: 42650.393 | BB22: =BA22-C22 -> 10.351389 | BC22: 0.711 | BD22: 1.7 | BE22: 42651.397 | BF22: =BE22-C22 -> 11.355556 | BG22: 0.54 | BH22: 1.52
A23: 19 | B23: GIORGI Giovanni | C23: 42648.438 | D23: Prasugrel | E23: 42648.889 | F23: =E23-C23 -> 0.45138889 | G23: 28.39 | H23: 377.7 | I23: 42649.05 | J23: =I23-C23 -> 0.6125 | K23: 15.65 | L23: 304 | M23: 42649.393 | N23: =M23-C23 -> 0.95555556 | O23: 9.97 | P23: 228.4 | Q23: 42651.397 | R23: =Q23-C23 -> 2.9597222 | S23: 2.66 | T23: 3.94 | U23: 42652.385 | V23: =U23-C23 -> 3.9472222 | W23: 2.27 | X23: 5.23 | Y23: 42653.392 | Z23: =Y23-C23 -> 4.9548611 | AA23: 1.76 | AB23: 5.68 | AC23: 42654.434 | AD23: =AC23-C23 -> 5.9965278 | AE23: 1.46 | AF23: 6.34
A24: 20 | B24: TAMBORRINO Nerina | C24: 42652 | D24: Ticagrelor | E24: 42653.624 | F24: =E24-C24 -> 1.6236111 | G24: 5.74 | H24: 292.4 | I24: 42653.833 | J24: =I24-C24 -> 1.8333333 | K24: 8.74 | L24: 345.5 | M24: 42654.494 | N24: =M24-C24 -> 2.49375 | O24: 3.3 | P24: 151.2 | Q24: 42655.403 | R24: =Q24-C24 -> 3.4034722 | S24: 3.26 | T24: 17.02 | U24: 42656.381 | V24: =U24-C24 -> 4.38125 | W24: 3.36 | X24: 5.85 | Y24: 42657.434 | Z24: =Y24-C24 -> 5.4340278 | AA24: 3.01 | AB24: 3.24 | AC24: 42657.794 | AD24: =AC24-C24 -> 5.79375 | AE24: 2.57 | AF24: 3.05 | AG24: 42658.467 | AH24: =AG24-C24 -> 6.4666667 | AI24: 1.29 | AJ24: 2.74 | AK24: 42659.469 | AL24: =AK24-C24 -> 7.46875 | AM24: 0.579 | AN24: 2.65 | AO24: 42660.448 | AP24: =AO24-C24 -> 8.4479167 | AQ24: 0.305 | AR24: 3.24

Sheet STEMI_TEMPO_ACQUISIZIONE
A1: ACQUISIZIONI EFFETTUATE IN TEMPI BREVISSIMI
A2: PAZIENTI CON DATE DI ACQUISIZIONE CORRETTE
A3: INTERVALLO TEMPORALE TRA UN'ACQUISIZIONE E L'EVENTO | Q3: LIVELLI DI TROPONINA CARDIACA T MISURATI
A4: PAZIENTE | Q4: PAZIENTE
A5: pat.1 | B5: =STEMI_ORGANIZZATI!F5 -> 2.7548611 | D5: =STEMI_ORGANIZZATI!N5 -> 2.8923611 | E5: =STEMI_ORGANIZZATI!R5 -> 3.9152778 | F5: =STEMI_ORGANIZZATI!V5 -> 5.5881944 | Q5: pat.1 | R5: =STEMI_ORGANIZZATI!G5 -> 0.814 | S5: =STEMI_ORGANIZZATI!O5 -> 0.967 | T5: =STEMI_ORGANIZZATI!S5 -> 0.848 | U5: =STEMI_ORGANIZZATI!W5 -> 0.909
A6: pat.2 | B6: =STEMI_ORGANIZZATI!F6 -> 0.19722222 | D6: =STEMI_ORGANIZZATI!N6 -> 0.5375 | E6: =STEMI_ORGANIZZATI!R6 -> 0.60694444 | F6: =STEMI_ORGANIZZATI!V6 -> 1.6402778 | G6: =STEMI_ORGANIZZATI!Z6 -> 2.6493056 | H6: =STEMI_ORGANIZZATI!AD6 -> 3.0381944 | I6: =STEMI_ORGANIZZATI!AH6 -> 3.6625 | J6: =STEMI_ORGANIZZATI!AL6 -> 4.64375 | K6: =STEMI_ORGANIZZATI!AP6 -> 5.6034722 | L6: =STEMI_ORGANIZZATI!AT6 -> 6.6222222 | M6: =STEMI_ORGANIZZATI!AX6 -> 7.7013889 | Q6: pat.2 | R6: =STEMI_ORGANIZZATI!G6 -> 0.098 | S6: =STEMI_ORGANIZZATI!O6 -> 0.13 | T6: =STEMI_ORGANIZZATI!S6 -> 0.131 | U6: =STEMI_ORGANIZZATI!W6 -> 0.163 | V6: =STEMI_ORGANIZZATI!AA6 -> 0.15 | W6: =STEMI_ORGANIZZATI!AE6 -> 0.147 | X6: =STEMI_ORGANIZZATI!AI6 -> 0.178 | Y6: =STEMI_ORGANIZZATI!AM6 -> 0.181 | Z6: =STEMI_ORGANIZZATI!AQ6 -> 0.183 | AA6: =STEMI_ORGANIZZATI!AU6 -> 0.139 | AB6: =STEMI_ORGANIZZATI!AY6 -> 0.094
A7: pat.3 | B7: =STEMI_ORGANIZZATI!F7 -> 0.25 | C7: =STEMI_ORGANIZZATI!J7 -> 0.43611111 | D7: =STEMI_ORGANIZZATI!N7 -> 0.78888889 | E7: =STEMI_ORGANIZZATI!R7 -> 1.8111111 | F7: =STEMI_ORGANIZZATI!V7 -> 2.8090278 | G7: =STEMI_ORGANIZZATI!Z7 -> 3.8576389 | H7: =STEMI_ORGANIZZATI!AD7 -> 4.8416667 | I7: =STEMI_ORGANIZZATI!AH7 -> 6.8375 | Q7: pat.3 | R7: =STEMI_ORGANIZZATI!G7 -> 12.9 | S7: =STEMI_ORGANIZZATI!K7 -> 6.94 | T7: =STEMI_ORGANIZZATI!O7 -> 4.58 | U7: =STEMI_ORGANIZZATI!S7 -> 2.93 | V7: =STEMI_ORGANIZZATI!W7 -> 4.08 | W7: =STEMI_ORGANIZZATI!AA7 -> 3.72 | X7: =STEMI_ORGANIZZATI!AE7 -> 2.41 | Y7: =STEMI_ORGANIZZATI!AI7 -> 0.674
A8: pat.4 | B8: =STEMI_ORGANIZZATI!F8 -> 0.21111111 | C8: =STEMI_ORGANIZZATI!J8 -> 0.42986111 | D8: =STEMI_ORGANIZZATI!N8 -> 0.95138889 | E8: =STEMI_ORGANIZZATI!R8 -> 2.0048611 | F8: =STEMI_ORGANIZZATI!V8 -> 3.0034722 | G8: =STEMI_ORGANIZZATI!Z8 -> 4.0527778 | H8: =STEMI_ORGANIZZATI!AD8 -> 5.0319444 | I8: =STEMI_ORGANIZZATI!AH8 -> 6.0270833 | J8: =STEMI_ORGANIZZATI!AL8 -> 7.0291667 | Q8: pat.4 | R8: =STEMI_ORGANIZZATI!G8 -> 0.189 | S8: =STEMI_ORGANIZZATI!K8 -> 0.468 | T8: =STEMI_ORGANIZZATI!O8 -> 0.322 | U8: =STEMI_ORGANIZZATI!S8 -> 0.232 | V8: =STEMI_ORGANIZZATI!W8 -> 0.24 | W8: =STEMI_ORGANIZZATI!AA8 -> 0.231 | X8: =STEMI_ORGANIZZATI!AE8 -> 0.199 | Y8: =STEMI_ORGANIZZATI!AI8 -> 0.146 | Z8: =STEMI_ORGANIZZATI!AM8 -> 0.11
A9: pat.5 | B9: =STEMI_ORGANIZZATI!F9 -> 0.035416667 | C9: =STEMI_ORGANIZZATI!J9 -> 0.16041667 | D9: =STEMI_ORGANIZZATI!N9 -> 0.46180556 | E9: =STEMI_ORGANIZZATI!R9 -> 1.4638889 | F9: =STEMI_ORGANIZZATI!V9 -> 2.4375 | G9: =STEMI_ORGANIZZATI!Z9 -> 3.4159722 | H9: =STEMI_ORGANIZZATI!AD9 -> 4.4298611 | Q9: pat.5 | R9: =STEMI_ORGANIZZATI!G9 -> 2.24 | S9: =STEMI_ORGANIZZATI!K9 -> 6.93 | T9: =STEMI_ORGANIZZATI!O9 -> 7.01 | U9: =STEMI_ORGANIZZATI!S9 -> 2.49 | V9: =STEMI_ORGANIZZATI!W9 -> 3.16 | W9: =STEMI_ORGANIZZATI!AA9 -> 3.82 | X9: =STEMI_ORGANIZZATI!AE9 -> 3.4
A10: pat.6 | B10: =STEMI_ORGANIZZATI!F10 -> 0.21458333 | C10: =STEMI_ORGANIZZATI!J10 -> 0.51527778 | D10: =STEMI_ORGANIZZATI!N10 -> 0.81111111 | E10: =STEMI_ORGANIZZATI!R10 -> 1.8638889 | F10: =STEMI_ORGANIZZATI!V10 -> 2.84375 | Q10: pat.6 | R10: =STEMI_ORGANIZZATI!G10 -> 0.345 | S10: =STEMI_ORGANIZZATI!K10 -> 1.3 | T10: =STEMI_ORGANIZZATI!O10 -> 0.893 | U10: =STEMI_ORGANIZZATI!S10 -> 0.759 | V10: =STEMI_ORGANIZZATI!W10 -> 1.02
A11: pat.7 | B11: =STEMI_ORGANIZZATI!F11 -> 0.21597222 | C11: =STEMI_ORGANIZZATI!J11 -> 0.39375 | D11: =STEMI_ORGANIZZATI!N11 -> 1.2319444 | E11: =STEMI_ORGANIZZATI!R11 -> 2.2902778 | F11: =STEMI_ORGANIZZATI!V11 -> 3.2770833 | G11: =STEMI_ORGANIZZATI!Z11 -> 4.2694444 | H11: =STEMI_ORGANIZZATI!AD11 -> 5.2715278 | Q11: pat.7 | R11: =STEMI_ORGANIZZATI!G11 -> 0.096 | S11: =STEMI_ORGANIZZATI!K11 -> 0.245 | T11: =STEMI_ORGANIZZATI!O11 -> 0.636 | U11: =STEMI_ORGANIZZATI!S11 -> 0.474 | V11: =STEMI_ORGANIZZATI!W11 -> 0.614 | W11: =STEMI_ORGANIZZATI!AA11 -> 0.628 | X11: =STEMI_ORGANIZZATI!AE11 -> 0.39
A12: pat.8 | B12: =STEMI_ORGANIZZATI!F12 -> 0.18263889 | C12: =STEMI_ORGANIZZATI!J12 -> 0.50347222 | D12: =STEMI_ORGANIZZATI!N12 -> 0.58819444 | E12: =STEMI_ORGANIZZATI!R12 -> 1.5944444 | F12: =STEMI_ORGANIZZATI!V12 -> 2.5763889 | G12: =STEMI_ORGANIZZATI!Z12 -> 3.5847222 | H12: =STEMI_ORGANIZZATI!AD12 -> 4.5986111 | Q12: pat.8 | R12: =STEMI_ORGANIZZATI!G12 -> 0.153 | S12: =STEMI_ORGANIZZATI!K12 -> 0.155 | T12: =STEMI_ORGANIZZATI!O12 -> 0.174 | U12: =STEMI_ORGANIZZATI!S12 -> 0.113 | V12: =STEMI_ORGANIZZATI!W12 -> 0.114 | W12: =STEMI_ORGANIZZATI!AA12 -> 0.142 | X12: =STEMI_ORGANIZZATI!AE12 -> 0.07
A13: pat.9 | B13: =STEMI_ORGANIZZATI!F13 -> 0.36319444 | C13: =STEMI_ORGANIZZATI!J13 -> 1.0847222 | D13: =STEMI_ORGANIZZATI!N13 -> 2.1180556 | Q13: pat.9 | R13: =STEMI_ORGANIZZATI!G13 -> 0.029 | S13: =STEMI_ORGANIZZATI!K13 -> 0.031 | T13: =STEMI_ORGANIZZATI!O13 -> 0.036
A14: pat.10 | B14: =STEMI_ORGANIZZATI!F14 -> 1.3493056 | C14: =STEMI_ORGANIZZATI!J14 -> 1.7930556 | D14: =STEMI_ORGANIZZATI!N14 -> 2.8263889 | E14: =STEMI_ORGANIZZATI!R14 -> 3.14375 | F14: =STEMI_ORGANIZZATI!V14 -> 3.7770833 | G14: =STEMI_ORGANIZZATI!Z14 -> 4.8138889 | Q14: pat.10 | R14: =STEMI_ORGANIZZATI!G14 -> 1.78 | S14: =STEMI_ORGANIZZATI!K14 -> 2.06 | T14: =STEMI_ORGANIZZATI!O14 -> 2.17 | U14: =STEMI_ORGANIZZATI!S14 -> 1.96 | V14: =STEMI_ORGANIZZATI!W14 -> 1.67 | W14: =STEMI_ORGANIZZATI!AA14 -> 1.06
A15: pat.11 | B15: =STEMI_ORGANIZZATI!F15 -> 0.20555556 | C15: =STEMI_ORGANIZZATI!J15 -> 0.36597222 | D15: =STEMI_ORGANIZZATI!N15 -> 0.79097222 | E15: =STEMI_ORGANIZZATI!R15 -> 1.8111111 | F15: =STEMI_ORGANIZZATI!V15 -> 2.8090278 | G15: =STEMI_ORGANIZZATI!Z15 -> 3.7736111 | Q15: pat.11 | R15: =STEMI_ORGANIZZATI!G15 -> 0.096 | S15: =STEMI_ORGANIZZATI!K15 -> 0.389 | T15: =STEMI_ORGANIZZATI!O15 -> 0.796 | U15: =STEMI_ORGANIZZATI!S15 -> 0.436 | V15: =STEMI_ORGANIZZATI!W15 -> 0.487 | W15: =STEMI_ORGANIZZATI!AA15 -> 0.521
A16: pat.12 | B16: =STEMI_ORGANIZZATI!F16 -> 0.30694444 | C16: =STEMI_ORGANIZZATI!J16 -> 0.65625 | D16: =STEMI_ORGANIZZATI!N16 -> 1.0638889 | E16: =STEMI_ORGANIZZATI!R16 -> 1.8034722 | F16: =STEMI_ORGANIZZATI!V16 -> 2.7673611 | G16: =STEMI_ORGANIZZATI!Z16 -> 3.7319444 | H16: =STEMI_ORGANIZZATI!AD16 -> 4.7888889 | I16: =STEMI_ORGANIZZATI!AH16 -> 6.7756944 | Q16: pat.12 | R16: =STEMI_ORGANIZZATI!G16 -> 18.24 | S16: =STEMI_ORGANIZZATI!K16 -> 11.91 | T16: =STEMI_ORGANIZZATI!O16 -> 8.33 | U16: =STEMI_ORGANIZZATI!S16 -> 6.01 | V16: =STEMI_ORGANIZZATI!W16 -> 5.64 | W16: =STEMI_ORGANIZZATI!AA16 -> 5.68 | X16: =STEMI_ORGANIZZATI!AE16 -> 5.45 | Y16: =STEMI_ORGANIZZATI!AI16 -> 2.07
A17: pat.13 | B17: =STEMI_ORGANIZZATI!F17 -> 0.99166667 | C17: =STEMI_ORGANIZZATI!J17 -> 0.99027778 | D17: =STEMI_ORGANIZZATI!N17 -> 1.2173611 | E17: =STEMI_ORGANIZZATI!R17 -> 1.7694444 | F17: =STEMI_ORGANIZZATI!V17 -> 2.7673611 | G17: =STEMI_ORGANIZZATI!Z17 -> 3.7111111 | H17: =STEMI_ORGANIZZATI!AD17 -> 4.7652778 | I17: =STEMI_ORGANIZZATI!AH17 -> 5.7805556 | J17: =STEMI_ORGANIZZATI!AL17 -> 5.7805556 | Q17: pat.13 | R17: =STEMI_ORGANIZZATI!G17 -> 3.87 | S17: =STEMI_ORGANIZZATI!K17 -> 3.87 | T17: =STEMI_ORGANIZZATI!O17 -> 2.9 | U17: =STEMI_ORGANIZZATI!S17 -> 3.1 | V17: =STEMI_ORGANIZZATI!W17 -> 2.38 | W17: =STEMI_ORGANIZZATI!AA17 -> 2.64 | X17: =STEMI_ORGANIZZATI!AE17 -> 2.49 | Y17: =STEMI_ORGANIZZATI!AI17 -> 0.01 | Z17: =STEMI_ORGANIZZATI!AM17 -> 2.03
A18: pat.14 | B18: =STEMI_ORGANIZZATI!F18 -> 0.56458333 | C18: =STEMI_ORGANIZZATI!J18 -> 0.77291667 | D18: =STEMI_ORGANIZZATI!N18 -> 1.1548611 | E18: =STEMI_ORGANIZZATI!R18 -> 1.6041667 | F18: =STEMI_ORGANIZZATI!V18 -> 2.1375 | G18: =STEMI_ORGANIZZATI!Z18 -> 3.1381944 | H18: =STEMI_ORGANIZZATI!AD18 -> 4.2034722 | I18: =STEMI_ORGANIZZATI!AH18 -> 5.1645833 | J18: =STEMI_ORGANIZZATI!AL18 -> 6.1715278 | K18: =STEMI_ORGANIZZATI!AP18 -> 7.1513889 | Q18: pat.14 | R18: =STEMI_ORGANIZZATI!G18 -> 2.83 | S18: =STEMI_ORGANIZZATI!K18 -> 4.1 | T18: =STEMI_ORGANIZZATI!O18 -> 2.44 | U18: =STEMI_ORGANIZZATI!S18 -> 1.68 | V18: =STEMI_ORGANIZZATI!W18 -> 2.16 | W18: =STEMI_ORGANIZZATI!AA18 -> 2.87 | X18: =STEMI_ORGANIZZATI!AE18 -> 2.09 | Y18: =STEMI_ORGANIZZATI!AI18 -> 0.992 | Z18: =STEMI_ORGANIZZATI!AM18 -> 0.451 | AA18: =STEMI_ORGANIZZATI!AQ18 -> 0.205
A19: pat.15 | B19: =STEMI_ORGANIZZATI!F19 -> 0.74722222 | C19: =STEMI_ORGANIZZATI!J19 -> 1.2729167 | D19: =STEMI_ORGANIZZATI!N19 -> 1.6159722 | E19: =STEMI_ORGANIZZATI!R19 -> 2.6375 | F19: =STEMI_ORGANIZZATI!V19 -> 3.0104167 | G19: =STEMI_ORGANIZZATI!Z19 -> 3.6479167 | H19: =STEMI_ORGANIZZATI!AD19 -> 5.6770833 | Q19: pat.15 | R19: =STEMI_ORGANIZZATI!G19 -> 1.44 | S19: =STEMI_ORGANIZZATI!K19 -> 2.01 | T19: =STEMI_ORGANIZZATI!O19 -> 1.7 | U19: =STEMI_ORGANIZZATI!S19 -> 1.89 | V19: =STEMI_ORGANIZZATI!W19 -> 1.72 | W19: =STEMI_ORGANIZZATI!AA19 -> 1.69 | X19: =STEMI_ORGANIZZATI!AE19 -> 0.731
A20: pat.16 | B20: =STEMI_ORGANIZZATI!F20 -> 0.48611111 | C20: =STEMI_ORGANIZZATI!J20 -> 0.50625 | D20: =STEMI_ORGANIZZATI!N20 -> 0.80625 | E20: =STEMI_ORGANIZZATI!R20 -> 1.3548611 | F20: =STEMI_ORGANIZZATI!V20 -> 2.35625 | G20: =STEMI_ORGANIZZATI!Z20 -> 3.3826389 | H20: =STEMI_ORGANIZZATI!AD20 -> 4.3729167 | I20: =STEMI_ORGANIZZATI!AH20 -> 5.3236111 | J20: =STEMI_ORGANIZZATI!AL20 -> 7.4284722 | K20: =STEMI_ORGANIZZATI!AP20 -> 8.3680556 | Q20: pat.16 | R20: =STEMI_ORGANIZZATI!G20 -> 3.94 | S20: =STEMI_ORGANIZZATI!K20 -> 10 | T20: =STEMI_ORGANIZZATI!O20 -> 10.68 | U20: =STEMI_ORGANIZZATI!S20 -> 7.18 | V20: =STEMI_ORGANIZZATI!W20 -> 4.98 | W20: =STEMI_ORGANIZZATI!AA20 -> 5.1 | X20: =STEMI_ORGANIZZATI!AE20 -> 4.45 | Y20: =STEMI_ORGANIZZATI!AI20 -> 3.22 | Z20: =STEMI_ORGANIZZATI!AM20 -> 1.25 | AA20: =STEMI_ORGANIZZATI!AQ20 -> 0.744
A21: pat.17 | B21: =STEMI_ORGANIZZATI!F21 -> 0.375 | C21: =STEMI_ORGANIZZATI!J21 -> 0.85069444 | D21: =STEMI_ORGANIZZATI!N21 -> 1.3583333 | E21: =STEMI_ORGANIZZATI!R21 -> 2.35625 | F21: =STEMI_ORGANIZZATI!V21 -> 3.4118056 | G21: =STEMI_ORGANIZZATI!Z21 -> 4.375 | H21: =STEMI_ORGANIZZATI!AD21 -> 5.3194444 | I21: =STEMI_ORGANIZZATI!AH21 -> 6.3548611 | Q21: pat.17 | R21: =STEMI_ORGANIZZATI!G21 -> 7.01 | S21: =STEMI_ORGANIZZATI!K21 -> 5.27 | T21: =STEMI_ORGANIZZATI!O21 -> 4.95 | U21: =STEMI_ORGANIZZATI!S21 -> 3.43 | V21: =STEMI_ORGANIZZATI!W21 -> 4.01 | W21: =STEMI_ORGANIZZATI!AA21 -> 4.7 | X21: =STEMI_ORGANIZZATI!AE21 -> 3.72 | Y21: =STEMI_ORGANIZZATI!AI21 -> 3.06
A22: pat.18 | B22: =STEMI_ORGANIZZATI!F22 -> 0.74861111 | C22: =STEMI_ORGANIZZATI!J22 -> 0.86527778 | D22: =STEMI_ORGANIZZATI!N22 -> 1.3625 | E22: =STEMI_ORGANIZZATI!R22 -> 2.4118056 | F22: =STEMI_ORGANIZZATI!V22 -> 3.3729167 | G22: =STEMI_ORGANIZZATI!Z22 -> 4.3270833 | H22: =STEMI_ORGANIZZATI!AD22 -> 5.3548611 | I22: =STEMI_ORGANIZZATI!AH22 -> 6.3881944 | J22: =STEMI_ORGANIZZATI!AL22 -> 7.3354167 | K22: =STEMI_ORGANIZZATI!AP22 -> 7.9361111 | L22: =STEMI_ORGANIZZATI!AT22 -> 8.3479167 | M22: =STEMI_ORGANIZZATI!AX22 -> 8.7145833 | N22: =STEMI_ORGANIZZATI!BB22 -> 10.351389 | O22: =STEMI_ORGANIZZATI!BF22 -> 11.355556 | Q22: pat.18 | R22: =STEMI_ORGANIZZATI!G22 -> 11.24 | S22: =STEMI_ORGANIZZATI!K22 -> 7.79 | T22: =STEMI_ORGANIZZATI!O22 -> 5.03 | U22: =STEMI_ORGANIZZATI!S22 -> 2.84 | V22: =STEMI_ORGANIZZATI!W22 -> 3.69 | W22: =STEMI_ORGANIZZATI!AA22 -> 4.56 | X22: =STEMI_ORGANIZZATI!AE22 -> 3.98 | Y22: =STEMI_ORGANIZZATI!AI22 -> 2.27 | Z22: =STEMI_ORGANIZZATI!AM22 -> 1.65 | AA22: =STEMI_ORGANIZZATI!AQ22 -> 1.5 | AB22: =STEMI_ORGANIZZATI!AU22 -> 1.3 | AC22: =STEMI_ORGANIZZATI!AY22 -> 1.16 | AD22: =STEMI_ORGANIZZATI!BC22 -> 0.711 | AE22: =STEMI_ORGANIZZATI!BG22 -> 0.54
A23: pat.19 | B23: =STEMI_ORGANIZZATI!F23 -> 0.45138889 | C23: =STEMI_ORGANIZZATI!J23 -> 0.6125 | D23: =STEMI_ORGANIZZATI!N23 -> 0.95555556 | E23: =STEMI_ORGANIZZATI!R23 -> 2.9597222 | F23: =STEMI_ORGANIZZATI!V23 -> 3.9472222 | G23: =STEMI_ORGANIZZATI!Z23 -> 4.9548611 | H23: =STEMI_ORGANIZZATI!AD23 -> 5.9965278 | Q23: pat.19 | R23: =STEMI_ORGANIZZATI!G23 -> 28.39 | S23: =STEMI_ORGANIZZATI!K23 -> 15.65 | T23: =STEMI_ORGANIZZATI!O23 -> 9.97 | U23: =STEMI_ORGANIZZATI!S23 -> 2.66 | V23: =STEMI_ORGANIZZATI!W23 -> 2.27 | W23: =STEMI_ORGANIZZATI!AA23 -> 1.76 | X23: =STEMI_ORGANIZZATI!AE23 -> 1.46
A24: pat.20 | B24: =STEMI_ORGANIZZATI!F24 -> 1.6236111 | C24: =STEMI_ORGANIZZATI!J24 -> 1.8333333 | D24: =STEMI_ORGANIZZATI!N24 -> 2.49375 | E24: =STEMI_ORGANIZZATI!R24 -> 3.4034722 | F24: =STEMI_ORGANIZZATI!V24 -> 4.38125 | G24: =STEMI_ORGANIZZATI!Z24 -> 5.4340278 | H24: =STEMI_ORGANIZZATI!AD24 -> 5.79375 | I24: =STEMI_ORGANIZZATI!AH24 -> 6.4666667 | J24: =STEMI_ORGANIZZATI!AL24 -> 7.46875 | K24: =STEMI_ORGANIZZATI!AP24 -> 8.4479167 | Q24: pat.20 | R24: =STEMI_ORGANIZZATI!G24 -> 5.74 | S24: =STEMI_ORGANIZZATI!K24 -> 8.74 | T24: =STEMI_ORGANIZZATI!O24 -> 3.3 | U24: =STEMI_ORGANIZZATI!S24 -> 3.26 | V24: =STEMI_ORGANIZZATI!W24 -> 3.36 | W24: =STEMI_ORGANIZZATI!AA24 -> 3.01 | X24: =STEMI_ORGANIZZATI!AE24 -> 2.57 | Y24: =STEMI_ORGANIZZATI!AI24 -> 1.29 | Z24: =STEMI_ORGANIZZATI!AM24 -> 0.579 | AA24: =STEMI_ORGANIZZATI!AQ24 -> 0.305
A26: PAZIENTI CON DATE DI ACQUISIZIONE CORRETTE (in decimali)
A27: INTERVALLO TEMPORALE TRA UN'ACQUISIZIONE E L'EVENTO
A28: PAZIENTE
A29: pat.1 | B29: =STEMI_ORGANIZZATI!F5*24 -> 66.116667 | C29: =STEMI_ORGANIZZATI!N5*24 -> 69.416667 | D29: =STEMI_ORGANIZZATI!R5*24 -> 93.966667 | E29: =STEMI_ORGANIZZATI!V5*24 -> 134.11667
A30: pat.2 | B30: =STEMI_ORGANIZZATI!F6*24 -> 4.7333333 | C30: =STEMI_ORGANIZZATI!N6*24 -> 12.9 | D30: =STEMI_ORGANIZZATI!R6*24 -> 14.566667 | E30: =STEMI_ORGANIZZATI!V6*24 -> 39.366667 | F30: =STEMI_ORGANIZZATI!Z6*24 -> 63.583333 | G30: =STEMI_ORGANIZZATI!AD6*24 -> 72.916667 | H30: =STEMI_ORGANIZZATI!AH6*24 -> 87.9 | I30: =STEMI_ORGANIZZATI!AL6*24 -> 111.45 | J30: =STEMI_ORGANIZZATI!AP6*24 -> 134.48333 | K30: =STEMI_ORGANIZZATI!AT6*24 -> 158.93333 | L30: =STEMI_ORGANIZZATI!AX6*24 -> 184.83333
A31: pat.3 | B31: =STEMI_ORGANIZZATI!F7*24 -> 6 | C31: =STEMI_ORGANIZZATI!J7*24 -> 10.466667 | D31: =STEMI_ORGANIZZATI!N7*24 -> 18.933333 | E31: =STEMI_ORGANIZZATI!R7*24 -> 43.466667 | F31: =STEMI_ORGANIZZATI!V7*24 -> 67.416667 | G31: =STEMI_ORGANIZZATI!Z7*24 -> 92.583333 | H31: =STEMI_ORGANIZZATI!AD7*24 -> 116.2 | I31: =STEMI_ORGANIZZATI!AH7*24 -> 164.1
A32: pat.4 | B32: =STEMI_ORGANIZZATI!F8*24 -> 5.0666667 | C32: =STEMI_ORGANIZZATI!J8*24 -> 10.316667 | D32: =STEMI_ORGANIZZATI!N8*24 -> 22.833333 | E32: =STEMI_ORGANIZZATI!R8*24 -> 48.116667 | F32: =STEMI_ORGANIZZATI!V8*24 -> 72.083333 | G32: =STEMI_ORGANIZZATI!Z8*24 -> 97.266667 | H32: =STEMI_ORGANIZZATI!AD8*24 -> 120.76667 | I32: =STEMI_ORGANIZZATI!AH8*24 -> 144.65 | J32: =STEMI_ORGANIZZATI!AL8*24 -> 168.7
A33: pat.5 | B33: =STEMI_ORGANIZZATI!F9*24 -> 0.85 | C33: =STEMI_ORGANIZZATI!J9*24 -> 3.85 | D33: =STEMI_ORGANIZZATI!N9*24 -> 11.083333 | E33: =STEMI_ORGANIZZATI!R9*24 -> 35.133333 | F33: =STEMI_ORGANIZZATI!V9*24 -> 58.5 | G33: =STEMI_ORGANIZZATI!Z9*24 -> 81.983333 | H33: =STEMI_ORGANIZZATI!AD9*24 -> 106.31667
A34: pat.6 | B34: =STEMI_ORGANIZZATI!F10*24 -> 5.15 | C34: =STEMI_ORGANIZZATI!J10*24 -> 12.366667 | D34: =STEMI_ORGANIZZATI!N10*24 -> 19.466667 | E34: =STEMI_ORGANIZZATI!R10*24 -> 44.733333 | F34: =STEMI_ORGANIZZATI!V10*24 -> 68.25
A35: pat.7 | B35: =STEMI_ORGANIZZATI!F11*24 -> 5.1833333 | C35: =STEMI_ORGANIZZATI!J11*24 -> 9.45 | D35: =STEMI_ORGANIZZATI!N11*24 -> 29.566667 | E35: =STEMI_ORGANIZZATI!R11*24 -> 54.966667 | F35: =STEMI_ORGANIZZATI!V11*24 -> 78.65 | G35: =STEMI_ORGANIZZATI!Z11*24 -> 102.46667 | H35: =STEMI_ORGANIZZATI!AD11*24 -> 126.51667
A36: pat.8 | B36: =STEMI_ORGANIZZATI!F12*24 -> 4.3833333 | C36: =STEMI_ORGANIZZATI!J12*24 -> 12.083333 | D36: =STEMI_ORGANIZZATI!N12*24 -> 14.116667 | E36: =STEMI_ORGANIZZATI!R12*24 -> 38.266667 | F36: =STEMI_ORGANIZZATI!V12*24 -> 61.833333 | G36: =STEMI_ORGANIZZATI!Z12*24 -> 86.033333 | H36: =STEMI_ORGANIZZATI!AD12*24 -> 110.36667
A37: pat.9 | B37: =STEMI_ORGANIZZATI!F13*24 -> 8.7166667 | C37: =STEMI_ORGANIZZATI!J13*24 -> 26.033333 | D37: =STEMI_ORGANIZZATI!N13*24 -> 50.833333
A38: pat.10 | B38: =STEMI_ORGANIZZATI!F14*24 -> 32.383333 | C38: =STEMI_ORGANIZZATI!J14*24 -> 43.033333 | D38: =STEMI_ORGANIZZATI!N14*24 -> 67.833333 | E38: =STEMI_ORGANIZZATI!R14*24 -> 75.45 | F38: =STEMI_ORGANIZZATI!V14*24 -> 90.65 | G38: =STEMI_ORGANIZZATI!Z14*24 -> 115.53333
A39: pat.11 | B39: =STEMI_ORGANIZZATI!F15*24 -> 4.9333333 | C39: =STEMI_ORGANIZZATI!J15*24 -> 8.7833333 | D39: =STEMI_ORGANIZZATI!N15*24 -> 18.983333 | E39: =STEMI_ORGANIZZATI!R15*24 -> 43.466667 | F39: =STEMI_ORGANIZZATI!V15*24 -> 67.416667 | G39: =STEMI_ORGANIZZATI!Z15*24 -> 90.566667
A40: pat.12 | B40: =STEMI_ORGANIZZATI!F16*24 -> 7.3666667 | C40: =STEMI_ORGANIZZATI!J16*24 -> 15.75 | D40: =STEMI_ORGANIZZATI!N16*24 -> 25.533333 | E40: =STEMI_ORGANIZZATI!R16*24 -> 43.283333 | F40: =STEMI_ORGANIZZATI!V16*24 -> 66.416667 | G40: =STEMI_ORGANIZZATI!Z16*24 -> 89.566667 | H40: =STEMI_ORGANIZZATI!AD16*24 -> 114.93333 | I40: =STEMI_ORGANIZZATI!AH16*24 -> 162.61667
A41: pat.13 | B41: =STEMI_ORGANIZZATI!F17*24 -> 23.8 | C41: =STEMI_ORGANIZZATI!J17*24 -> 23.766667 | D41: =STEMI_ORGANIZZATI!N17*24 -> 29.216667 | E41: =STEMI_ORGANIZZATI!R17*24 -> 42.466667 | F41: =STEMI_ORGANIZZATI!V17*24 -> 66.416667 | G41: =STEMI_ORGANIZZATI!Z17*24 -> 89.066667 | H41: =STEMI_ORGANIZZATI!AD17*24 -> 114.36667 | I41: =STEMI_ORGANIZZATI!AH17*24 -> 138.73333 | J41: =STEMI_ORGANIZZATI!AL17*24 -> 138.73333
...

Sheet STEMI_ANALIZZATI
A1: PAZIENTE | B1: Pat.1 | H1: PAZIENTE | I1: Pat.11
A2: TEMPO | B2: =STEMI_TEMPO_ACQUISIZIONE!B5 -> 2.7548611 | C2: =STEMI_TEMPO_ACQUISIZIONE!D5 -> 2.8923611 | D2: =STEMI_TEMPO_ACQUISIZIONE!E5 -> 3.9152778 | E2: =STEMI_TEMPO_ACQUISIZIONE!F5 -> 5.5881944 | H2: TEMPO | I2: =STEMI_TEMPO_ACQUISIZIONE!B15 -> 0.20555556 | J2: =STEMI_TEMPO_ACQUISIZIONE!C15 -> 0.36597222 | K2: =STEMI_TEMPO_ACQUISIZIONE!D15 -> 0.79097222 | L2: =STEMI_TEMPO_ACQUISIZIONE!E15 -> 1.8111111 | M2: =STEMI_TEMPO_ACQUISIZIONE!F15 -> 2.8090278 | N2: =STEMI_TEMPO_ACQUISIZIONE!G15 -> 3.7736111
A3: ACQUISIZIONE | B3: =STEMI_TEMPO_ACQUISIZIONE!R5 -> 0.814 | C3: =STEMI_TEMPO_ACQUISIZIONE!S5 -> 0.967 | D3: =STEMI_TEMPO_ACQUISIZIONE!T5 -> 0.848 | E3: =STEMI_TEMPO_ACQUISIZIONE!U5 -> 0.909 | H3: ACQUISIZIONE | I3: =STEMI_TEMPO_ACQUISIZIONE!R15 -> 0.096 | J3: =STEMI_TEMPO_ACQUISIZIONE!S15 -> 0.389 | K3: =STEMI_TEMPO_ACQUISIZIONE!T15 -> 0.796 | L3: =STEMI_TEMPO_ACQUISIZIONE!U15 -> 0.436 | M3: =STEMI_TEMPO_ACQUISIZIONE!V15 -> 0.487 | N3: =STEMI_TEMPO_ACQUISIZIONE!W15 -> 0.521
A19: PAZIENTE | B19: Pat.2 | O19: PAZIENTE | P19: Pat.12
A20: TEMPO | B20: =STEMI_TEMPO_ACQUISIZIONE!B6 -> 0.19722222 | C20: =STEMI_TEMPO_ACQUISIZIONE!D6 -> 0.5375 | D20: =STEMI_TEMPO_ACQUISIZIONE!E6 -> 0.60694444 | E20: =STEMI_TEMPO_ACQUISIZIONE!F6 -> 1.6402778 | F20: =STEMI_TEMPO_ACQUISIZIONE!G6 -> 2.6493056 | G20: =STEMI_TEMPO_ACQUISIZIONE!H6 -> 3.0381944 | H20: =STEMI_TEMPO_ACQUISIZIONE!I6 -> 3.6625 | I20: =STEMI_TEMPO_ACQUISIZIONE!J6 -> 4.64375 | J20: =STEMI_TEMPO_ACQUISIZIONE!K6 -> 5.6034722 | ... L20: =STEMI_TEMPO_ACQUISIZIONE!M6 -> 7.7013889 | O20: TEMPO | P20: =STEMI_TEMPO_ACQUISIZIONE!B16 -> 0.30694444 | Q20: =STEMI_TEMPO_ACQUISIZIONE!C16 -> 0.65625 | R20: =STEMI_TEMPO_ACQUISIZIONE!D16 -> 1.0638889 | S20: =STEMI_TEMPO_ACQUISIZIONE!E16 -> 1.8034722 | T20: =STEMI_TEMPO_ACQUISIZIONE!F16 -> 2.7673611 | U20: =STEMI_TEMPO_ACQUISIZIONE!G16 -> 3.7319444 | V20: =STEMI_TEMPO_ACQUISIZIONE!H16 -> 4.7888889 | W20: =STEMI_TEMPO_ACQUISIZIONE!I16 -> 6.7756944
A21: ACQUISIZIONE | B21: =STEMI_TEMPO_ACQUISIZIONE!R6 -> 0.098 | C21: =STEMI_TEMPO_ACQUISIZIONE!S6 -> 0.13 | D21: =STEMI_TEMPO_ACQUISIZIONE!T6 -> 0.131 | E21: =STEMI_TEMPO_ACQUISIZIONE!U6 -> 0.163 | F21: =STEMI_TEMPO_ACQUISIZIONE!V6 -> 0.15 | G21: =STEMI_TEMPO_ACQUISIZIONE!W6 -> 0.147 | H21: =STEMI_TEMPO_ACQUISIZIONE!X6 -> 0.178 | I21: =STEMI_TEMPO_ACQUISIZIONE!Y6 -> 0.181 | ... L21: =STEMI_TEMPO_ACQUISIZIONE!AB6 -> 0.094 | O21: ACQUISIZIONE | P21: =STEMI_TEMPO_ACQUISIZIONE!R16 -> 18.24 | Q21: =STEMI_TEMPO_ACQUISIZIONE!S16 -> 11.91 | R21: =STEMI_TEMPO_ACQUISIZIONE!T16 -> 8.33 | S21: =STEMI_TEMPO_ACQUISIZIONE!U16 -> 6.01 | T21: =STEMI_TEMPO_ACQUISIZIONE!V16 -> 5.64 | U21: =STEMI_TEMPO_ACQUISIZIONE!W16 -> 5.68 | V21: =STEMI_TEMPO_ACQUISIZIONE!X16 -> 5.45 | W21: =STEMI_TEMPO_ACQUISIZIONE!Y16 -> 2.07
A37: PAZIENTE | B37: Pat.3
A38: TEMPO | B38: =STEMI_TEMPO_ACQUISIZIONE!B7 -> 0.25 | C38: =STEMI_TEMPO_ACQUISIZIONE!C7 -> 0.43611111 | D38: =STEMI_TEMPO_ACQUISIZIONE!D7 -> 0.78888889 | E38: =STEMI_TEMPO_ACQUISIZIONE!E7 -> 1.8111111 | F38: =STEMI_TEMPO_ACQUISIZIONE!F7 -> 2.8090278 | G38: =STEMI_TEMPO_ACQUISIZIONE!G7 -> 3.8576389 | H38: =STEMI_TEMPO_ACQUISIZIONE!H7 -> 4.8416667 | I38: =STEMI_TEMPO_ACQUISIZIONE!I7 -> 6.8375 | K38: PAZIENTE | L38: Pat.13
A39: ACQUISIZIONE | B39: =STEMI_TEMPO_ACQUISIZIONE!R7 -> 12.9 | C39: =STEMI_TEMPO_ACQUISIZIONE!S7 -> 6.94 | D39: =STEMI_TEMPO_ACQUISIZIONE!T7 -> 4.58 | E39: =STEMI_TEMPO_ACQUISIZIONE!U7 -> 2.93 | F39: =STEMI_TEMPO_ACQUISIZIONE!V7 -> 4.08 | G39: =STEMI_TEMPO_ACQUISIZIONE!W7 -> 3.72 | H39: =STEMI_TEMPO_ACQUISIZIONE!X7 -> 2.41 | I39: =STEMI_TEMPO_ACQUISIZIONE!Y7 -> 0.674 | K39: TEMPO | L39: =STEMI_TEMPO_ACQUISIZIONE!B17 -> 0.99166667 | M39: =STEMI_TEMPO_ACQUISIZIONE!C17 -> 0.99027778 | N39: =STEMI_TEMPO_ACQUISIZIONE!D17 -> 1.2173611 | O39: =STEMI_TEMPO_ACQUISIZIONE!E17 -> 1.7694444 | P39: =STEMI_TEMPO_ACQUISIZIONE!F17 -> 2.7673611 | Q39: =STEMI_TEMPO_ACQUISIZIONE!G17 -> 3.7111111 | R39: =STEMI_TEMPO_ACQUISIZIONE!H17 -> 4.7652778 | S39: =STEMI_TEMPO_ACQUISIZIONE!I17 -> 5.7805556 | T39: =STEMI_TEMPO_ACQUISIZIONE!J17 -> 5.7805556
K40: ACQUISIZIONE | L40: =STEMI_TEMPO_ACQUISIZIONE!R17 -> 3.87 | M40: =STEMI_TEMPO_ACQUISIZIONE!S17 -> 3.87 | N40: =STEMI_TEMPO_ACQUISIZIONE!T17 -> 2.9 | O40: =STEMI_TEMPO_ACQUISIZIONE!U17 -> 3.1 | P40: =STEMI_TEMPO_ACQUISIZIONE!V17 -> 2.38 | Q40: =STEMI_TEMPO_ACQUISIZIONE!W17 -> 2.64 | R40: =STEMI_TEMPO_ACQUISIZIONE!X17 -> 2.49 | S40: =STEMI_TEMPO_ACQUISIZIONE!Y17 -> 0.01 | T40: =STEMI_TEMPO_ACQUISIZIONE!Z17 -> 2.03
A55: PAZIENTE | B55: Pat.4 | L55: PAZIENTE | M55: Pat.14
A56: TEMPO | B56: =STEMI_TEMPO_ACQUISIZIONE!B8 -> 0.21111111 | C56: =STEMI_TEMPO_ACQUISIZIONE!C8 -> 0.42986111 | D56: =STEMI_TEMPO_ACQUISIZIONE!D8 -> 0.95138889 | E56: =STEMI_TEMPO_ACQUISIZIONE!E8 -> 2.0048611 | F56: =STEMI_TEMPO_ACQUISIZIONE!F8 -> 3.0034722 | G56: =STEMI_TEMPO_ACQUISIZIONE!G8 -> 4.0527778 | H56: =STEMI_TEMPO_ACQUISIZIONE!H8 -> 5.0319444 | I56: =STEMI_TEMPO_ACQUISIZIONE!I8 -> 6.0270833 | J56: =STEMI_TEMPO_ACQUISIZIONE!J8 -> 7.0291667 | L56: TEMPO | M56: =STEMI_TEMPO_ACQUISIZIONE!B18 -> 0.56458333 | N56: =STEMI_TEMPO_ACQUISIZIONE!C18 -> 0.77291667 | O56: =STEMI_TEMPO_ACQUISIZIONE!D18 -> 1.1548611 | P56: =STEMI_TEMPO_ACQUISIZIONE!E18 -> 1.6041667 | Q56: =STEMI_TEMPO_ACQUISIZIONE!F18 -> 2.1375 | R56: =STEMI_TEMPO_ACQUISIZIONE!G18 -> 3.1381944 | S56: =STEMI_TEMPO_ACQUISIZIONE!H18 -> 4.2034722 | T56: =STEMI_TEMPO_ACQUISIZIONE!I18 -> 5.1645833 | ... V56: =STEMI_TEMPO_ACQUISIZIONE!K18 -> 7.1513889
A57: ACQUISIZIONE | B57: =STEMI_TEMPO_ACQUISIZIONE!R8 -> 0.189 | C57: =STEMI_TEMPO_ACQUISIZIONE!S8 -> 0.468 | D57: =STEMI_TEMPO_ACQUISIZIONE!T8 -> 0.322 | E57: =STEMI_TEMPO_ACQUISIZIONE!U8 -> 0.232 | F57: =STEMI_TEMPO_ACQUISIZIONE!V8 -> 0.24 | G57: =STEMI_TEMPO_ACQUISIZIONE!W8 -> 0.231 | H57: =STEMI_TEMPO_ACQUISIZIONE!X8 -> 0.199 | I57: =STEMI_TEMPO_ACQUISIZIONE!Y8 -> 0.146 | J57: =STEMI_TEMPO_ACQUISIZIONE!Z8 -> 0.11 | L57: ACQUISIZIONE | M57: =STEMI_TEMPO_ACQUISIZIONE!R18 -> 2.83 | N57: =STEMI_TEMPO_ACQUISIZIONE!S18 -> 4.1 | O57: =STEMI_TEMPO_ACQUISIZIONE!T18 -> 2.44 | P57: =STEMI_TEMPO_ACQUISIZIONE!U18 -> 1.68 | Q57: =STEMI_TEMPO_ACQUISIZIONE!V18 -> 2.16 | R57: =STEMI_TEMPO_ACQUISIZIONE!W18 -> 2.87 | S57: =STEMI_TEMPO_ACQUISIZIONE!X18 -> 2.09 | T57: =STEMI_TEMPO_ACQUISIZIONE!Y18 -> 0.992 | ... V57: =STEMI_TEMPO_ACQUISIZIONE!AA18 -> 0.205
A73: PAZIENTE | B73: Pat.5 | L73: PAZIENTE | M73: Pat.15
A74: TEMPO | B74: =STEMI_TEMPO_ACQUISIZIONE!B9 -> 0.035416667 | C74: =STEMI_TEMPO_ACQUISIZIONE!C9 -> 0.16041667 | D74: =STEMI_TEMPO_ACQUISIZIONE!D9 -> 0.46180556 | E74: =STEMI_TEMPO_ACQUISIZIONE!E9 -> 1.4638889 | F74: =STEMI_TEMPO_ACQUISIZIONE!F9 -> 2.4375 | G74: =STEMI_TEMPO_ACQUISIZIONE!G9 -> 3.4159722 | H74: =STEMI_TEMPO_ACQUISIZIONE!H9 -> 4.4298611 | L74: TEMPO | M74: =STEMI_TEMPO_ACQUISIZIONE!B19 -> 0.74722222 | N74: =STEMI_TEMPO_ACQUISIZIONE!C19 -> 1.2729167 | O74: =STEMI_TEMPO_ACQUISIZIONE!D19 -> 1.6159722 | P74: =STEMI_TEMPO_ACQUISIZIONE!E19 -> 2.6375 | Q74: =STEMI_TEMPO_ACQUISIZIONE!F19 -> 3.0104167 | R74: =STEMI_TEMPO_ACQUISIZIONE!G19 -> 3.6479167 | S74: =STEMI_TEMPO_ACQUISIZIONE!H19 -> 5.6770833
A75: ACQUISIZIONE | B75: =STEMI_TEMPO_ACQUISIZIONE!R9 -> 2.24 | C75: =STEMI_TEMPO_ACQUISIZIONE!S9 -> 6.93 | D75: =STEMI_TEMPO_ACQUISIZIONE!T9 -> 7.01 | E75: =STEMI_TEMPO_ACQUISIZIONE!U9 -> 2.49 | F75: =STEMI_TEMPO_ACQUISIZIONE!V9 -> 3.16 | G75: =STEMI_TEMPO_ACQUISIZIONE!W9 -> 3.82 | H75: =STEMI_TEMPO_ACQUISIZIONE!X9 -> 3.4 | L75: ACQUISIZIONE | M75: =STEMI_TEMPO_ACQUISIZIONE!R19 -> 1.44 | N75: =STEMI_TEMPO_ACQUISIZIONE!S19 -> 2.01 | O75: =STEMI_TEMPO_ACQUISIZIONE!T19 -> 1.7 | P75: =STEMI_TEMPO_ACQUISIZIONE!U19 -> 1.89 | Q75: =STEMI_TEMPO_ACQUISIZIONE!V19 -> 1.72 | R75: =STEMI_TEMPO_ACQUISIZIONE!W19 -> 1.69 | S75: =STEMI_TEMPO_ACQUISIZIONE!X19 -> 0.731
A91: PAZIENTE | B91: Pat.6
A92: TEMPO | B92: =STEMI_TEMPO_ACQUISIZIONE!B10 -> 0.21458333 | C92: =STEMI_TEMPO_ACQUISIZIONE!C10 -> 0.51527778 | D92: =STEMI_TEMPO_ACQUISIZIONE!D10 -> 0.81111111 | E92: =STEMI_TEMPO_ACQUISIZIONE!E10 -> 1.8638889 | F92: =STEMI_TEMPO_ACQUISIZIONE!F10 -> 2.84375 | J92: PAZIENTE | K92: Pat.16
A93: ACQUISIZIONE | B93: =STEMI_TEMPO_ACQUISIZIONE!R10 -> 0.345 | C93: =STEMI_TEMPO_ACQUISIZIONE!S10 -> 1.3 | D93: =STEMI_TEMPO_ACQUISIZIONE!T10 -> 0.893 | E93: =STEMI_TEMPO_ACQUISIZIONE!U10 -> 0.759 | F93: =STEMI_TEMPO_ACQUISIZIONE!V10 -> 1.02 | J93: TEMPO | K93: =STEMI_TEMPO_ACQUISIZIONE!B20 -> 0.48611111 | L93: =STEMI_TEMPO_ACQUISIZIONE!C20 -> 0.50625 | M93: =STEMI_TEMPO_ACQUISIZIONE!D20 -> 0.80625 | N93: =STEMI_TEMPO_ACQUISIZIONE!E20 -> 1.3548611 | O93: =STEMI_TEMPO_ACQUISIZIONE!F20 -> 2.35625 | P93: =STEMI_TEMPO_ACQUISIZIONE!G20 -> 3.3826389 | Q93: =STEMI_TEMPO_ACQUISIZIONE!H20 -> 4.3729167 | R93: =STEMI_TEMPO_ACQUISIZIONE!I20 -> 5.3236111 | ... T93: =STEMI_TEMPO_ACQUISIZIONE!K20 -> 8.3680556
J94: ACQUISIZIONE | K94: =STEMI_TEMPO_ACQUISIZIONE!R20 -> 3.94 | L94: =STEMI_TEMPO_ACQUISIZIONE!S20 -> 10 | M94: =STEMI_TEMPO_ACQUISIZIONE!T20 -> 10.68 | N94: =STEMI_TEMPO_ACQUISIZIONE!U20 -> 7.18 | O94: =STEMI_TEMPO_ACQUISIZIONE!V20 -> 4.98 | P94: =STEMI_TEMPO_ACQUISIZIONE!W20 -> 5.1 | Q94: =STEMI_TEMPO_ACQUISIZIONE!X20 -> 4.45 | R94: =STEMI_TEMPO_ACQUISIZIONE!Y20 -> 3.22 | ... T94: =STEMI_TEMPO_ACQUISIZIONE!AA20 -> 0.744
A109: PAZIENTE | B109: Pat.7
A110: TEMPO | B110: =STEMI_TEMPO_ACQUISIZIONE!B11 -> 0.21597222 | C110: =STEMI_TEMPO_ACQUISIZIONE!C11 -> 0.39375 | D110: =STEMI_TEMPO_ACQUISIZIONE!D11 -> 1.2319444 | E110: =STEMI_TEMPO_ACQUISIZIONE!E11 -> 2.2902778 | F110: =STEMI_TEMPO_ACQUISIZIONE!F11 -> 3.2770833 | G110: =STEMI_TEMPO_ACQUISIZIONE!G11 -> 4.2694444 | H110: =STEMI_TEMPO_ACQUISIZIONE!H11 -> 5.2715278 | J110: PAZIENTE | K110: Pat.17
A111: ACQUISIZIONE | B111: =STEMI_TEMPO_ACQUISIZIONE!R11 -> 0.096 | C111: =STEMI_TEMPO_ACQUISIZIONE!S11 -> 0.245 | D111: =STEMI_TEMPO_ACQUISIZIONE!T11 -> 0.636 | E111: =STEMI_TEMPO_ACQUISIZIONE!U11 -> 0.474 | F111: =STEMI_TEMPO_ACQUISIZIONE!V11 -> 0.614 | G111: =STEMI_TEMPO_ACQUISIZIONE!W11 -> 0.628 | H111: =STEMI_TEMPO_ACQUISIZIONE!X11 -> 0.39 | J111: TEMPO | K111: =STEMI_TEMPO_ACQUISIZIONE!B21 -> 0.375 | L111: =STEMI_TEMPO_ACQUISIZIONE!C21 -> 0.85069444 | M111: =STEMI_TEMPO_ACQUISIZIONE!D21 -> 1.3583333 | N111: =STEMI_TEMPO_ACQUISIZIONE!E21 -> 2.35625 | O111: =STEMI_TEMPO_ACQUISIZIONE!F21 -> 3.4118056 | P111: =STEMI_TEMPO_ACQUISIZIONE!G21 -> 4.375 | Q111: =STEMI_TEMPO_ACQUISIZIONE!H21 -> 5.3194444 | R111: =STEMI_TEMPO_ACQUISIZIONE!I21 -> 6.3548611
J112: ACQUISIZIONE | K112: =STEMI_TEMPO_ACQUISIZIONE!R21 -> 7.01 | L112: =STEMI_TEMPO_ACQUISIZIONE!S21 -> 5.27 | M112: =STEMI_TEMPO_ACQUISIZIONE!T21 -> 4.95 | N112: =STEMI_TEMPO_ACQUISIZIONE!U21 -> 3.43 | O112: =STEMI_TEMPO_ACQUISIZIONE!V21 -> 4.01 | P112: =STEMI_TEMPO_ACQUISIZIONE!W21 -> 4.7 | Q112: =STEMI_TEMPO_ACQUISIZIONE!X21 -> 3.72 | R112: =STEMI_TEMPO_ACQUISIZIONE!Y21 -> 3.06
A127: PAZIENTE | B127: Pat.8
A128: TEMPO | B128: =STEMI_TEMPO_ACQUISIZIONE!B12 -> 0.18263889 | C128: =STEMI_TEMPO_ACQUISIZIONE!C12 -> 0.50347222 | D128: =STEMI_TEMPO_ACQUISIZIONE!D12 -> 0.58819444 | E128: =STEMI_TEMPO_ACQUISIZIONE!E12 -> 1.5944444 | F128: =STEMI_TEMPO_ACQUISIZIONE!F12 -> 2.5763889 | G128: =STEMI_TEMPO_ACQUISIZIONE!G12 -> 3.5847222 | H128: =STEMI_TEMPO_ACQUISIZIONE!H12 -> 4.5986111
A129: ACQUISIZIONE | B129: =STEMI_TEMPO_ACQUISIZIONE!R12 -> 0.153 | C129: =STEMI_TEMPO_ACQUISIZIONE!S12 -> 0.155 | D129: =STEMI_TEMPO_ACQUISIZIONE!T12 -> 0.174 | E129: =STEMI_TEMPO_ACQUISIZIONE!U12 -> 0.113 | F129: =STEMI_TEMPO_ACQUISIZIONE!V12 -> 0.114 | G129: =STEMI_TEMPO_ACQUISIZIONE!W12 -> 0.142 | H129: =STEMI_TEMPO_ACQUISIZIONE!X12 -> 0.07 | J129: PAZIENTE | K129: Pat.18
J130: TEMPO | K130: =STEMI_TEMPO_ACQUISIZIONE!B22 -> 0.74861111 | L130: =STEMI_TEMPO_ACQUISIZIONE!C22 -> 0.86527778 | M130: =STEMI_TEMPO_ACQUISIZIONE!D22 -> 1.3625 | N130: =STEMI_TEMPO_ACQUISIZIONE!E22 -> 2.4118056 | O130: =STEMI_TEMPO_ACQUISIZIONE!F22 -> 3.3729167 | P130: =STEMI_TEMPO_ACQUISIZIONE!G22 -> 4.3270833 | Q130: =STEMI_TEMPO_ACQUISIZIONE!H22 -> 5.3548611 | R130: =STEMI_TEMPO_ACQUISIZIONE!I22 -> 6.3881944 | ... X130: =STEMI_TEMPO_ACQUISIZIONE!O22 -> 11.355556
J131: ACQUISIZIONE | K131: =STEMI_TEMPO_ACQUISIZIONE!R22 -> 11.24 | L131: =STEMI_TEMPO_ACQUISIZIONE!S22 -> 7.79 | M131: =STEMI_TEMPO_ACQUISIZIONE!T22 -> 5.03 | N131: =STEMI_TEMPO_ACQUISIZIONE!U22 -> 2.84 | O131: =STEMI_TEMPO_ACQUISIZIONE!V22 -> 3.69 | P131: =STEMI_TEMPO_ACQUISIZIONE!W22 -> 4.56 | Q131: =STEMI_TEMPO_ACQUISIZIONE!X22 -> 3.98 | R131: =STEMI_TEMPO_ACQUISIZIONE!Y22 -> 2.27 | ... X131: =STEMI_TEMPO_ACQUISIZIONE!AE22 -> 0.54
A145: PAZIENTE | B145: Pat.9
A146: TEMPO | B146: =STEMI_TEMPO_ACQUISIZIONE!B13 -> 0.36319444 | C146: =STEMI_TEMPO_ACQUISIZIONE!C13 -> 1.0847222 | D146: =STEMI_TEMPO_ACQUISIZIONE!D13 -> 2.1180556
A147: ACQUISIZIONE | B147: =STEMI_TEMPO_ACQUISIZIONE!R13 -> 0.029 | C147: =STEMI_TEMPO_ACQUISIZIONE!S13 -> 0.031 | D147: =STEMI_TEMPO_ACQUISIZIONE!T13 -> 0.036
J148: PAZIENTE | K148: Pat.19
J149: TEMPO | K149: =STEMI_TEMPO_ACQUISIZIONE!B23 -> 0.45138889 | L149: =STEMI_TEMPO_ACQUISIZIONE!C23 -> 0.6125 | M149: =STEMI_TEMPO_ACQUISIZIONE!D23 -> 0.95555556 | N149: =STEMI_TEMPO_ACQUISIZIONE!E23 -> 2.9597222 | O149: =STEMI_TEMPO_ACQUISIZIONE!F23 -> 3.9472222 | P149: =STEMI_TEMPO_ACQUISIZIONE!G23 -> 4.9548611 | Q149: =STEMI_TEMPO_ACQUISIZIONE!H23 -> 5.9965278
J150: ACQUISIZIONE | K150: =STEMI_TEMPO_ACQUISIZIONE!R23 -> 28.39 | L150: =STEMI_TEMPO_ACQUISIZIONE!S23 -> 15.65 | M150: =STEMI_TEMPO_ACQUISIZIONE!T23 -> 9.97 | N150: =STEMI_TEMPO_ACQUISIZIONE!U23 -> 2.66 | O150: =STEMI_TEMPO_ACQUISIZIONE!V23 -> 2.27 | P150: =STEMI_TEMPO_ACQUISIZIONE!W23 -> 1.76 | Q150: =STEMI_TEMPO_ACQUISIZIONE!X23 -> 1.46
A163: PAZIENTE | B163: Pat.10
A164: TEMPO | B164: =STEMI_TEMPO_ACQUISIZIONE!B14 -> 1.3493056 | C164: =STEMI_TEMPO_ACQUISIZIONE!C14 -> 1.7930556 | D164: =STEMI_TEMPO_ACQUISIZIONE!D14 -> 2.8263889 | E164: =STEMI_TEMPO_ACQUISIZIONE!E14 -> 3.14375 | F164: =STEMI_TEMPO_ACQUISIZIONE!F14 -> 3.7770833 | G164: =STEMI_TEMPO_ACQUISIZIONE!G14 -> 4.8138889
A165: ACQUISIZIONE | B165: =STEMI_TEMPO_ACQUISIZIONE!R14 -> 1.78 | C165: =STEMI_TEMPO_ACQUISIZIONE!S14 -> 2.06 | D165: =STEMI_TEMPO_ACQUISIZIONE!T14 -> 2.17 | E165: =STEMI_TEMPO_ACQUISIZIONE!U14 -> 1.96 | F165: =STEMI_TEMPO_ACQUISIZIONE!V14 -> 1.67 | G165: =STEMI_TEMPO_ACQUISIZIONE!W14 -> 1.06
J167: PAZIENTE | K167: Pat.20
J168: TEMPO | K168: =STEMI_TEMPO_ACQUISIZIONE!B24 -> 1.6236111 | L168: =STEMI_TEMPO_ACQUISIZIONE!C24 -> 1.8333333 | M168: =STEMI_TEMPO_ACQUISIZIONE!D24 -> 2.49375 | N168: =STEMI_TEMPO_ACQUISIZIONE!E24 -> 3.4034722 | O168: =STEMI_TEMPO_ACQUISIZIONE!F24 -> 4.38125 | P168: =STEMI_TEMPO_ACQUISIZIONE!G24 -> 5.4340278 | Q168: =STEMI_TEMPO_ACQUISIZIONE!H24 -> 5.79375 | R168: =STEMI_TEMPO_ACQUISIZIONE!I24 -> 6.4666667 | ... T168: =STEMI_TEMPO_ACQUISIZIONE!K24 -> 8.4479167
...

Sheet STEMI TROBOLISATO
B3: PAT ID | C3: DATI PROCEDURA E RICOVERO | D3: TROMBOLISI
B4: Cognome-nome | C4: Data evento | E4: ANTIAGGREGANTE (1 Plavix; 2 Altro) | F4: TnThs MIRE 1 | G4: CK-MB 1 | H4: TnThs MIRE 2 | I4: CK-MB 2 | J4: TnThs MIRE 3 | K4: CK-MB 3 | L4: TnThs MIRE 4 | M4: CK-MB 4 | N4: TnThs MIRE 5 | O4: CK-MB 5 | P4: TnThs MIRE 6 | Q4: CK-MB 6 | R4: TnThs MIRE 7 | S4: CK-MB 7 | T4: TnThs MIRE 8 | U4: CK-MB 8 | V4: TnThs MIRE 9 | W4: CK-MB 9 | X4: TnThs MIRE 10 | Y4: CK-MB 10
A5: 1 | B5: BERLINGERI Antonio | C5: 16/08/2016 ore 00:30 | D5: 1 | E5: Prasugrel | F5: 12 ore 06:14 16/08/2016 | G5: >600 | H5: 11,950 ore 11:03 16/0/2016 | I5: 600 | J5: 13,560 ore 13:30 16/08/2016 | K5: 600 | L5: 10,230 ore 17:53 16/08/2016 | M5: 514 | N5: 5,620 ore 09:18 17/08/2016 | O5: 198 | P5: 3,520 ore 09:00 18/08/2016 | Q5: 24.91 | R5: 3,620 ore 08:17 19/08/2016 | S5: 7.57 | T5: 3,470 ore 20/08/2016 10:06 | U5: 4.76 | V5: 2,320 ore 09:40 21/08/2016 | W5: 3.92 | X5: 1,450 ore 09:38 22/08/2016 | Y5: 3.47
A6: 2 | B6: LAMA Grazia | C6: 22/08/2016 ore 13:00 | D6: 1 | E6: Ticagrelor | F6: 4,650 ore 18:39 22/08/2016 | G6: 277.7 | H6: 4,550 ore 23:28 22/08/2016 | I6: 216.5 | J6: 4,050 ore 09:38 23/08/2016 | K6: 142.5 | L6: 2,260 ore 09:26 24/08/2016 | M6: 14.12 | N6: 2,630 ore 09:37 25/08/2016 | O6: 5.9 | P6: 1,740 ore 09:39 26/08/2016 | Q6: 3.86 | R6: 2,290 ore 10:12 28/08/2016 | S6: 2.36 | T6: 1,610 ore 09:10 29/08/2016 | U6: 1.8 | V6: 1,090 ore 10:10 30/08/2016 | W6: 1.38
