Workbook

Sheet STEMI
B3: PAT ID | C3: DATI PROCEDURA E RICOVERO | D3: TROMBOLISI | E3: Diabete | F3: Ins. Renale | G3: ANTIAGGREGANTE
B4: Cognome-nome | C4: Data evento | D4: (0 no, 1 efficace,2 inefficace) | E4: (0 no, 1 si) | F4: (0 no, 1 si) | G4: (1 Plavix; 2 Altro) | H4: GENSINI | I4: IRC (1 Si; 2 No) | J4: TnThs MIRE 1 | K4: CK-MB 1 | L4: TnThs MIRE 2 | M4: CK-MB 2 | N4: TnThs MIRE 3 | O4: CK-MB 3 | P4: TnThs MIRE 4 | Q4: CK-MB 4 | R4: TnThs MIRE 5 | S4: CK-MB 5 | T4: TnThs MIRE 6 | U4: CK-MB 6 | V4: TnThs MIRE 7 | W4: CK-MB 7 | X4: TnThs MIRE 8 | Y4: CK-MB 8 | Z4: TnThs MIRE 9 | AA4: CK-MB 9 | AB4: TnThs MIRE 10 | AC4: CK-MB 10 | AD4: TnThs MIRE 11 | AE4: CK-MB 11
A5: 1 | B5: Dattolo Salvatore | C5: 29/11/2015_09:00 | D5: 2 | E5: 0 | F5: 0 | G5: 2 | I5: 2 | J5: 1,210_29/11/2015 ore 13:06 | K5: 36.33 | L5: 2,790_29/11/2015 ore 19:_18 | M5: 70.23 | N5: 1,250_30/11/2015 ore 09:39 | O5: 38.51 | P5: 0,603_01/12/2015 ore 09:28 | Q5: 9.19 | R5: 0,665_02/12/2015 ore 08:58 | S5: 3.69 | T5: 0,692_03/12/2015 ore 09:53 | U5: 2.04 | V5: 0,541_03/12/2015 ore 18:36 | W5: 2.5 | X5: 0,483_04/12/2015 ore 10:05 | Y5: 2.83 | Z5: 0,102_06/12/2015 ore 09:35 | AA5: 6.13 | AB5: 0,069_07/12/2015 ore 10:29 | AC5: 5.65 | AD5: 0,051_08/12/2015 ore 10:26 | AE5: 5.19 | AF5: 0,035_09/12/2015 ore 11:04 | AG5: 2.67
A6: 2 | B6: Baldo Caterina | C6: 18/12/2015_20:00 | D6: 0 | E6: 0 | F6: 0 | G6: 2 | I6: 2 | J6: 16,63_19/12/2015 ore 04:31 | K6: 600 | L6: 21,430/19/12/2015 ore 11:22 | M6: 600 | N6: 13,570_19/12/2015 ore 17:53 | O6: 459.4 | P6: 8,8_20/12/2015 ore 11:16 | Q6: 89.88 | R6: 7,910_21/12/2015 | S6: 12.75 | T6: 7,220_22/12/2015 ore 09:20 | U6: 6.74 | V6: 6,78_22/12/2015 ore 17:45 | W6: 7.51 | X6: 5,47:23/12/2015 ore 09:28 | Y6: 6.72 | Z6: 4,720_24/12/2015 ore 09:11 | AA6: 3.93 | AB6: 3,830_25/12/2015 ore 09:47 | AC6: 4.22 | AD6: 3,020_26/12/2015 ore 10:16 | AE6: 5.47 | AF6: 2,35_27/12/2015 ore 10:32 | AG6: 4.34 | AH6: 1,520_28/12/2015 ore 09:45 | AI6: 3.53 | AJ6: 1,120_29/12/2015 ore 10:25 | AK6: 2.77
A7: 3 | B7: Trimboli Paolo | C7: 05/12/2015_17:00 | D7: 2 | E7: 0 | F7: 0 | G7: 2 | I7: 2 | J7: 1,08_05/12/2015 ore 21:11 | K7: 135.7 | L7: 7,250_06/12/2015 ore 01:37 | M7: 7.25 | N7: 11,130_06/12/2015 ore 09:59 | O7: 400.7 | P7: 6,280_07/12/2015 ore 10:29 | Q7: 29 | R7: 6,410_08/12/2015 ore 10:26 | S7: 5.93 | T7: 5,470_09/12/2015 ore 10:26 | U7: 2.98 | V7: 4_10/12/2015 ore 10:15 | W7: 2.33 | X7: 1,340_12/12/2015 ore 08:56 | Y7: 1.54 | Z7: 0,828_13/12/2015 ore 10:41 | AA7: 1.29 | AB7: 0,476_14/12/2015 ore 1213 | AC7: 1.15
A8: 4 | B8: Di Giacco Teresa | C8: 20/11/2015_21:00 | D8: 0 | E8: 1 | F8: 0 | G8: 2 | I8: 2 | J8: 0,058_21/11/2015 ore 02:50 | K8: 5.46 | L8: 0,215_21/12/2015 ore 10:11 | M8: 17.71 | N8: 0,331_21/11/2015 ore 17:28 | O8: 20.35 | P8: 0,298_22/11/2015 ore 10:36 | Q8: 6.62 | R8: 0,330_23/11/2015 ore 10:02 | S8: 2.28 | T8: 0,333_24/11/2015 ore 09:36 | U8: 1.56 | V8: 0,196_25/11/2015 ore 09:06 | W8: 1.58 | X8: 0,078_26/11/2015 ore 09:17 | Y8: 1.72 | Z8: 0,035_27/11/2015 ore 10:19 | AA8: 1.87
A9: 5 | B9: Basadonna Maurizio | C9: 13/12/2015_15:00 | D9: 0 | E9: 1 | F9: 0 | G9: 1 | I9: 2 | J9: 0,530_13/12/2015 ore 20:26 | K9: 24.14 | L9: 0,749_14/12/2015 ore 00:10 | M9: 31.89 | N9: 0,911_14/12/2015 ore 09:46 | O9: 34.93 | P9: 0,673_14/12/2015 ore 19:07 | Q9: 19.85 | R9: 0,474_15/12/2015 ore 09:03 | S9: 7.36 | T9: 0,438_16/12/2015 ore 09:46 | U9: 3 | V9: 0,354_16/12/2015 ore 17:24 | W9: 2.94 | X9: 0,371_17/12/2015 ore 09:05 | Y9: 2.67 | Z9: 0,281_18/12/2015 ore 10:07 | AA9: 3.08
A10: 6 | B10: Nadile Giuseppe | C10: 23/11/2015_15:00 | D10: 0 | E10: 1 | F10: 0 | G10: 2 | I10: 2 | J10: 1,680_23/11/2015 ore 19:26 | K10: 114.4 | L10: 3,740_24/11/2015 ore 01:14 | M10: 387.3 | N10: 6,420_24/11/2015 ore 10:43 | O10: 125.6 | P10: 3,690_24/11/2015 ore 15:37 | Q10: 184.2 | R10: 3,050_25/11/2015 ore 07:08 | S10: 49.45 | T10: 2,410_26/11/2015 ore 09:17 | U10: 8.33 | V10: 2,140_26/11/2015 ore 18:49 | W10: 5.94 | X10: 2,390_27/11/2015 ore 09:54 | Y10: 4.84 | Z10: 1,480_28/11/2015 ore 08:32 | AA10: 2.69 | AB10: 0,620_29/11/2015 ore 09:37 | AC10: 2.24 | AD10: 0,319_30/11/2015 ore 10:37 | AE10: 2.36
A11: 7 | B11: Riccio Bruno | C11: 42338 | D11: 0 | E11: 0 | F11: 0 | G11: 1 | I11: 2 | J11: 1,710_30/11/2015 ore 17:54 | K11: 105.6 | L11: 9,360_30/11/2015 ore 23:19 | M11: 299.6 | N11: 8,430_01/12/2015 ore 09:50 | O11: 171.9 | P11: 4,30_02/12/2005 ore 08:58 | Q11: 12.88 | R11: 4,740_03/12/2015 ore 09:22 | S11: 3.43 | T11: 3,850_04/12/2015 ore 10:37 | U11: 1.64
A12: 8 | B12: Calabretta Gregorio | C12: 27/11/2013_03:00 | D12: 0 | E12: 0 | F12: 0 | G12: 2 | I12: 2 | J12: 0,310_27/11/2015 ore 07:44 | K12: 48.95 | L12: 3,720_27/11/2015 ore 16:13 | M12: >300 | N12: 4,180_28/11/2015 ore 09:01 | O12: 184.1 | P12: 2,130_29/11/2015 ore 09:37 | Q12: 17.78 | R12: 2,670_30/11/2015 ore 09:19 | S12: 4.67 | T12: 3,990_01/12/2015 ore 09:14 | U12: 2.03 | V12: 3,160_02/12/2015 ore 08:58 | W12: 1.76 | X12: 1,710_03/12/2015 ore 10:03 | Y12: 1.73 | Z12: 0,760_04/12/2015 ore 10:37 | AA12: 1.75 | AB12: 0,455_05/12/2015 ore 10:28 | AC12: 1.56 | AD12: 0,293_06/12/2015 ore 09:13 | AE12: 1.3 | AF12: 0,182_07/12/2015 ore 11:00 | AG12: 1.31
A13: 9 | B13: Papalia Domenica | C13: 21/12/2015_19:00 | D13: 0 | E13: 0 | F13: 0 | G13: 2 | I13: 2 | J13: 1,570_21/12/2015 ore 23:36 | K13: 121.9 | L13: 7,810_22/12/2015 ore 06:58 | M13: >300 | N13: 7,460_22/12/2015 ore 17:45 | O13: 205.4 | P13: 6,580_23/12/2015 ore 09:28 | Q13: 61.94 | R13: 5,930_24/12/2015 ore 08:30 | S13: 11.91 | T13: 4,980_25/12/2015 ore 10:19 | U13: 5.6 | V13: 1,720_26/12/2015 ore 10:32 | W13: 3.37 | X13: 0,430_27/12/2015 ore 10:44 | Y13: 2.94 | Z13: 0,144_28/12/2015 ore 08:24 | AA13: 3.86 | AB13: 2,180_28/12/2015 ore 18:55 | AC13: 59.68 | AD13: 2,140_28/12/2015 ore 23:52 | AE13: 54.25 | AF13: 2,160_29/12/2015 ore 09:36 | AG13: 35.74 | AH13: 0,896_30/12/2015 ore 09:18 | AI13: 5.72 | AJ13: 0,973_31/12/2015 ore 09:44 | AK13: 4.74
A14: 10 | B14: Brosio Maurizio | C14: 16/12/2015_15:00 | D14: 0 | E14: 0 | F14: 0 | G14: 2 | I14: 2 | J14: 5,150_16/12/2015 ore 22:21 | K14: 215.8 | L14: 3,820_17/12/2015 ore 03:09 | M14: 288.9 | N14: 3,03_17/12/2015 ore 09:46 | O14: 170.5 | P14: 2,810_18/12/2015 ore 10:07 | Q14: 16.8 | R14: 2,690_19/12/2015 ore 10:41 | S14: 4.96 | T14: 2,130_20/12/2015 ore 10:12 | U14: 3.41 | V14: 0,889_21/12/2015 ore 11:01 | W14: 3.4 | X14: 0,458_22/12/2015 ore 09:37 | Y14: 3.26 | Z14: 0,228_23/12/2015 ore 11:18 | AA14: 3.01 | AB14: 0,124_24/12/2015 ore 10:16 | AC14: 2.55
A15: 11 | B15: Gulla' Francesco | C15: 03/12/2015_08:00 | D15: 2 | E15: 0 | F15: 0 | G15: 2 | I15: 2 | J15: 5,650_03/12/2015 ore 11:58 | K15: 203.8 | L15: 18,550_03/12/2015 ore 17:52 | M15: 290.3 | N15: 9,430_04/12/2015 ore 10:14 | O15: 93.66 | P15: 4,240_05/12/2015 ore 10:29 | Q15: 11.9 | R15: 3,510_06/12/2015 ore 09:50 | S15: 5.93 | T15: 3,170_07/12/2015 ore 09:53 | U15: 5.28 | V15: 2,360_07/12/2015 ore 17:57 | W15: 3.94 | X15: 2,7_08/12/2015 ore 10:02 | Y15: 3.64 | Z15: 1,910_09/12/2015 ore 11:12 | AA15: 2.83 | AB15: 1,560_10/12/2015 ore 10:15 | AC15: 2.43
A16: 12 | B16: Travaglini Luigi | C16: 06/12/2015_15:00 | D16: 0 | E16: 1 | F16: 1 | G16: 2 | I16: 1 | J16: 0,733_06/12/2015 ore 18:59 | K16: 31.5 | L16: 1,110_06/12/2015 ore 23:42 | M16: 26.33 | N16: 1,180_07/12/2015 ore 10:29 | O16: 35.67 | P16: 0,963_07/12/2015 ore 21:48 | Q16: 14.45 | R16: 0,963_07/12/2015 ore 22:10 | S16: 14.45 | T16: 1,090_08/12/2015 ore 10:02 | U16: 8.5 | V16: 1,870_09/12/2015 ore 10:26 | W16: 3.8 | X16: 2,160_10/12/2015 ore 11:15 | Y16: 2.2 | Z16: 1,920:11/12/2015 ore 11:01 | AA16: 2.18 | AB16: 1,460_12/12/2015 ore 08:56 | AC16: 2.01
A17: 13 | B17: Gullo-Domenico | C17: 02/04/2015 ore 15:00 | D17: 0 | E17: 0 | F17: 0 | G17: 2 | I17: 2 | J17: 0,206_02/04/2015 ore 22:34 | K17: 28.32 | L17: 0,803_03/04/201 ore 02:18 | M17: 49.33 | N17: 1,050_03/04/2015 ore 10:24 | O17: 58.12 | P17: 0,504_05/042015 ore 11:34 | Q17: 2.87 | R17: 0,753_06/04/2015 ore 10:36 | S17: 1.99 | T17: 0,620_07/04/2015 ore 10:47 | U17: 3.12 | V17: 0,428_08/04/2015 ore 09:37 | W17: 4.06 | X17: 0,247_09/04/2015 ore 10:16 | Y17: 3.82
A18: 14 | B18: Arconte Giovanni | C18: 06/02/2015_10:00 | D18: 1 | E18: 0 | F18: 0 | G18: 2 | I18: 2 | J18: 0,088_06/02/2015 ore 18:41 | K18: 2.83 | L18: 0,069_06/02/2015 ore 23:24 | M18: 3.86 | N18: 0,073_07/02/2015 ore 10:55 | O18: 5.73 | P18: 0,069_08/02/2015 ore 10:47 | Q18: 3.4 | R18: 0,076_09/02/2015 ore 10:07 | S18: 1.59 | T18: 0,066_10/02/2015 ore 09:30 | U18: 1.19 | V18: 0,041_11/02/2015 ore 10:31 | W18: 0.88
A19: 15 | B19: Bartone salvatore | C19: 06/02/2015_11:00 | D19: 1 | E19: 0 | F19: 0 | G19: 2 | I19: 2 | J19: 15,13_06/02/2015 ore 18:40 | K19: 254.7 | L19: 24,39_06/02/2015 ore 23:37 | M19: 277.2 | N19: 21,44_07/02/2015 ore 10:55 | O19: 166.6 | P19: 10,59_08/02/2015 ore 10:47 | Q19: 23.28 | R19: 8,730_09/02/2015 ore 10:07 | S19: 12.19 | T19: 7,280_10/02/2015 ore 10:32 | U19: 7.88 | V19: 6,220_10/02/2015 ore 17:41 | W19: 5,880_11/02/2015 ore 10:15 | X19: 5.22
A20: 16 | B20: Calarco francesco | C20: 06/02/2015_16:00 | D20: 2 | E20: 0 | F20: 0 | G20: 2 | I20: 2 | J20: 1,540_06/02/2015 ore 21:51 | K20: 58.85 | L20: 2,470_06/02/2015 ore 23:48 | M20: 73.6 | N20: 2,510_07/02/2015 ore 10:55 | O20: 62.28 | P20: 1,370_08/02/2015 ore 10:47 | Q20: 13.02 | R20: 1,070_09/02/2015 ore 10:07 | S20: 3.95 | T20: 1,080_09/02/2015 ore 18:44 | U20: 4.99 | V20: 1,210_10/02/2015 ore 09:30 | W20: 3.58 | X20: 1,020_11/02/2015 ore 0:32 | Y20: 2.56
A21: 17 | B21: Pascuzzi Salvatore | C21: 23/02/2015_11:00 | D21: 1 | E21: 1 | F21: 0 | G21: 2 | I21: 2 | J21: 2,560_24/02/2015 ore 18:38 | K21: 27.61 | L21: 2,550_24/02/2015 ore 23:26 | M21: 18.3 | N21: 2,2_25/02/2015 ore 12:43 | O21: 10.89 | P21: 1,740_26/02/2015 ore 11:30 | Q21: 3.94 | R21: 0,812_28/02/2015 ore 12:05 | S21: 2.48
A22: 18 | B22: Trifini Maria | C22: 27/03/2015 ore 16:00 | D22: 2 | E22: 0 | F22: 0 | G22: 1 | I22: 2 | J22: 2,420_28/03/2015 ore 13:28 | K22: 263.2 | L22: 13_29/03/2015 ore 01:14 | M22: 514.5 | N22: 12,670_29/03/2015 ore 10:00 | O22: 284.5 | P22: 8,940_30/03/2015 ore 12:57 | Q22: 31.52 | R22: 8,220_01/04/2015 ore 09:58 | S22: 4.03 | T22: 6,660_01/04/2015 ore 20:13 | U22: 4.47 | V22: 5,110_02/04/2015 ore 10:52 | W22: 3.94 | X22: 2,10_03/04/2015 ore 10:24 | Y22: 2.86 | Z22: 0,758_04/04/2015 ore 13:34 | AA22: 3
A23: 19 | B23: Mauro Sergio | C23: 03/02/2015_17:00 | D23: 1 | E23: 0 | F23: 0 | G23: 1 | I23: 2 | J23: 1,340_04/02/2015 ore 09:59 | K23: 99.78 | L23: 3,110_04/02/2015 ore 17:03 | M23: 244.6 | N23: 2,670_05/02/2015 ore 08:57 | O23: 86.71 | P23: 2,780_06/02/2015 ore 10:01 | Q23: 11.81 | R23: 2,9_07/02/2015 ore 10:09 | S23: 3.89 | T23: 2,130_08/02/2015 ore 10:46 | U23: 2.21 | V23: 0,969_09/02/2015 ore 10:18 | W23: 1.81 | X23: 0,658_09/02/2015 ore 17:06 | Y23: 1.57 | Z23: 0,483_10/02/2015 ore 09:31 | AA23: 3.21 | AB23: 0,268_11/02/2015 ore 10:40 | AC23: 1.42 | AD23: 0,189_12/02/2015 ore 10:21 | AE23: 0.99 | AF23: 0,118_13/02/2015 ore 10:53 | AG23: 0.93
A24: 20 | B24: Cosentino Orlando | C24: 14/02/2015_04:00 | D24: 1 | E24: 1 | F24: 0 | G24: 2 | I24: 2 | J24: 5,270_14/02/2015 ore 11:47 | K24: 103.4 | L24: 4,40_15/02/2015 ore 07:48 | M24: 74.25 | N24: 2,420_15/02/2015 ore 10:55 | O24: 34.88 | P24: 1,080_16/02/2015 ore 10:45 | Q24: 5.97 | R24: 0,752_17/02/2015 ore 09:46 | S24: 1.85 | T24: 0,668_18/02/2015 ore 11:14 | U24: 2.49
A25: 21 | B25: Bernando Ferraro | C25: 11/02/2015_15:00 | D25: 1 | E25: 0 | F25: 0 | G25: 2 | I25: 2 | J25: 20,850_11/02/2015 ore 19:12 | K25: 547.5 | L25: 17,720_12/02/2015 ore 01:57 | M25: 495.6 | N25: 9,850_12/02/2015 ore 11:03 | O25: 275.5 | P25: 7,470_12/02/2015 ore 18:22 | Q25: 87.33 | R25: 6,160_13/02/2015 ore 10:32 | S25: 24.35 | T25: 5,750_14/02/2015 ore 10:56 | U25: 5.18 | V25: 4,520_15/02/2015 ore 10:56 | W25: 2.59 | X25: 2,950_16/02/2015 ore 10:15 | Y25: 3.28 | Z25: 1,330_17/02/2015 ore 10:58 | AA25: 2.82
A26: 22 | B26: Boninsegna Salvatore | C26: 02/11/2015_16:30 | D26: 0 | E26: 0 | F26: 0 | G26: 2 | I26: 2 | J26: 2,820_02/11/2015 ore 21:17 | K26: 219.6 | L26: 12,210_03/11/2015 ore 00:22 | M26: 424 | N26: 7,8_03/11/2015 ore 09:02 | O26: 277.4 | P26: 3,480_04/11/2015 ore 10:19 | Q26: 24.05 | R26: 3,660_05/11/2015 ore 09:52 | S26: 5.76 | T26: 3,660_06/11/2015 ore 10:24 | U26: 3.07 | V26: 2,220_07/11/2015 ore 11:01 | W26: 2.35
A27: 23 | B27: Paluccio Mario Cosimo | C27: 02/12/2015_07:00 | D27: 0 | E27: 0 | F27: 1 | G27: 2 | I27: 2 | J27: 4_02/12/2015 ore 17:53 | K27: 265.9 | L27: 13,96_02/12/2015 ore 22:54 | M27: 589.8 | N27: 12,05_03/12/2015 ore 10:06 | O27: 296 | P27: 12,330_04/12/2015 ore 10:41 | Q27: 30.8 | R27: 11,890_05/12/2015 ore 11:44 | S27: 8.67 | T27: 9,590_06/12/2015 ore 09:59 | U27: 5.17 | V27: 8,9_07/12/2015 ore 09:53 | W27: 3.53 | X27: 7,060_08/12/2015 ore 10:26 | Y27: 3.3
A28: 24 | B28: Valenzisi Antonio | C28: 24/11/2015_16:30 | D28: 0 | E28: 0 | F28: 0 | G28: 1 | I28: 2 | J28: 1,020_24/11/2015 ore 01:55 | K28: 90.09 | L28: 9,640_24/11/2015 ore 10;12 | M28: 230.2 | N28: 5,760_24/11/2015 ore 15:37 | O28: 116.3 | P28: 3,160_25/11/2015 ore 09:07 | Q28: 33.64 | R28: 2,680_26/11/2015 ore 09:27 | S28: 7.73 | T28: 2,930_27/11/2015 ore 09:54 | U28: 3.27 | V28: 2,9_28/11/2015 ore 08:32 | W28: 1.87 | X28: 2,110_29/11/2015 ore 10:26 | Y28: 1.52 | Z28: 1,340_30/11/2015 ore 09:20 | AA28: 1.65 | AB28: 0,744_01/12/2015 ore 10:21 | AC28: 1.61
A29: 25 | B29: Galloro Alberto | C29: 02/12/2015_13:15 | D29: 0 | E29: 0 | F29: 0 | G29: 2 | I29: 2 | J29: 0,899_02/12/2015 ore 17:32 | K29: 234.4 | L29: 2,830_02/12/2015 ore 22:52 | M29: 274.5 | N29: 3,110_03/12/2015 ore 09:53 | O29: 138.4 | P29: 1,830_04/12/2015 ore 10:05 | Q29: 17.74 | R29: 1,910_05/12/2015 ore 10:29 | S29: 5.93 | T29: 1,640_06/12/2015 ore 09:50 | U29: 3.15 | V29: 1,440_07/12/2015 ore 09:53 | W29: 2.31 | X29: 1,140_08/12/2015 ore 10:26 | Y29: 2.34 | Z29: 0,782_09/12/2015 ore 11:04 | AA29: 2.23

Sheet NSTEMI
B3: PAT ID | C3: DATI PROCEDURA E RICOVERO
B4: Cognome-nome | C4: Data evento | D4: ANTIAGGREGANTE (1 Plavix; 2 Altro) | E4: GENSINI | F4: Insufficienza renale (1 Si; 2 No) | G4: TnThs MIRE 1 | H4: CK-MB 1 | I4: TnThs MIRE 2 | J4: CK-MB 2 | K4: TnThs MIRE 3 | L4: CK-MB 3 | M4: TnThs MIRE 4 | N4: CK-MB 4 | O4: TnThs MIRE 5 | P4: CK-MB 5 | Q4: TnThs MIRE 6 | R4: CK-MB 6 | S4: TnThs MIRE 7 | T4: CK-MB 7 | U4: TnThs MIRE 8 | V4: CK-MB 8 | W4: TnThs MIRE 9 | X4: CK-MB 9 | Y4: TnThs MIRE 10 | Z4: CK-MB 10
A5: 1 | B5: Megna Emilio | C5: 05/03/2013_13:00 | D5: 2 | F5: 2 | G5: 0,514_05/03/2013 ore17:20 | H5: 3.67 | I5: 0,618_05/03/2013 ore 22:56 | J5: 2.93 | K5: 0,542_06/03/2013 ore 08:39 | L5: 2.73 | M5: 0,579_06/03/2013 ore 18:17 | N5: 3.25 | O5: 0,422_07/03/2013 ore 08:36 | P5: 2.45 | Q5: 0,366_08/03/2013 ore 08:56 | R5: 1.28
A6: 2 | B6: Cavallaro Erminia | C6: 04/03/2013_14:00 | D6: 2 | F6: 2 | G6: 0,059_06/03/2013 ore 13:34 | H6: 1.77 | I6: 0,0782_06/03/2013 ore 23:05 | J6: 2.11 | K6: 0,078_07/03/2013 ore 08:53 | L6: 3.03 | M6: 0,072_08/03/2013 ore 10:11
A7: 3 | B7: Mileto Mariangela | C7: 41337 | D7: 1 | F7: 2 | G7: 0,194_08/03/2013 ore 12:19 | H7: 27.19 | I7: 0,789_08/03/2013 ore 22:49 | J7: 26.16 | K7: 0,531_09/03/2013 ore 10:34 | L7: 12.16 | M7: 0,818_10/03/2013 ore 10:22 | N7: 2.67 | O7: 0,761_11/03/2013 ore 09:49 | P7: 1.64
A8: 4 | B8: Romano Pasquale | C8: 41367 | D8: 1 | F8: 2 | G8: 0,205_03/04/2013 ore 16:24 | H8: 2.55 | I8: 0,127_04/04/2013 ore 09:45 | J8: 3.65 | K8: 0,196_04/04/2013 ore 22:59 | L8: 6.01 | M8: 0,278_05/04/2013 ore 09:14 | N8: 11.53 | O8: 0,184_06/04/2013 ore 09:34 | P8: 3.95 | Q8: 0,182_07/04/2013 ore 10:45
A9: 5 | B9: Lagana' Natale | C9: 17/04/2013_12:00 | D9: 1 | F9: 2 | G9: 0,335_17/04/2013 ore 22:59 | H9: 14.1 | I9: 0,296_18/04/2013 ore 10:43 | J9: 11 | K9: 0,236_18/04/2013 ore 23:45 | L9: 12.48 | M9: 0,237_19/04/2013 ore 09:07 | N9: 17.05 | O9: 0,411_20/04/2013 ore 10:10 | Q9: 0,255_20/04/2013 ore 15:46 | S9: 0,298_21/04/2013 ore 10:05 | U9: 0,351_21/04/2013 ore 16:30 | W9: 0,341_22/04/2013 ore 10:56
A10: 6 | B10: Fasano Giuseppe | C10: 41389 | D10: 2 | F10: 2 | G10: 0,160_25/04/2013 ore 18:18 | H10: 16.92 | I10: 0,320_26/04/2013 ore 10:23 | J10: 13.86 | K10: 0,249_26/04/2013 ore 17:03 | L10: 9.76 | M10: 0,271_27/04/2013 ore 08:55 | N10: 12.12 | O10: 0,290_28/04/2013 ore 09:44 | P10: 4.3 | Q10: 0,296_29/04/2013 ore 08:30 | R10: 2.55 | S10: 0,235_30/04/2013 ore 08:35 | T10: 2.12 | U10: 0,169_01/05/2013 ore 10:21 | V10: 1.63
A11: 7 | B11: Falduto Paolino | C11: 41383 | D11: 1 | F11: 2 | G11: 0,118_19/04/2013 ore 11:50 | H11: 1.4 | I11: 0,147_20/04/2013 ore 00:36 | J11: 1.87 | K11: 0,158_20/04/2013 ore 09:51 | L11: 5.2 | M11: 0,149_21/04/2013 ore 10:05 | O11: 0,135_21/04/2013 ore 16:30 | Q11: 0,144_22/04/2013 ore 11:05 | R11: 1.52
A12: 8 | B12: De Giovanni Armenia | C12: 41354 | D12: 1 | F12: 2 | G12: 0,621_21/03/2013 ore 14:53 | H12: 2.22 | I12: 0,317_22/04/2013 ore 10:59 | J12: 1.81 | K12: 0,308_22/04/2013 ore 22:16 | L12: 10.41 | M12: 0,379_23/04/2013 ore 10:45 | N12: 7.77 | O12: 0,263_24/04/2013 ore 10:24 | P12: 2.95 | Q12: 0,288_25/04/2013 ore 09:31 | R12: 2.86
A13: 9 | B13: Cannizzaro Domenico | C13: 41367 | D13: 1 | F13: 2 | G13: 0,466_03/04/2013 ore 15:48 | H13: 39.56 | I13: 0,539_03/04/2013 ore 22:21 | J13: 30.6 | K13: 0,417_04/04/2013 ore 09:45 | L13: 18.57 | M13: 0,375_05/04/2013 ore 08:36 | N13: 6.21 | O13: 0,472_06/04/2013 ore 10:03
A14: 10 | B14: Tallarida Vincenzo | C14: 42342 | D14: 2 | F14: 2 | G14: 3,350_06/12/2015 ore 12:17 | H14: 22.59 | I14: 3,2_07/12/2015 ore 10:29 | J14: 7.09 | K14: 2,340_07/12/2015 ore 21:48 | L14: 6.24 | M14: 2,930_08/12/2015 ore 10:02 | N14: 8.9 | O14: 2,240_09/12/2015 ore 10:26 | P14: 3.53 | Q14: 1,680_09/12/2015 ore 19:58 | R14: 2.5 | S14: 2,290_10/12/2015 ore 10:15 | T14: 3.7 | U14: 1,660_11/12/2015 ore 09:14 | V14: 2.36 | W14: 1,090_12/12/2015 ore 09:52 | X14: 1.89 | Y14: 0,819_13/12/2015 ore 10:19 | Z14: 1.08 | AA14: 0,652_14/12/2015 ore 11:35 | AB14: 0.86 | AC14: 0,640_15/12/2015 ore 10:11 | AD14: 0.64
A15: 11 | B15: Todarello Michele | C15: 42341 | D15: 2 | F15: 2 | G15: 0,125_05/12/2015 ore 11:44 | H15: 3.03 | I15: 0,143_06/12/2015 ore 09:35 | J15: 2.27 | K15: 0,133_07/12/2015 ore 10:29 | L15: 2.44 | M15: 0,105_07/11/2015 ore 17:28 | N15: 2.94 | O15: 0,1_08/12/2015 ore 10:39 | P15: 2.5 | Q15: 0,046_09/12/2015 ore 10:46 | R15: 3.32 | S15: 0,027_10/12/2015 ore 11:15 | T15: 2.24 | U15: 0,021_12/12/2015 ore 10:23 | V15: 2.31 | W15: 0,021_13/12/2015 ore 11:53 | X15: 2.24 | Y15: 0,020_14/12/2015 ore 10:13 | Z15: 2.26
A16: 12 | B16: Carlizzi Stefano | C16: 29/11/2015_15:00 | D16: 2 | F16: 2 | G16: 1,330_30/11/2015 ore 17:08 | H16: 94.68 | I16: 1,120_30/11/2015 ore 23:19 | J16: 59.2 | K16: 09:28_01/12/2015 ore 09:28 | L16: 42.04 | M16: 1,470_02/12/2015 ore 08:58 | N16: 9.6 | O16: 1,630_03/12/2015 ore 09:22 | P16: 4.68 | Q16: 1,5_03/12/2015 ore 17:59 | R16: 5.92 | S16: 1,250_04/12/2015 ore 10:05 | T16: 9.45 | U16: 0,695_05/12/2015 ore 10:29 | V16: 4.24 | W16: 0,338_06/12/2015 ore 11:18 | X16: 3.12 | Y16: 0,222_07/12/2015 ore 10:47 | Z16: 2.56
A17: 13 | B17: Muraca Saverio | C17: 42340 | D17: 2 | F17: 2 | G17: 0,045_11/12/2015 ore 13:34 | H17: 2.12 | I17: 0,045_11/12/2015 ore 18:11 | J17: 2.53 | K17: 0,080_12/12/2015 ore 10:00 | L17: 5.56 | M17: 0,059_13/12/2015 ore 10:19 | N17: 4.79 | O17: 0,055_14/12/2015 ore 09:20 | P17: 3.54 | Q17: 0,055_14/12/2015 ore 22:08 | R17: 3.96 | S17: 0,066_15/12/2015 ore 09:31 | T17: 4.93 | U17: 0,055_16/12/2015 ore 10:58 | V17: 3.9
A18: 14 | B18: Malena Giuseppina | C18: 42329 | D18: 2 | F18: 2 | G18: 0,475_22/11/2015 ore 16:34 | H18: 44.03 | I18: 0,476_23/11/2015 ore 09:23 | J18: 16.99 | K18: 0,624_23/11/2015 ore 18:07 | L18: 10.3 | M18: 0,624_23/11/2015 ore 10:30 | N18: 0.4375 | O18: 0,733_24/11/2015 ore 10:35 | P18: 18.76 | Q18: 0,515_25/11/2015 ore 09:07 | R18: 3.18 | S18: 0,497_26/11/2015 ore 09:17 | T18: 1.4 | U18: 0,426_27/11/2015 ore 10:03 | V18: 1.44
A19: 15 | B19: Misale Giuseppe | C19: 42336 | D19: 1 | F19: 2 | G19: 0,022_04/12/2015 ore 15:54 | H19: 2.57 | I19: 0,075_04/12/2015 ore 22:03 | J19: 4.85 | K19: 5,52_05/12/2015 ore 10:53 | L19: 5.52 | M19: 0,268_06/12/2015 ore 09:41 | N19: 4.08 | O19: 0,329_07/12/2015 ore 09:53 | P19: 3.75 | Q19: 0,439_08/12/2015 ore 10:02 | R19: 1.9 | S19: 0,448_09/12/2015 ore 12:56 | T19: 1.83 | U19: 0,384_10/12/2015 ore 11:15 | V19: 1.87
A20: 16 | B20: Scozzafava Antonio | C20: 42351 | D20: 2 | F20: 2 | G20: 0,540_14/12/2015 ore 21:26 | H20: 25.7 | I20: 0,476_15/12/2015 ore 09:31 | J20: 14.48 | K20: 0,535_15/12/2015 ore 17:53 | L20: 37.44 | M20: 1,360_16/12/2015 ore 10:09 | N20: 24.73 | O20: 0,940_16/12/2015 ore 17:25 | P20: 24.73 | Q20: 1,00_17/12/2015 ore 09:32 | R20: 9.9 | S20: 0,886_18/12/2015 ore 10:07 | T20: 3.41 | U20: 0,828_18/12/2015 ore 19:24 | V20: 3.22 | W20: 0,910_19/12/2015 ore 10:14 | X20: 7.72 | Y20: 0,817_19/12/2015 ore 17:48 | Z20: 5.3 | AA20: 0,740_20/12/2015 ore 10:07 | AB20: 3.17 | AC20: 0,532_21/12/2015 ore 11:24 | AD20: 2.17
A21: 17 | B21: Gambino Pietro | C21: 09/12/2015_16:30 | D21: 2 | F21: 2 | G21: 0,267_09/12/2015 ore 19:08 | H21: 58.25 | I21: 0,833_10/12/2015 ore 11:15 | J21: 49.6 | K21: 1,820_10/12/2015 ore 16:04 | L21: 35.46 | M21: 1,040_11/12/2015 ore 10:09 | N21: 10.41 | O21: 1,2_12/12/2015 ore 10:23 | P21: 2.91 | Q21: 1,030_13/12/2015 ore 10:41 | R21: 1.96 | S21: 0,593_14/12/2015 ore 11:35 | T21: 1.46
A22: 18 | B22: Zangari Michele | C22: 42340 | D22: 2 | F22: 2 | G22: 0,096_09/12/2015 ore 18:08 | H22: 3.48 | I22: 0,098_09/12/2015 ore 13:32 | J22: 2.19 | K22: 0,106_10/12/2015 ore 11:15 | L22: 4.45 | M22: 0,075_11/12/2015 ore 09:14 | N22: 2.63 | O22: 0,082_11/12/2015 ore 18:11 | P22: 3.3 | Q22: 0,126_12/12/2015 ore 09:52 | R22: 6.5 | S22: 0,137_13/12/2015 ore 10:19 | T22: 4.01 | U22: 0,139_14/12/2015 ore 09:46 | V22: 1.95
A23: 19 | B23: Albanese Domenico | C23: 02/12/2015_02:00 | D23: 2 | F23: 2 | G23: 0,798_02/12/2015 ore 16:42 | H23: 124.6 | I23: 1,950_03/12/2015 ore 09:15 | J23: 54.34 | K23: 5,080_03/12/2015 ore 19:43 | L23: 129.9 | M23: 4,740_04/12/2015 ore 10:05 | N23: 43.97 | O23: 4,320_05/12/2015 ore 10:52 | P23: 5.35 | Q23: 3,050_06/12/2015 ore 09:50 | R23: 2.08 | S23: 1,780_07/12/2015 ore 11:13 | T23: 1.41
A24: 20 | B24: Sia Pasquale | C24: 24/12/2015_03:00 | D24: 2 | F24: 2 | G24: 0,046_24/12/2015 ore 07:04 | H24: 9.82 | I24: 0,045_24/12/2015 ore 08:28 | J24: 9.77 | K24: 0,180_25/12/2015 ore 10:19 | L24: 7.37 | M24: 0,171_26/12/2015 ore 09:05 | N24: 2.9 | O24: 0,172_27/12/2015 ore 10:32 | P24: 1.92 | Q24: 0,130_28/12/2015 ore 09:20 | R24: 1.82 | S24: 0,100_28/12/2015 ore 23:52 | T24: 1.64 | U24: 0,090_29/12/2015 ore 09:34 | V24: 2.33 | W24: 0,077_30/12/2015 ore 10:42 | X24: 1.41 | Y24: 0,055_31/12/2015 ore 10:06 | Z24: 1.64
A25: 21 | B25: Rupolo Francesco | C25: 25/12/2015_03:00 | D25: 2 | F25: 2 | G25: 0,873_27/12/2015 ore 12:23 | H25: 3.68 | I25: 0,813_28/12/2015 ore 09:20 | J25: 1.87 | K25: 00,962_28/12/2015 ore 23:52 | L25: 3.05 | M25: 0,864_29/12/2015 ore 09:36 | N25: 3.77 | O25: 0,832_30/12/2015 ore 09:45 | P25: 2.09 | Q25: 0,605_31/12/2015 ore 10:54 | R25: 2.26
A26: 22 | B26: Contartese michele | C26: 42356 | D26: 2 | F26: 2 | G26: 0,477_18/12/2015 ore 13:50 | H26: 8.52 | I26: 0,626_18/12/2015 ore 23:28 | J26: 7.16 | K26: 0,856_19/12/2015 ore 10:14 | L26: 7.98 | M26: 0,813_19/12/2015 ore 17:46 | N26: 5.06 | O26: 0,871_20/12/2015 ore 10:57 | P26: 3.24 | Q26: 0,859_21/12/2015 ore 11:31 | R26: 2.39 | S26: 0,877_21/12/2015 ore 17:37 | T26: 36.94 | U26: 1,0_21/12/2015 ore 23:36 | V26: 50.09 | W26: 1,260_22/12/2015 ore 08:42 | X26: 42.12 | Y26: 1,050_23/12/2015 ore 08:33 | Z26: 6.87 | AA26: 1,0_24/12/2015 ore 08:30 | AB26: 2.84
A27: 23 | B27: Schiavello Francesco | C27: 15/12/2015_16:00 | D27: 2 | F27: 2 | G27: 0,010_15/12/2015 ore 23:30 | H27: 0.085416667 | I27: 0.010_16/12/2015 ore 10:02 | J27: 1.95 | K27: 0,087_16/12/2015 ore 17:25 | L27: 4.16 | M27: 0,085_17/12/2015 ore 09:32 | N27: 7.01 | O27: 0,108_18/12/2015 ore 10:07 | P27: 3.07 | Q27: 0,093_19/12/2015 ore 10:42 | R27: 2.46 | S27: 0,089_20/12/2015 ore 10:09 | T27: 1.65
A28: 24 | B28: Arsena Giovanni | C28: 42346 | D28: 2 | F28: 2 | G28: 0,014_19/12/2015 ore 17:38 | H28: 1.9 | I28: 0,013_10/12/2015 ore 10:15 | J28: 1.64 | K28: 0,122_10/12/2015 ore 17:47 | L28: 6.78 | M28: 0,176_11/12/2015 ore 09:14 | N28: 9.08 | O28: 0,110_11/12/2015 ore 18:14 | P28: 8.93 | Q28: 0,141_12/12/2015 ore 10:23 | R28: 5.31 | S28: 0,154_13/12/2015 ore 10:19 | T28: 2.6 | U28: 0,135_14/12/2015 ore 11:37 | V28: 2.85
A29: 25 | B29: Gallo Francesco | C29: 15/12/2015_15:00 | D29: 1 | F29: 2 | G29: 0,137_16/12/2015 ore 12:59 | H29: 9.62 | I29: 0,117_16/12/2015 ore 17:24 | J29: 7.18 | K29: 0,120_17/12/2015 ore 09:32 | L29: 3.9 | M29: 0,151_18/12/2015 ore 10:07 | N29: 2.21 | O29: 0,144_19/12/2015 ore 10:51 | P29: 1.48 | Q29: 0,112_20/12/2015 ore 10:09 | R29: 1.36

Sheet STEMI_MODIF.
B1: data ricovero originale 24/11/15
B3: PAT ID | C3: DATI PROCEDURA E RICOVERO | D3: TROMBOLISI | E3: ANTIAGGREGANTE
B4: Cognome-nome | C4: Data evento | D4: (0 no, 1 efficace,2 inefficace) | E4: (1 Plavix; 2 Altro) | F4: GENSINI | G4: IRC (1 Si; 2 No) | H4: A1 | I4: TIME FROM t0[h.m] | J4: TnThs MIRE 1 | K4: CK-MB 1 | L4: A2 | M4: TIME FROM t0[h.m] | N4: TnThs MIRE 2 | O4: CK-MB 2 | P4: A3 | Q4: TIME FROM t0[h.m] | R4: TnThs MIRE 3 | S4: CK-MB 3 | T4: A4 | U4: TIME FROM t0[h.m] | V4: TnThs MIRE 4 | W4: CK-MB 4 | X4: A5 | Y4: TIME FROM t0[h.m] | Z4: TnThs MIRE 5 | AA4: CK-MB 5 | AB4: A6 | AC4: TIME FROM t0[h.m] | AD4: TnThs MIRE 6 | AE4: CK-MB 6 | AF4: A7 | AG4: TIME FROM t0[h.m] | AH4: TnThs MIRE 7 | AI4: CK-MB 7 | AJ4: A8 | AK4: TIME FROM t0[h.m] | AL4: TnThs MIRE 8 | AM4: CK-MB 8 | AN4: A9 | AO4: TIME FROM t0[h.m] | AP4: TnThs MIRE 9 | AQ4: CK-MB 9 | AR4: A10 | AS4: TIME FROM t0[h.m] | AT4: TnThs MIRE 10 | AU4: CK-MB 10 | AV4: A11 | AW4: TIME FROM t0[h.m] | AX4: TnThs MIRE 11 | AY4: CK-MB 11 | AZ4: A12 | BA4: TIME FROM t0[h.m] | BB4: TnThs MIRE 12 | BC4: CK-MB 12 | BD4: A13 | BE4: TIME FROM t0[h.m] | BF4: TnThs MIRE 13 | BG4: CK-MB 13 | BH4: A14 | BI4: TIME FROM t0[h.m] | BJ4: TnThs MIRE 14 | BK4: CK-MB 14
A5: 1 | B5: Dattolo Salvatore | C5: 42337.375 | D5: 2 | E5: 2 | G5: 2 | H5: 42337.546 | I5: =H5-C5 -> 0.17083333 | J5: 1.21 | K5: 36.33 | L5: 42337.804 | M5: =L5-C5 -> 0.42916667 | N5: 2.79 | O5: 70.23 | P5: 42338.402 | Q5: =P5-C5 -> 1.0270833 | R5: 1.25 | S5: 38.51 | T5: 42339.394 | U5: =T5-C5 -> 2.0194444 | V5: 0.603 | W5: 9.19 | X5: 42340.374 | Y5: =X5-C5 -> 2.9986111 | Z5: 0.665 | AA5: 3.69 | AB5: 42341.412 | AC5: =AB5-C5 -> 4.0368056 | AD5: 0.692 | AE5: 2.04 | AF5: 42341.775 | AG5: =AF5-C5 -> 4.4 | AH5: 0.541 | AI5: 2.5 | AJ5: 42342.42 | AK5: =AJ5-C5 -> 5.0451389 | AL5: 0.483 | AM5: 2.83 | AN5: 42344.399 | AO5: =AN5-C5 -> 7.0243056 | AP5: 0.102 | AQ5: 6.13 | AR5: 42345.437 | AS5: =AR5-C5 -> 8.0618056 | AT5: 0.069 | AU5: 5.65 | AV5: 42346.435 | AW5: =AV5-C5 -> 9.0597222 | AX5: 0.051 | AY5: 5.19 | AZ5: 42347.461 | BA5: =AZ5-C5 -> 10.086111 | BB5: 0.035 | BC5: 2.67
A6: 2 | B6: Baldo Caterina | C6: 42356.833 | D6: 0 | E6: 2 | G6: 2 | H6: 42357.188 | I6: =H6-C6 -> 0.35486111 | J6: 16.63 | K6: 600 | L6: 42357.474 | M6: =L6-C6 -> 0.64027778 | N6: 21.43 | O6: 600 | P6: 42357.745 | Q6: =P6-C6 -> 0.91180556 | R6: 13.57 | S6: 459.4 | T6: 42358.469 | U6: =T6-C6 -> 1.6361111 | V6: 8.8 | W6: 89.88 | X6: 42359.5 | Y6: =X6-C6 -> 2.6666667 | Z6: 7.91 | AA6: 12.75 | AB6: 42360.389 | AC6: =AB6-C6 -> 3.5555556 | AD6: 7.22 | AE6: 6.74 | AF6: 42360.74 | AG6: =AF6-C6 -> 3.90625 | AH6: 6.78 | AI6: 7.51 | AJ6: 42361.394 | AK6: =AJ6-C6 -> 4.5611111 | AL6: 5.47 | AM6: 6.72 | AN6: 42362.383 | AO6: =AN6-C6 -> 5.5493056 | AP6: 4.72 | AQ6: 3.93 | AR6: 42363.408 | AS6: =AR6-C6 -> 6.5743056 | AT6: 3.83 | AU6: 4.22 | AV6: 42364.428 | AW6: =AV6-C6 -> 7.5944444 | AX6: 3.02 | AY6: 5.47 | AZ6: 42365.439 | BA6: =AZ6-C6 -> 8.6055556 | BB6: 2.35 | BC6: 4.34 | BD6: 42366.406 | BE6: =BD6-C6 -> 9.5729167 | BF6: 1.52 | BG6: 3.53 | BH6: 42367.434 | BI6: =BH6-C6 -> 10.600694 | BJ6: 1.12 | BK6: 2.77
A7: 3 | B7: Trimboli Paolo | C7: 42343.708 | D7: 2 | E7: 2 | G7: 2 | H7: 42343.883 | I7: =H7-C7 -> 0.17430556 | J7: 1.08 | K7: 135.7 | L7: 42344.067 | M7: =L7-C7 -> 0.35902778 | N7: 7.25 | O7: 7.25 | P7: 42344.416 | Q7: =P7-C7 -> 0.70763889 | R7: 11.13 | S7: 400.7 | T7: 42345.437 | U7: =T7-C7 -> 1.7284722 | V7: 6.28 | W7: 29 | X7: 42346.435 | Y7: =X7-C7 -> 2.7263889 | Z7: 6.41 | AA7: 5.93 | AB7: 42347.435 | AC7: =AB7-C7 -> 3.7263889 | AD7: 5.47 | AE7: 2.98 | AF7: 42348.427 | AG7: =AF7-C7 -> 4.71875 | AH7: 4 | AI7: 2.33 | AJ7: 42350.372 | AK7: =AJ7-C7 -> 6.6638889 | AL7: 1.34 | AM7: 1.54 | AN7: 42351.445 | AO7: =AN7-C7 -> 7.7368056 | AP7: 0.828 | AQ7: 1.29 | AR7: 42352.509 | AS7: =AR7-C7 -> 8.8006944 | AT7: 0.476 | AU7: 1.15
A8: 4 | B8: Di Giacco Teresa | C8: 42328.875 | D8: 0 | E8: 2 | G8: 2 | H8: 42329.118 | I8: =H8-C8 -> 0.24305556 | J8: 0.058 | K8: 5.46 | L8: 42329.424 | M8: =L8-C8 -> 0.54930556 | N8: 0.215 | O8: 17.71 | P8: 42329.728 | Q8: =P8-C8 -> 0.85277778 | R8: 0.331 | S8: 20.35 | T8: 42330.442 | U8: =T8-C8 -> 1.5666667 | V8: 0.298 | W8: 6.62 | X8: 42331.418 | Y8: =X8-C8 -> 2.5430556 | Z8: 0.33 | AA8: 2.28 | AB8: 42332.4 | AC8: =AB8-C8 -> 3.525 | AD8: 0.333 | AE8: 1.56 | AF8: 42333.379 | AG8: =AF8-C8 -> 4.5041667 | AH8: 0.196 | AI8: 1.58 | AJ8: 42334.387 | AK8: =AJ8-C8 -> 5.5118056 | AL8: 0.078 | AM8: 1.72 | AN8: 42335.43 | AO8: =AN8-C8 -> 6.5548611 | AP8: 0.035 | AQ8: 1.87
A9: 5 | B9: Basadonna Maurizio | C9: 42351.625 | D9: 0 | E9: 1 | G9: 2 | H9: 42351.851 | I9: =H9-C9 -> 0.22638889 | J9: 0.53 | K9: 24.14 | L9: 42352.007 | M9: =L9-C9 -> 0.38194444 | N9: 0.749 | O9: 31.89 | P9: 42352.407 | Q9: =P9-C9 -> 0.78194444 | R9: 0.911 | S9: 34.93 | T9: 42352.797 | U9: =T9-C9 -> 1.1715278 | V9: 0.673 | W9: 19.85 | X9: 42353.377 | Y9: =X9-C9 -> 1.7520833 | Z9: 0.474 | AA9: 7.36 | AB9: 42354.407 | AC9: =AB9-C9 -> 2.7819444 | AD9: 0.438 | AE9: 3 | AF9: 42354.725 | AG9: =AF9-C9 -> 3.1 | AH9: 0.354 | AI9: 2.94 | AJ9: 42355.378 | AK9: =AJ9-C9 -> 3.7534722 | AL9: 0.371 | AM9: 2.67 | AN9: 42356.422 | AO9: =AN9-C9 -> 4.7965278 | AP9: 0.281 | AQ9: 3.08
A10: 6 | B10: Nadile Giuseppe | C10: 42331.625 | D10: 0 | E10: 2 | G10: 2 | H10: 42331.81 | I10: =H10-C10 -> 0.18472222 | J10: 1.68 | K10: 114.4 | L10: 42332.051 | M10: =L10-C10 -> 0.42638889 | N10: 3.74 | O10: 387.3 | P10: 42332.447 | Q10: =P10-C10 -> 0.82152778 | R10: 6.42 | S10: 125.6 | T10: 42332.651 | U10: =T10-C10 -> 1.0256944 | V10: 3.69 | W10: 184.2 | X10: 42333.297 | Y10: =X10-C10 -> 1.6722222 | Z10: 3.05 | AA10: 49.45 | AB10: 42334.387 | AC10: =AB10-C10 -> 2.7618056 | AD10: 2.41 | AE10: 8.33 | AF10: 42334.784 | AG10: =AF10-C10 -> 3.1590278 | AH10: 2.14 | AI10: 5.94 | AJ10: 42335.412 | AK10: =AJ10-C10 -> 3.7875 | AL10: 2.39 | AM10: 4.84 | AN10: 42336.356 | AO10: =AN10-C10 -> 4.7305556 | AP10: 1.48 | AQ10: 2.69 | AR10: 42337.401 | AS10: =AR10-C10 -> 5.7756944 | AT10: 0.62 | AU10: 2.24 | AV10: 42338.442 | AW10: =AV10-C10 -> 6.8173611 | AX10: 0.319 | AY10: 2.36
A11: 7 | B11: Riccio Bruno | C11: 42338.5 | D11: 0 | E11: 1 | G11: 2 | H11: 42338.746 | I11: =H11-C11 -> 0.24583333 | J11: 1.71 | K11: 105.6 | L11: 42338.972 | M11: =L11-C11 -> 0.47152778 | N11: 9.36 | O11: 299.6 | P11: 42339.41 | Q11: =P11-C11 -> 0.90972222 | R11: 8.43 | S11: 171.9 | T11: 42340.374 | U11: =T11-C11 -> 1.8736111 | V11: 4.3 | W11: 12.88 | X11: 42341.39 | Y11: =X11-C11 -> 2.8902778 | Z11: 4.74 | AA11: 3.43 | AB11: 42342.442 | AC11: =AB11-C11 -> 3.9423611 | AD11: 3.85 | AE11: 1.64
A12: 8 | B12: Calabretta Gregorio | C12: 42335.125 | D12: 0 | E12: 2 | G12: 2 | H12: 42335.322 | I12: =H12-C12 -> 0.19722222 | J12: 0.31 | K12: 48.95 | L12: 42335.676 | M12: =L12-C12 -> 0.55069444 | N12: 3.72 | O12: 300 | P12: 42336.376 | Q12: =P12-C12 -> 1.2506944 | R12: 4.18 | S12: 184.1 | T12: 42337.401 | U12: =T12-C12 -> 2.2756944 | V12: 2.13 | W12: 17.78 | X12: 42338.388 | Y12: =X12-C12 -> 3.2631944 | Z12: 2.67 | AA12: 4.67 | AB12: 42339.385 | AC12: =AB12-C12 -> 4.2597222 | AD12: 3.99 | AE12: 2.03 | AF12: 42340.374 | AG12: =AF12-C12 -> 5.2486111 | AH12: 3.16 | AI12: 1.76 | AJ12: 42341.419 | AK12: =AJ12-C12 -> 6.29375 | AL12: 1.71 | AM12: 1.73 | AN12: 42342.442 | AO12: =AN12-C12 -> 7.3173611 | AP12: 0.76 | AQ12: 1.75 | AR12: 42343.436 | AS12: =AR12-C12 -> 8.3111111 | AT12: 0.455 | AU12: 1.56 | AV12: 42344.384 | AW12: =AV12-C12 -> 9.2590278 | AX12: 0.293 | AY12: 1.3 | AZ12: 42345.458 | BA12: =AZ12-C12 -> 10.333333 | BB12: 0.182 | BC12: 1.31
A13: 9 | B13: Papalia Domenica | C13: 42359.792 | D13: 0 | E13: 2 | G13: 2 | H13: 42359.983 | I13: =H13-C13 -> 0.19166667 | J13: 1.57 | K13: 121.9 | L13: 42360.29 | M13: =L13-C13 -> 0.49861111 | N13: 7.81 | O13: 300 | P13: 42360.74 | Q13: =P13-C13 -> 0.94791667 | R13: 7.46 | S13: 205.4 | T13: 42361.394 | U13: =T13-C13 -> 1.6027778 | V13: 6.58 | W13: 61.94 | X13: 42362.354 | Y13: =X13-C13 -> 2.5625 | Z13: 5.93 | AA13: 11.91 | AB13: 42363.43 | AC13: =AB13-C13 -> 3.6381944 | AD13: 4.98 | AE13: 5.6 | AF13: 42364.439 | AG13: =AF13-C13 -> 4.6472222 | AH13: 1.72 | AI13: 3.37 | AJ13: 42365.447 | AK13: =AJ13-C13 -> 5.6555556 | AL13: 0.43 | AM13: 2.94 | AN13: 42366.35 | AO13: =AN13-C13 -> 6.5583333 | AP13: 0.144 | AQ13: 3.86 | AR13: 42366.788 | AS13: =AR13-C13 -> 6.9965278 | AT13: 2.18 | AU13: 59.68 | AV13: 42366.994 | AW13: =AV13-C13 -> 7.2027778 | AX13: 2.14 | AY13: 54.25 | AZ13: 42367.4 | BA13: =AZ13-C13 -> 7.6083333 | BB13: 2.16 | BC13: 35.74 | BD13: 42368.387 | BE13: =BD13-C13 -> 8.5958333 | BF13: 0.896 | BG13: 5.72 | BH13: 42369.406 | BI13: =BH13-C13 -> 9.6138889 | BJ13: 0.973 | BK13: 4.74
A14: 10 | B14: Brosio Maurizio | C14: 42354.625 | D14: 0 | E14: 2 | G14: 2 | H14: 42354.931 | I14: =H14-C14 -> 0.30625 | J14: 5.15 | K14: 215.8 | L14: 42355.131 | M14: =L14-C14 -> 0.50625 | N14: 3.82 | O14: 288.9 | P14: 42355.407 | Q14: =P14-C14 -> 0.78194444 | R14: 3.03 | S14: 170.5 | T14: 42356.422 | U14: =T14-C14 -> 1.7965278 | V14: 2.81 | W14: 16.8 | X14: 42357.445 | Y14: =X14-C14 -> 2.8201389 | Z14: 2.69 | AA14: 4.96 | AB14: 42358.425 | AC14: =AB14-C14 -> 3.8 | AD14: 2.13 | AE14: 3.41 | AF14: 42359.459 | AG14: =AF14-C14 -> 4.8340278 | AH14: 0.889 | AI14: 3.4 | AJ14: 42360.401 | AK14: =AJ14-C14 -> 5.7756944 | AL14: 0.458 | AM14: 3.26 | AN14: 42361.471 | AO14: =AN14-C14 -> 6.8458333 | AP14: 0.228 | AQ14: 3.01 | AR14: 42362.428 | AS14: =AR14-C14 -> 7.8027778 | AT14: 0.124 | AU14: 2.55
A15: 11 | B15: Gulla' Francesco | C15: 42341.333 | D15: 2 | E15: 2 | G15: 2 | H15: 42341.499 | I15: =H15-C15 -> 0.16527778 | J15: 5.65 | K15: 203.8 | L15: 42341.744 | M15: =L15-C15 -> 0.41111111 | N15: 18.55 | O15: 290.3 | P15: 42342.426 | Q15: =P15-C15 -> 1.0930556 | R15: 9.43 | S15: 93.66 | T15: 42343.437 | U15: =T15-C15 -> 2.1034722 | V15: 4.24 | W15: 11.9 | X15: 42344.41 | Y15: =X15-C15 -> 3.0763889 | Z15: 3.51 | AA15: 5.93 | AB15: 42345.412 | AC15: =AB15-C15 -> 4.0784722 | AD15: 3.17 | AE15: 5.28 | AF15: 42345.748 | AG15: =AF15-C15 -> 4.4145833 | AH15: 2.36 | AI15: 3.94 | AJ15: 42346.418 | AK15: =AJ15-C15 -> 5.0847222 | AL15: 42553 | AM15: 3.64 | AN15: 42347.467 | AO15: =AN15-C15 -> 6.1333333 | AP15: 1.91 | AQ15: 2.83 | AR15: 42348.427 | AS15: =AR15-C15 -> 7.09375 | AT15: 1.56 | AU15: 2.43
A16: 12 | B16: Travaglini Luigi | C16: 42344.625 | D16: 0 | E16: 2 | G16: 1 | H16: 42344.791 | I16: =H16-C16 -> 0.16597222 | J16: 0.733 | K16: 31.5 | L16: 42344.988 | M16: =L16-C16 -> 0.3625 | N16: 1.11 | O16: 26.33 | P16: 42345.437 | Q16: =P16-C16 -> 0.81180556 | R16: 1.18 | S16: 35.67 | T16: 42345.908 | U16: =T16-C16 -> 1.2833333 | V16: 0.963 | W16: 14.45 | X16: 42345.924 | Y16: =X16-C16 -> 1.2986111 | Z16: 0.963 | AA16: 14.45 | AB16: 42346.418 | AC16: =AB16-C16 -> 1.7930556 | AD16: 1.09 | AE16: 8.5 | AF16: 42347.435 | AG16: =AF16-C16 -> 2.8097222 | AH16: 1.87 | AI16: 3.8 | AJ16: 42348.469 | AK16: =AJ16-C16 -> 3.84375 | AL16: 2.16 | AM16: 2.2 | AN16: 42349.459 | AO16: =AN16-C16 -> 4.8340278 | AP16: 1.92 | AQ16: 2.18 | AR16: 42350.372 | AS16: =AR16-C16 -> 5.7472222 | AT16: 1.46 | AU16: 2.01
A17: 13 | B17: Gullo-Domenico | C17: 42096.625 | D17: 0 | E17: 2 | G17: 2 | H17: 42096.94 | I17: =H17-C17 -> 0.31527778 | J17: 0.206 | K17: 28.32 | L17: 42097.096 | M17: =L17-C17 -> 0.47083333 | N17: 0.803 | O17: 49.33 | P17: 42097.433 | Q17: =P17-C17 -> 0.80833333 | R17: 1.05 | S17: 58.12 | T17: 42099.482 | U17: =T17-C17 -> 2.8569444 | V17: 0.504 | W17: 2.87 | X17: 42100.442 | Y17: =X17-C17 -> 3.8166667 | Z17: 0.753 | AA17: 1.99 | AB17: 42101.449 | AC17: =AB17-C17 -> 4.8243056 | AD17: 0.62 | AE17: 3.12 | AF17: 42102.401 | AG17: =AF17-C17 -> 5.7756944 | AH17: 0.428 | AI17: 4.06 | AJ17: 42103.428 | AK17: =AJ17-C17 -> 6.8027778 | AL17: 0.247 | AM17: 3.82
A18: 14 | B18: Arconte Giovanni | C18: 42041.417 | D18: 1 | E18: 2 | G18: 2 | H18: 42041.778 | I18: =H18-C18 -> 0.36180556 | J18: 0.088 | K18: 2.83 | L18: 42041.975 | M18: =L18-C18 -> 0.55833333 | N18: 0.069 | O18: 3.86 | P18: 42042.455 | Q18: =P18-C18 -> 1.0381944 | R18: 0.073 | S18: 5.73 | T18: 42043.449 | U18: =T18-C18 -> 2.0326389 | V18: 0.069 | W18: 3.4 | X18: 42044.422 | Y18: =X18-C18 -> 3.0048611 | Z18: 0.076 | AA18: 1.59 | AB18: 42045.396 | AC18: =AB18-C18 -> 3.9791667 | AD18: 0.066 | AE18: 1.19 | AF18: 42046.438 | AG18: =AF18-C18 -> 5.0215278 | AH18: 0.041 | AI18: 0.88
A19: 15 | B19: Bartone salvatore | C19: 42041.458 | D19: 1 | E19: 2 | G19: 2 | H19: 42041.778 | I19: =H19-C19 -> 0.31944444 | J19: 15.13 | K19: 254.7 | L19: 42041.984 | M19: =L19-C19 -> 0.52569444 | N19: 24.39 | O19: 277.2 | P19: 42042.455 | Q19: =P19-C19 -> 0.99652778 | R19: 21.44 | S19: 166.6 | T19: 42043.449 | U19: =T19-C19 -> 1.9909722 | V19: 10.59 | W19: 23.28 | X19: 42044.422 | Y19: =X19-C19 -> 2.9631944 | Z19: 8.73 | AA19: 12.19 | AB19: 42045.439 | AC19: =AB19-C19 -> 3.9805556 | AD19: 7.28 | AE19: 7.88 | AF19: 42045.737 | AG19: =AF19-C19 -> 4.2784722 | AH19: 6.22 | AJ19: 42046.427 | AK19: =AJ19-C19 -> 4.96875 | AL19: 5.88 | AM19: 5.22
A20: 16 | B20: Calarco francesco | C20: 42041.667 | D20: 2 | E20: 2 | G20: 2 | H20: 42041.91 | I20: =H20-C20 -> 0.24375 | J20: 1.54 | K20: 58.85 | L20: 42041.992 | M20: =L20-C20 -> 0.325 | N20: 2.47 | O20: 73.6 | P20: 42042.455 | Q20: =P20-C20 -> 0.78819444 | R20: 2.51 | S20: 62.28 | T20: 42043.449 | U20: =T20-C20 -> 1.7826389 | V20: 1.37 | W20: 13.02 | X20: 42044.422 | Y20: =X20-C20 -> 2.7548611 | Z20: 1.07 | AA20: 3.95 | AB20: 42044.781 | AC20: =AB20-C20 -> 3.1138889 | AD20: 1.08 | AE20: 4.99 | AF20: 42045.396 | AG20: =AF20-C20 -> 3.7291667 | AH20: 1.21 | AI20: 3.58 | AJ20: 42046.022 | AK20: =AJ20-C20 -> 4.3555556 | AL20: 1.02 | AM20: 2.56
A21: 17 | B21: Pascuzzi Salvatore | C21: 42058.458 | D21: 1 | E21: 2 | G21: 2 | H21: 42059.776 | I21: =H21-C21 -> 1.3180556 | J21: 2.56 | K21: 27.61 | L21: 42059.976 | M21: =L21-C21 -> 1.5180556 | N21: 2.55 | O21: 18.3 | P21: 42060.53 | Q21: =P21-C21 -> 2.0715278 | R21: 2.2 | S21: 10.89 | T21: 42061.479 | U21: =T21-C21 -> 3.0208333 | V21: 1.74 | W21: 3.94 | X21: 42063.503 | Y21: =X21-C21 -> 5.0451389 | Z21: 0.812 | AA21: 2.48
A22: 18 | B22: Trifini Maria | C22: 42090.667 | D22: 2 | E22: 1 | G22: 2 | H22: 42091.561 | I22: =H22-C22 -> 0.89444444 | J22: 2.42 | K22: 263.2 | L22: 42092.051 | M22: =L22-C22 -> 1.3847222 | N22: 13 | O22: 514.5 | P22: 42092.417 | Q22: =P22-C22 -> 1.75 | R22: 12.67 | S22: 284.5 | T22: 42093.54 | U22: =T22-C22 -> 2.8729167 | V22: 8.94 | W22: 31.52 | X22: 42095.415 | Y22: =X22-C22 -> 4.7486111 | Z22: 8.22 | AA22: 4.03 | AB22: 42095.842 | AC22: =AB22-C22 -> 5.1756944 | AD22: 6.66 | AE22: 4.47 | AF22: 42096.453 | AG22: =AF22-C22 -> 5.7861111 | AH22: 5.11 | AI22: 3.94 | AJ22: 42097.433 | AK22: =AJ22-C22 -> 6.7666667 | AL22: 42645 | AM22: 2.86 | AN22: 42098.565 | AO22: =AN22-C22 -> 7.8986111 | AP22: 0.758 | AQ22: 3
A23: 19 | B23: Mauro Sergio | C23: 42038.708 | D23: 1 | E23: 1 | G23: 2 | H23: 42039.416 | I23: =H23-C23 -> 0.70763889 | J23: 1.34 | K23: 99.78 | L23: 42039.71 | M23: =L23-C23 -> 1.0020833 | N23: 3.11 | O23: 244.6 | P23: 42040.373 | Q23: =P23-C23 -> 1.6645833 | R23: 2.67 | S23: 86.71 | T23: 42041.417 | U23: =T23-C23 -> 2.7090278 | V23: 2.78 | W23: 11.81 | X23: 42042.423 | Y23: =X23-C23 -> 3.7145833 | Z23: 2.9 | AA23: 3.89 | AB23: 42043.449 | AC23: =AB23-C23 -> 4.7402778 | AD23: 2.13 | AE23: 2.21 | AF23: 42044.429 | AG23: =AF23-C23 -> 5.7208333 | AH23: 0.969 | AI23: 1.81 | AJ23: 42044.713 | AK23: =AJ23-C23 -> 6.0041667 | AL23: 0.658 | AM23: 1.57 | AN23: 42045.397 | AO23: =AN23-C23 -> 6.6881944 | AP23: 0.483 | AQ23: 3.21 | AR23: 42046.444 | AS23: =AR23-C23 -> 7.7361111 | AT23: 0.268 | AU23: 1.42 | AV23: 42047.431 | AW23: =AV23-C23 -> 8.7229167 | AX23: 0.189 | AY23: 0.99 | AZ23: 42048.453 | BA23: =AZ23-C23 -> 9.7451389 | BB23: 0.118 | BC23: 0.93
A24: 20 | B24: Cosentino Orlando | C24: 42049.167 | D24: 1 | E24: 2 | G24: 2 | H24: 42049.491 | I24: =H24-C24 -> 0.32430556 | J24: 5.27 | K24: 103.4 | L24: 42050.325 | M24: =L24-C24 -> 1.1583333 | N24: 4.4 | O24: 74.25 | P24: 42050.455 | Q24: =P24-C24 -> 1.2881944 | R24: 2.42 | S24: 34.88 | T24: 42051.448 | U24: =T24-C24 -> 2.28125 | V24: 1.08 | W24: 5.97 | X24: 42052.407 | Y24: =X24-C24 -> 3.2402778 | Z24: 0.752 | AA24: 1.85 | AB24: 42053.468 | AC24: =AB24-C24 -> 4.3013889 | AD24: 0.668 | AE24: 2.49
A25: 21 | B25: Bernando Ferraro | C25: 42046.625 | D25: 1 | E25: 2 | G25: 2 | H25: 42046.8 | I25: =H25-C25 -> 0.175 | J25: 20.85 | K25: 547.5 | L25: 42047.081 | M25: =L25-C25 -> 0.45625 | N25: 17.72 | O25: 495.6 | P25: 42047.46 | Q25: =P25-C25 -> 0.83541667 | R25: 9.85 | S25: 275.5 | T25: 42047.765 | U25: =T25-C25 -> 1.1402778 | V25: 7.47 | W25: 87.33 | X25: 42048.439 | Y25: =X25-C25 -> 1.8138889 | Z25: 6.16 | AA25: 24.35 | AB25: 42049.456 | AC25: =AB25-C25 -> 2.8305556 | AD25: 5.75 | AE25: 5.18 | AF25: 42050.456 | AG25: =AF25-C25 -> 3.8305556 | AH25: 4.52 | AI25: 2.59 | AJ25: 42051.427 | AK25: =AJ25-C25 -> 4.8020833 | AL25: 2.95 | AM25: 3.28 | AN25: 42052.457 | AO25: =AN25-C25 -> 5.8319444 | AP25: 1.33 | AQ25: 2.82
A26: 22 | B26: Boninsegna Salvatore | C26: 42310.688 | D26: 0 | E26: 2 | G26: 2 | H26: 42310.887 | I26: =H26-C26 -> 0.19930556 | J26: 2.82 | K26: 219.6 | L26: 42311.015 | M26: =L26-C26 -> 0.32777778 | N26: 12.21 | O26: 424 | P26: 42311.376 | Q26: =P26-C26 -> 0.68888889 | R26: 7.8 | S26: 277.4 | T26: 42312.43 | U26: =T26-C26 -> 1.7423611 | V26: 3.48 | W26: 24.05 | X26: 42313.411 | Y26: =X26-C26 -> 2.7236111 | Z26: 3.66 | AA26: 5.76 | AB26: 42314.433 | AC26: =AB26-C26 -> 3.7458333 | AD26: 3.66 | AE26: 3.07 | AF26: 42315.459 | AG26: =AF26-C26 -> 4.7715278 | AH26: 2.22 | AI26: 2.35
A27: 23 | B27: Paluccio Mario Cosimo | C27: 42340.292 | D27: 0 | E27: 2 | G27: 2 | H27: 42340.745 | I27: =H27-C27 -> 0.45347222 | J27: 4 | K27: 265.9 | L27: 42340.954 | M27: =L27-C27 -> 0.6625 | N27: 13.96 | O27: 589.8 | P27: 42341.421 | Q27: =P27-C27 -> 1.1291667 | R27: 12.05 | S27: 296 | T27: 42342.445 | U27: =T27-C27 -> 2.1534722 | V27: 12.33 | W27: 30.8 | X27: 42343.489 | Y27: =X27-C27 -> 3.1972222 | Z27: 11.89 | AA27: 8.67 | AB27: 42344.416 | AC27: =AB27-C27 -> 4.1243056 | AD27: 9.59 | AE27: 5.17 | AF27: 42345.412 | AG27: =AF27-C27 -> 5.1201389 | AH27: 8.9 | AI27: 3.53 | AJ27: 42346.435 | AK27: =AJ27-C27 -> 6.1430556 | AL27: 7.06 | AM27: 3.3
A28: 24 | B28: Valenzisi Antonio | C28: 42331.688 | D28: 0 | E28: 1 | G28: 2 | H28: 42332.08 | I28: =H28-C28 -> 0.39236111 | J28: 1.02 | K28: 90.09 | L28: 42332.425 | M28: =L28-C28 -> 0.7375 | N28: 9.64 | O28: 230.2 | P28: 42332.651 | Q28: =P28-C28 -> 0.96319444 | R28: 5.76 | S28: 116.3 | T28: 42333.38 | U28: =T28-C28 -> 1.6923611 | V28: 3.16 | W28: 33.64 | X28: 42334.394 | Y28: =X28-C28 -> 2.70625 | Z28: 2.68 | AA28: 7.73 | AB28: 42335.412 | AC28: =AB28-C28 -> 3.725 | AD28: 2.93 | AE28: 3.27 | AF28: 42336.356 | AG28: =AF28-C28 -> 4.6680556 | AH28: 2.9 | AI28: 1.87 | AJ28: 42337.435 | AK28: =AJ28-C28 -> 5.7472222 | AL28: 2.11 | AM28: 1.52 | AN28: 42338.389 | AO28: =AN28-C28 -> 6.7013889 | AP28: 1.34 | AQ28: 1.65 | AR28: 42339.431 | AS28: =AR28-C28 -> 7.74375 | AT28: 0.744 | AU28: 1.61
A29: 25 | B29: Galloro Alberto | C29: 42340.552 | D29: 0 | E29: 2 | G29: 2 | H29: 42340.731 | I29: =H29-C29 -> 0.17847222 | J29: 0.899 | K29: 234.4 | L29: 42340.953 | M29: =L29-C29 -> 0.40069444 | N29: 2.83 | O29: 274.5 | P29: 42341.412 | Q29: =P29-C29 -> 0.85972222 | R29: 3.11 | S29: 138.4 | T29: 42342.42 | U29: =T29-C29 -> 1.8680556 | V29: 1.83 | W29: 17.74 | X29: 42343.437 | Y29: =X29-C29 -> 2.8847222 | Z29: 1.91 | AA29: 5.93 | AB29: 42344.41 | AC29: =AB29-C29 -> 3.8576389 | AD29: 1.64 | AE29: 3.15 | AF29: 42345.412 | AG29: =AF29-C29 -> 4.8597222 | AH29: 1.44 | AI29: 2.31 | AJ29: 42346.435 | AK29: =AJ29-C29 -> 5.8826389 | AL29: 1.14 | AM29: 2.34 | AN29: 42347.461 | AO29: =AN29-C29 -> 6.9090278 | AP29: 0.782 | AQ29: 2.23

Sheet cTnTvsCK-MB
A1: CK-MB
A2: PAZIENTE
A3: S1 | B3: =STEMI_MODIF.!K5 -> 36.33 | C3: =STEMI_MODIF.!O5 -> 70.23 | D3: =STEMI_MODIF.!S5 -> 38.51 | E3: =STEMI_MODIF.!W5 -> 9.19 | F3: =STEMI_MODIF.!AA5 -> 3.69 | G3: =STEMI_MODIF.!AE5 -> 2.04 | H3: =STEMI_MODIF.!AI5 -> 2.5 | I3: =STEMI_MODIF.!AM5 -> 2.83 | J3: =STEMI_MODIF.!AQ5 -> 6.13 | K3: =STEMI_MODIF.!AU5 -> 5.65 | L3: =STEMI_MODIF.!AY5 -> 5.19 | M3: =STEMI_MODIF.!BC5 -> 2.67 | N3: =STEMI_MODIF.!BG5 -> 0 | O3: =STEMI_MODIF.!BK5 -> 0
A4: S2 | B4: =STEMI_MODIF.!K6 -> 600 | C4: =STEMI_MODIF.!O6 -> 600 | D4: =STEMI_MODIF.!S6 -> 459.4 | E4: =STEMI_MODIF.!W6 -> 89.88 | F4: =STEMI_MODIF.!AA6 -> 12.75 | G4: =STEMI_MODIF.!AE6 -> 6.74 | H4: =STEMI_MODIF.!AI6 -> 7.51 | I4: =STEMI_MODIF.!AM6 -> 6.72 | J4: =STEMI_MODIF.!AQ6 -> 3.93 | K4: =STEMI_MODIF.!AU6 -> 4.22 | L4: =STEMI_MODIF.!AY6 -> 5.47 | M4: =STEMI_MODIF.!BC6 -> 4.34 | N4: =STEMI_MODIF.!BG6 -> 3.53 | O4: =STEMI_MODIF.!BK6 -> 2.77
A5: S3 | B5: =STEMI_MODIF.!K7 -> 135.7 | C5: =STEMI_MODIF.!O7 -> 7.25 | D5: =STEMI_MODIF.!S7 -> 400.7 | E5: =STEMI_MODIF.!W7 -> 29 | F5: =STEMI_MODIF.!AA7 -> 5.93 | G5: =STEMI_MODIF.!AE7 -> 2.98 | H5: =STEMI_MODIF.!AI7 -> 2.33 | I5: =STEMI_MODIF.!AM7 -> 1.54 | J5: =STEMI_MODIF.!AQ7 -> 1.29 | K5: =STEMI_MODIF.!AU7 -> 1.15 | L5: =STEMI_MODIF.!AY7 -> 0 | M5: =STEMI_MODIF.!BC7 -> 0 | N5: =STEMI_MODIF.!BG7 -> 0 | O5: =STEMI_MODIF.!BK7 -> 0
A6: S4 | B6: =STEMI_MODIF.!K8 -> 5.46 | C6: =STEMI_MODIF.!O8 -> 17.71 | D6: =STEMI_MODIF.!S8 -> 20.35 | E6: =STEMI_MODIF.!W8 -> 6.62 | F6: =STEMI_MODIF.!AA8 -> 2.28 | G6: =STEMI_MODIF.!AE8 -> 1.56 | H6: =STEMI_MODIF.!AI8 -> 1.58 | I6: =STEMI_MODIF.!AM8 -> 1.72 | J6: =STEMI_MODIF.!AQ8 -> 1.87 | K6: =STEMI_MODIF.!AU8 -> 0 | L6: =STEMI_MODIF.!AY8 -> 0 | M6: =STEMI_MODIF.!BC8 -> 0 | N6: =STEMI_MODIF.!BG8 -> 0 | O6: =STEMI_MODIF.!BK8 -> 0
A7: S5 | B7: =STEMI_MODIF.!K9 -> 24.14 | C7: =STEMI_MODIF.!O9 -> 31.89 | D7: =STEMI_MODIF.!S9 -> 34.93 | E7: =STEMI_MODIF.!W9 -> 19.85 | F7: =STEMI_MODIF.!AA9 -> 7.36 | G7: =STEMI_MODIF.!AE9 -> 3 | H7: =STEMI_MODIF.!AI9 -> 2.94 | I7: =STEMI_MODIF.!AM9 -> 2.67 | J7: =STEMI_MODIF.!AQ9 -> 3.08 | K7: =STEMI_MODIF.!AU9 -> 0 | L7: =STEMI_MODIF.!AY9 -> 0 | M7: =STEMI_MODIF.!BC9 -> 0 | N7: =STEMI_MODIF.!BG9 -> 0 | O7: =STEMI_MODIF.!BK9 -> 0
A8: S6 | B8: =STEMI_MODIF.!K10 -> 114.4 | C8: =STEMI_MODIF.!O10 -> 387.3 | D8: =STEMI_MODIF.!S10 -> 125.6 | E8: =STEMI_MODIF.!W10 -> 184.2 | F8: =STEMI_MODIF.!AA10 -> 49.45 | G8: =STEMI_MODIF.!AE10 -> 8.33 | H8: =STEMI_MODIF.!AI10 -> 5.94 | I8: =STEMI_MODIF.!AM10 -> 4.84 | J8: =STEMI_MODIF.!AQ10 -> 2.69 | K8: =STEMI_MODIF.!AU10 -> 2.24 | L8: =STEMI_MODIF.!AY10 -> 2.36 | M8: =STEMI_MODIF.!BC10 -> 0 | N8: =STEMI_MODIF.!BG10 -> 0 | O8: =STEMI_MODIF.!BK10 -> 0
A9: S7 | B9: =STEMI_MODIF.!K11 -> 105.6 | C9: =STEMI_MODIF.!O11 -> 299.6 | D9: =STEMI_MODIF.!S11 -> 171.9 | E9: =STEMI_MODIF.!W11 -> 12.88 | F9: =STEMI_MODIF.!AA11 -> 3.43 | G9: =STEMI_MODIF.!AE11 -> 1.64 | H9: =STEMI_MODIF.!AI11 -> 0 | I9: =STEMI_MODIF.!AM11 -> 0 | J9: =STEMI_MODIF.!AQ11 -> 0 | K9: =STEMI_MODIF.!AU11 -> 0 | L9: =STEMI_MODIF.!AY11 -> 0 | M9: =STEMI_MODIF.!BC11 -> 0 | N9: =STEMI_MODIF.!BG11 -> 0 | O9: =STEMI_MODIF.!BK11 -> 0
A10: S8 | B10: =STEMI_MODIF.!K12 -> 48.95 | C10: =STEMI_MODIF.!O12 -> 300 | D10: =STEMI_MODIF.!S12 -> 184.1 | E10: =STEMI_MODIF.!W12 -> 17.78 | F10: =STEMI_MODIF.!AA12 -> 4.67 | G10: =STEMI_MODIF.!AE12 -> 2.03 | H10: =STEMI_MODIF.!AI12 -> 1.76 | I10: =STEMI_MODIF.!AM12 -> 1.73 | J10: =STEMI_MODIF.!AQ12 -> 1.75 | K10: =STEMI_MODIF.!AU12 -> 1.56 | L10: =STEMI_MODIF.!AY12 -> 1.3 | M10: =STEMI_MODIF.!BC12 -> 1.31 | N10: =STEMI_MODIF.!BG12 -> 0 | O10: =STEMI_MODIF.!BK12 -> 0
A11: S9 | B11: =STEMI_MODIF.!K13 -> 121.9 | C11: =STEMI_MODIF.!O13 -> 300 | D11: =STEMI_MODIF.!S13 -> 205.4 | E11: =STEMI_MODIF.!W13 -> 61.94 | F11: =STEMI_MODIF.!AA13 -> 11.91 | G11: =STEMI_MODIF.!AE13 -> 5.6 | H11: =STEMI_MODIF.!AI13 -> 3.37 | I11: =STEMI_MODIF.!AM13 -> 2.94 | J11: =STEMI_MODIF.!AQ13 -> 3.86 | K11: =STEMI_MODIF.!AU13 -> 59.68 | L11: =STEMI_MODIF.!AY13 -> 54.25 | M11: =STEMI_MODIF.!BC13 -> 35.74 | N11: =STEMI_MODIF.!BG13 -> 5.72 | O11: =STEMI_MODIF.!BK13 -> 4.74
A12: S10 | B12: =STEMI_MODIF.!K14 -> 215.8 | C12: =STEMI_MODIF.!O14 -> 288.9 | D12: =STEMI_MODIF.!S14 -> 170.5 | E12: =STEMI_MODIF.!W14 -> 16.8 | F12: =STEMI_MODIF.!AA14 -> 4.96 | G12: =STEMI_MODIF.!AE14 -> 3.41 | H12: =STEMI_MODIF.!AI14 -> 3.4 | I12: =STEMI_MODIF.!AM14 -> 3.26 | J12: =STEMI_MODIF.!AQ14 -> 3.01 | K12: =STEMI_MODIF.!AU14 -> 2.55 | L12: =STEMI_MODIF.!AY14 -> 0 | M12: =STEMI_MODIF.!BC14 -> 0 | N12: =STEMI_MODIF.!BG14 -> 0 | O12: =STEMI_MODIF.!BK14 -> 0
A13: S11 | B13: =STEMI_MODIF.!K15 -> 203.8 | C13: =STEMI_MODIF.!O15 -> 290.3 | D13: =STEMI_MODIF.!S15 -> 93.66 | E13: =STEMI_MODIF.!W15 -> 11.9 | F13: =STEMI_MODIF.!AA15 -> 5.93 | G13: =STEMI_MODIF.!AE15 -> 5.28 | H13: =STEMI_MODIF.!AI15 -> 3.94 | I13: =STEMI_MODIF.!AM15 -> 3.64 | J13: =STEMI_MODIF.!AQ15 -> 2.83 | K13: =STEMI_MODIF.!AU15 -> 2.43 | L13: =STEMI_MODIF.!AY15 -> 0 | M13: =STEMI_MODIF.!BC15 -> 0 | N13: =STEMI_MODIF.!BG15 -> 0 | O13: =STEMI_MODIF.!BK15 -> 0
A14: S12 | B14: =STEMI_MODIF.!K16 -> 31.5 | C14: =STEMI_MODIF.!O16 -> 26.33 | D14: =STEMI_MODIF.!S16 -> 35.67 | E14: =STEMI_MODIF.!W16 -> 14.45 | F14: =STEMI_MODIF.!AA16 -> 14.45 | G14: =STEMI_MODIF.!AE16 -> 8.5 | H14: =STEMI_MODIF.!AI16 -> 3.8 | I14: =STEMI_MODIF.!AM16 -> 2.2 | J14: =STEMI_MODIF.!AQ16 -> 2.18 | K14: =STEMI_MODIF.!AU16 -> 2.01 | L14: =STEMI_MODIF.!AY16 -> 0 | M14: =STEMI_MODIF.!BC16 -> 0 | N14: =STEMI_MODIF.!BG16 -> 0 | O14: =STEMI_MODIF.!BK16 -> 0
... A27: S25 | B27: =STEMI_MODIF.!K29 -> 234.4 | C27: =STEMI_MODIF.!O29 -> 274.5 | D27: =STEMI_MODIF.!S29 -> 138.4 | E27: =STEMI_MODIF.!W29 -> 17.74 | F27: =STEMI_MODIF.!AA29 -> 5.93 | G27: =STEMI_MODIF.!AE29 -> 3.15 | H27: =STEMI_MODIF.!AI29 -> 2.31 | I27: =STEMI_MODIF.!AM29 -> 2.34 | J27: =STEMI_MODIF.!AQ29 -> 2.23 | K27: =STEMI_MODIF.!AU29 -> 0 | L27: =STEMI_MODIF.!AY29 -> 0 | M27: =STEMI_MODIF.!BC29 -> 0 | N27: =STEMI_MODIF.!BG29 -> 0 | O27: =STEMI_MODIF.!BK29 -> 0
A29: TROPONINE
A30: PAZIENTE
A31: S1 | B31: =STEMI_MODIF.!J5 -> 1.21 | C31: =STEMI_MODIF.!N5 -> 2.79 | D31: =STEMI_MODIF.!R5 -> 1.25 | E31: =STEMI_MODIF.!V5 -> 0.603 | F31: =STEMI_MODIF.!Z5 -> 0.665 | G31: =STEMI_MODIF.!AD5 -> 0.692 | H31: =STEMI_MODIF.!AH5 -> 0.541 | I31: =STEMI_MODIF.!AL5 -> 0.483 | J31: =STEMI_MODIF.!AP5 -> 0.102 | K31: =STEMI_MODIF.!AT5 -> 0.069 | L31: =STEMI_MODIF.!AX5 -> 0.051 | M31: =STEMI_MODIF.!BB5 -> 0.035 | N31: =STEMI_MODIF.!BF5 -> 0 | O31: =STEMI_MODIF.!BJ5 -> 0
A32: S2 | B32: =STEMI_MODIF.!J6 -> 16.63 | C32: =STEMI_MODIF.!N6 -> 21.43 | D32: =STEMI_MODIF.!R6 -> 13.57 | E32: =STEMI_MODIF.!V6 -> 8.8 | F32: =STEMI_MODIF.!Z6 -> 7.91 | G32: =STEMI_MODIF.!AD6 -> 7.22 | H32: =STEMI_MODIF.!AH6 -> 6.78 | I32: =STEMI_MODIF.!AL6 -> 5.47 | J32: =STEMI_MODIF.!AP6 -> 4.72 | K32: =STEMI_MODIF.!AT6 -> 3.83 | L32: =STEMI_MODIF.!AX6 -> 3.02 | M32: =STEMI_MODIF.!BB6 -> 2.35 | N32: =STEMI_MODIF.!BF6 -> 1.52 | O32: =STEMI_MODIF.!BJ6 -> 1.12
A33: S3 | B33: =STEMI_MODIF.!J7 -> 1.08 | C33: =STEMI_MODIF.!N7 -> 7.25 | D33: =STEMI_MODIF.!R7 -> 11.13 | E33: =STEMI_MODIF.!V7 -> 6.28 | F33: =STEMI_MODIF.!Z7 -> 6.41 | G33: =STEMI_MODIF.!AD7 -> 5.47 | H33: =STEMI_MODIF.!AH7 -> 4 | I33: =STEMI_MODIF.!AL7 -> 1.34 | J33: =STEMI_MODIF.!AP7 -> 0.828 | K33: =STEMI_MODIF.!AT7 -> 0.476 | L33: =STEMI_MODIF.!AX7 -> 0 | M33: =STEMI_MODIF.!BB7 -> 0 | N33: =STEMI_MODIF.!BF7 -> 0 | O33: =STEMI_MODIF.!BJ7 -> 0
A34: S4 | B34: =STEMI_MODIF.!J8 -> 0.058 | C34: =STEMI_MODIF.!N8 -> 0.215 | D34: =STEMI_MODIF.!R8 -> 0.331 | E34: =STEMI_MODIF.!V8 -> 0.298 | F34: =STEMI_MODIF.!Z8 -> 0.33 | G34: =STEMI_MODIF.!AD8 -> 0.333 | H34: =STEMI_MODIF.!AH8 -> 0.196 | I34: =STEMI_MODIF.!AL8 -> 0.078 | J34: =STEMI_MODIF.!AP8 -> 0.035 | K34: =STEMI_MODIF.!AT8 -> 0 | L34: =STEMI_MODIF.!AX8 -> 0 | M34: =STEMI_MODIF.!BB8 -> 0 | N34: =STEMI_MODIF.!BF8 -> 0 | O34: =STEMI_MODIF.!BJ8 -> 0
A35: S5 | B35: =STEMI_MODIF.!J9 -> 0.53 | C35: =STEMI_MODIF.!N9 -> 0.749 | D35: =STEMI_MODIF.!R9 -> 0.911 | E35: =STEMI_MODIF.!V9 -> 0.673 | F35: =STEMI_MODIF.!Z9 -> 0.474 | G35: =STEMI_MODIF.!AD9 -> 0.438 | H35: =STEMI_MODIF.!AH9 -> 0.354 | I35: =STEMI_MODIF.!AL9 -> 0.371 | J35: =STEMI_MODIF.!AP9 -> 0.281 | K35: =STEMI_MODIF.!AT9 -> 0 | L35: =STEMI_MODIF.!AX9 -> 0 | M35: =STEMI_MODIF.!BB9 -> 0 | N35: =STEMI_MODIF.!BF9 -> 0 | O35: =STEMI_MODIF.!BJ9 -> 0
A36: S6 | B36: =STEMI_MODIF.!J10 -> 1.68 | C36: =STEMI_MODIF.!N10 -> 3.74 | D36: =STEMI_MODIF.!R10 -> 6.42 | E36: =STEMI_MODIF.!V10 -> 3.69 | F36: =STEMI_MODIF.!Z10 -> 3.05 | G36: =STEMI_MODIF.!AD10 -> 2.41 | H36: =STEMI_MODIF.!AH10 -> 2.14 | I36: =STEMI_MODIF.!AL10 -> 2.39 | J36: =STEMI_MODIF.!AP10 -> 1.48 | K36: =STEMI_MODIF.!AT10 -> 0.62 | L36: =STEMI_MODIF.!AX10 -> 0.319 | M36: =STEMI_MODIF.!BB10 -> 0 | N36: =STEMI_MODIF.!BF10 -> 0 | O36: =STEMI_MODIF.!BJ10 -> 0
A37: S7 | B37: =STEMI_MODIF.!J11 -> 1.71 | C37: =STEMI_MODIF.!N11 -> 9.36 | D37: =STEMI_MODIF.!R11 -> 8.43 | E37: =STEMI_MODIF.!V11 -> 4.3 | F37: =STEMI_MODIF.!Z11 -> 4.74 | G37: =STEMI_MODIF.!AD11 -> 3.85 | H37: =STEMI_MODIF.!AH11 -> 0 | I37: =STEMI_MODIF.!AL11 -> 0 | J37: =STEMI_MODIF.!AP11 -> 0 | K37: =STEMI_MODIF.!AT11 -> 0 | L37: =STEMI_MODIF.!AX11 -> 0 | M37: =STEMI_MODIF.!BB11 -> 0 | N37: =STEMI_MODIF.!BF11 -> 0 | O37: =STEMI_MODIF.!BJ11 -> 0
A38: S8 | B38: =STEMI_MODIF.!J12 -> 0.31 | C38: =STEMI_MODIF.!N12 -> 3.72 | D38: =STEMI_MODIF.!R12 -> 4.18 | E38: =STEMI_MODIF.!V12 -> 2.13 | F38: =STEMI_MODIF.!Z12 -> 2.67 | G38: =STEMI_MODIF.!AD12 -> 3.99 | H38: =STEMI_MODIF.!AH12 -> 3.16 | I38: =STEMI_MODIF.!AL12 -> 1.71 | J38: =STEMI_MODIF.!AP12 -> 0.76 | K38: =STEMI_MODIF.!AT12 -> 0.455 | L38: =STEMI_MODIF.!AX12 -> 0.293 | M38: =STEMI_MODIF.!BB12 -> 0.182 | N38: =STEMI_MODIF.!BF12 -> 0 | O38: =STEMI_MODIF.!BJ12 -> 0
A39: S9 | B39: =STEMI_MODIF.!J13 -> 1.57 | C39: =STEMI_MODIF.!N13 -> 7.81 | D39: =STEMI_MODIF.!R13 -> 7.46 | E39: =STEMI_MODIF.!V13 -> 6.58 | F39: =STEMI_MODIF.!Z13 -> 5.93 | G39: =STEMI_MODIF.!AD13 -> 4.98 | H39: =STEMI_MODIF.!AH13 -> 1.72 | I39: =STEMI_MODIF.!AL13 -> 0.43 | J39: =STEMI_MODIF.!AP13 -> 0.144 | K39: =STEMI_MODIF.!AT13 -> 2.18 | L39: =STEMI_MODIF.!AX13 -> 2.14 | M39: =STEMI_MODIF.!BB13 -> 2.16 | N39: =STEMI_MODIF.!BF13 -> 0.896 | O39: =STEMI_MODIF.!BJ13 -> 0.973
A40: S10 | B40: =STEMI_MODIF.!J14 -> 5.15 | C40: =STEMI_MODIF.!N14 -> 3.82 | D40: =STEMI_MODIF.!R14 -> 3.03 | E40: =STEMI_MODIF.!V14 -> 2.81 | F40: =STEMI_MODIF.!Z14 -> 2.69 | G40: =STEMI_MODIF.!AD14 -> 2.13 | H40: =STEMI_MODIF.!AH14 -> 0.889 | I40: =STEMI_MODIF.!AL14 -> 0.458 | J40: =STEMI_MODIF.!AP14 -> 0.228 | K40: =STEMI_MODIF.!AT14 -> 0.124 | L40: =STEMI_MODIF.!AX14 -> 0 | M40: =STEMI_MODIF.!BB14 -> 0 | N40: =STEMI_MODIF.!BF14 -> 0 | O40: =STEMI_MODIF.!BJ14 -> 0
A41: S11 | B41: =STEMI_MODIF.!J15 -> 5.65 | C41: =STEMI_MODIF.!N15 -> 18.55 | D41: =STEMI_MODIF.!R15 -> 9.43 | E41: =STEMI_MODIF.!V15 -> 4.24 | F41: =STEMI_MODIF.!Z15 -> 3.51 | G41: =STEMI_MODIF.!AD15 -> 3.17 | H41: =STEMI_MODIF.!AH15 -> 2.36 | I41: =STEMI_MODIF.!AL15 -> 42553 | J41: =STEMI_MODIF.!AP15 -> 1.91 | K41: =STEMI_MODIF.!AT15 -> 1.56 | L41: =STEMI_MODIF.!AX15 -> 0 | M41: =STEMI_MODIF.!BB15 -> 0 | N41: =STEMI_MODIF.!BF15 -> 0 | O41: =STEMI_MODIF.!BJ15 -> 0
A42: S12 | B42: =STEMI_MODIF.!J16 -> 0.733 | C42: =STEMI_MODIF.!N16 -> 1.11 | D42: =STEMI_MODIF.!R16 -> 1.18 | E42: =STEMI_MODIF.!V16 -> 0.963 | F42: =STEMI_MODIF.!Z16 -> 0.963 | G42: =STEMI_MODIF.!AD16 -> 1.09 | H42: =STEMI_MODIF.!AH16 -> 1.87 | I42: =STEMI_MODIF.!AL16 -> 2.16 | J42: =STEMI_MODIF.!AP16 -> 1.92 | K42: =STEMI_MODIF.!AT16 -> 1.46 | L42: =STEMI_MODIF.!AX16 -> 0 | M42: =STEMI_MODIF.!BB16 -> 0 | N42: =STEMI_MODIF.!BF16 -> 0 | O42: =STEMI_MODIF.!BJ16 -> 0
... A55: S25 | B55: =STEMI_MODIF.!J29 -> 0.899 | C55: =STEMI_MODIF.!N29 -> 2.83 | D55: =STEMI_MODIF.!R29 -> 3.11 | E55: =STEMI_MODIF.!V29 -> 1.83 | F55: =STEMI_MODIF.!Z29 -> 1.91 | G55: =STEMI_MODIF.!AD29 -> 1.64 | H55: =STEMI_MODIF.!AH29 -> 1.44 | I55: =STEMI_MODIF.!AL29 -> 1.14 | J55: =STEMI_MODIF.!AP29 -> 0.782 | K55: =STEMI_MODIF.!AT29 -> 0 | L55: =STEMI_MODIF.!AX29 -> 0 | M55: =STEMI_MODIF.!BB29 -> 0 | N55: =STEMI_MODIF.!BF29 -> 0 | O55: =STEMI_MODIF.!BJ29 -> 0

Sheet NSTEMI_MODIF.
B1: Valore negativo_prericovero
B3: PAT ID | C3: DATI PROCEDURA E RICOVERO
B4: Cognome-nome | C4: Data evento | D4: ANTIAGGREGANTE (1 Plavix; 2 Altro) | E4: GENSINI | F4: Insufficienza renale (1 Si; 2 No) | G4: A1 | H4: TIME FROM t0[h.m] | I4: TnThs MIRE 1 | J4: CK-MB 1 | K4: A2 | L4: TIME FROM t0[h.m] | M4: TnThs MIRE 2 | N4: CK-MB 2 | O4: A3 | P4: TIME FROM t0[h.m] | Q4: TnThs MIRE 3 | R4: CK-MB 3 | S4: A4 | T4: TIME FROM t0[h.m] | U4: TnThs MIRE 4 | V4: CK-MB 4 | W4: A5 | X4: TIME FROM t0[h.m] | Y4: TnThs MIRE 5 | Z4: CK-MB 5 | AA4: A6 | AB4: TIME FROM t0[h.m] | AC4: TnThs MIRE 6 | AD4: CK-MB 6 | AE4: A7 | AF4: TIME FROM t0[h.m] | AG4: TnThs MIRE 7 | AH4: CK-MB 7 | AI4: A8 | AJ4: TIME FROM t0[h.m] | AK4: TnThs MIRE 8 | AL4: CK-MB 8 | AM4: A9 | AN4: TIME FROM t0[h.m] | AO4: TnThs MIRE 9 | AP4: CK-MB 9 | AQ4: A10 | AR4: TIME FROM t0[h.m] | AS4: TnThs MIRE 10 | AT4: CK-MB 10 | AU4: A11 | AV4: TIME FROM t0[h.m] | AW4: TnThs MIRE 11 | AX4: CK-MB 11 | AY4: A12 | AZ4: TIME FROM t0[h.m] | BA4: TnThs MIRE 12 | BB4: CK-MB 12
A5: 1 | B5: Megna Emilio | C5: 41338.542 | D5: 2 | F5: 2 | G5: 41338.722 | H5: =G5-C5 -> 0.18055556 | I5: 0.514 | J5: 3.67 | K5: 41338.956 | L5: =K5-C5 -> 0.41388889 | M5: 0.618 | N5: 2.93 | O5: 41339.36 | P5: =O5-C5 -> 0.81875 | Q5: 0.542 | R5: 2.73 | S5: 41339.762 | T5: =S5-C5 -> 1.2201389 | U5: 0.579 | V5: 3.25 | W5: 41340.358 | X5: =W5-C5 -> 1.8166667 | Y5: 0.422 | Z5: 2.45 | AA5: 41341.372 | AB5: =AA5-C5 -> 2.8305556 | AC5: 0.366 | AD5: 1.28
A6: 2 | B6: Cavallaro Erminia | C6: 41337.583 | D6: 2 | F6: 2 | G6: 41339.565 | H6: =G6-C6 -> 1.9819444 | I6: 0.059 | J6: 1.77 | K6: 41339.962 | L6: =K6-C6 -> 2.3784722 | M6: 0.0782 | N6: 2.11 | O6: 41340.37 | P6: =O6-C6 -> 2.7868056 | Q6: 0.078 | R6: 3.03 | S6: 41341.424 | T6: =S6-C6 -> 3.8409722 | U6: 0.072
A7: 3 | B7: Mileto Mariangela | C7: 41337.5 | D7: 1 | F7: 2 | G7: 41341.513 | H7: =G7-C7 -> 4.0131944 | I7: 0.194 | J7: 27.19 | K7: 41341.951 | L7: =K7-C7 -> 4.4506944 | M7: 0.789 | N7: 26.16 | O7: 41342.44 | P7: =O7-C7 -> 4.9402778 | Q7: 0.531 | R7: 12.16 | S7: 41343.432 | T7: =S7-C7 -> 5.9319444 | U7: 0.818 | V7: 2.67 | W7: 41344.409 | X7: =W7-C7 -> 6.9090278 | Y7: 0.761 | Z7: 1.64
A8: 4 | B8: Romano Pasquale | C8: 41367.5 | D8: 1 | F8: 2 | G8: 41367.683 | H8: =G8-C8 -> 0.18333333 | I8: 0.205 | J8: 2.55 | K8: 41368.406 | L8: =K8-C8 -> 0.90625 | M8: 0.127 | N8: 3.65 | O8: 41368.958 | P8: =O8-C8 -> 1.4576389 | Q8: 0.196 | R8: 6.01 | S8: 41369.385 | T8: =S8-C8 -> 1.8847222 | U8: 0.278 | V8: 11.53 | W8: 41370.399 | X8: =W8-C8 -> 2.8986111 | Y8: 0.184 | Z8: 3.95 | AA8: 41371.448 | AB8: =AA8-C8 -> 3.9479167 | AC8: 0.182
A9: 5 | B9: Lagana' Natale | C9: 41381.5 | D9: 1 | F9: 2 | G9: 41381.958 | H9: =G9-C9 -> 0.45763889 | I9: 0.335 | J9: 14.1 | K9: 41382.447 | L9: =K9-C9 -> 0.94652778 | M9: 0.296 | N9: 11 | O9: 41382.99 | P9: =O9-C9 -> 1.4895833 | Q9: 0.236 | R9: 12.48 | S9: 41383.38 | T9: =S9-C9 -> 1.8798611 | U9: 0.237 | V9: 17.05 | W9: 41384.424 | X9: =W9-C9 -> 2.9236111 | Y9: 0.411 | AA9: 41384.657 | AB9: =AA9-C9 -> 3.1569444 | AC9: 0.255 | AE9: 41385.42 | AF9: =AE9-C9 -> 3.9201389 | AG9: 0.298 | AI9: 41385.688 | AJ9: =AI9-C9 -> 4.1875 | AK9: 0.351 | AM9: 41386.456 | AN9: =AM9-C9 -> 4.9555556 | AO9: 0.341
